2020-05-17 19:03:49,552 -  nornir.core -     INFO -        run() - Running task 'netmiko_send_config' with args {'config_commands': ['ping 10.0.0.1']} on 8 hosts
2020-05-17 19:03:49,560 - nornir.core.task -    ERROR -      start() - Host 'Automation': task 'netmiko_send_config' failed with traceback:
Traceback (most recent call last):
  File "/home/macaktom/.local/share/virtualenvs/network_automation-NLxdyicX/lib/python3.8/site-packages/netmiko/base_connection.py", line 884, in establish_connection
    self.remote_conn_pre.connect(**ssh_connect_params)
  File "/home/macaktom/.local/share/virtualenvs/network_automation-NLxdyicX/lib/python3.8/site-packages/paramiko/client.py", line 368, in connect
    raise NoValidConnectionsError(errors)
paramiko.ssh_exception.NoValidConnectionsError: [Errno None] Unable to connect to port 22 on 10.0.0.1

During handling of the above exception, another exception occurred:

Traceback (most recent call last):
  File "/home/macaktom/.local/share/virtualenvs/network_automation-NLxdyicX/lib/python3.8/site-packages/nornir/core/task.py", line 85, in start
    r = self.task(self, **self.params)
  File "/home/macaktom/.local/share/virtualenvs/network_automation-NLxdyicX/lib/python3.8/site-packages/nornir/plugins/tasks/networking/netmiko_send_config.py", line 24, in netmiko_send_config
    net_connect = task.host.get_connection("netmiko", task.nornir.config)
  File "/home/macaktom/.local/share/virtualenvs/network_automation-NLxdyicX/lib/python3.8/site-packages/nornir/core/inventory.py", line 294, in get_connection
    self.open_connection(
  File "/home/macaktom/.local/share/virtualenvs/network_automation-NLxdyicX/lib/python3.8/site-packages/nornir/core/inventory.py", line 345, in open_connection
    self.connections[connection].open(
  File "/home/macaktom/.local/share/virtualenvs/network_automation-NLxdyicX/lib/python3.8/site-packages/nornir/plugins/connections/netmiko.py", line 58, in open
    self.connection = ConnectHandler(**parameters)
  File "/home/macaktom/.local/share/virtualenvs/network_automation-NLxdyicX/lib/python3.8/site-packages/netmiko/ssh_dispatcher.py", line 246, in ConnectHandler
    return ConnectionClass(*args, **kwargs)
  File "/home/macaktom/.local/share/virtualenvs/network_automation-NLxdyicX/lib/python3.8/site-packages/netmiko/base_connection.py", line 317, in __init__
    self._open()
  File "/home/macaktom/.local/share/virtualenvs/network_automation-NLxdyicX/lib/python3.8/site-packages/netmiko/base_connection.py", line 322, in _open
    self.establish_connection()
  File "/home/macaktom/.local/share/virtualenvs/network_automation-NLxdyicX/lib/python3.8/site-packages/netmiko/base_connection.py", line 890, in establish_connection
    raise NetMikoTimeoutException(msg)
netmiko.ssh_exception.NetMikoTimeoutException: Connection to device timed-out: linux 10.0.0.1:22

2020-05-17 19:05:29,652 - nornir.core.task -    ERROR -      start() - Host 'R1': task 'netmiko_send_config' failed with traceback:
Traceback (most recent call last):
  File "/home/macaktom/.local/share/virtualenvs/network_automation-NLxdyicX/lib/python3.8/site-packages/netmiko/base_connection.py", line 884, in establish_connection
    self.remote_conn_pre.connect(**ssh_connect_params)
  File "/home/macaktom/.local/share/virtualenvs/network_automation-NLxdyicX/lib/python3.8/site-packages/paramiko/client.py", line 349, in connect
    retry_on_signal(lambda: sock.connect(addr))
  File "/home/macaktom/.local/share/virtualenvs/network_automation-NLxdyicX/lib/python3.8/site-packages/paramiko/util.py", line 283, in retry_on_signal
    return function()
  File "/home/macaktom/.local/share/virtualenvs/network_automation-NLxdyicX/lib/python3.8/site-packages/paramiko/client.py", line 349, in <lambda>
    retry_on_signal(lambda: sock.connect(addr))
socket.timeout: timed out

During handling of the above exception, another exception occurred:

Traceback (most recent call last):
  File "/home/macaktom/.local/share/virtualenvs/network_automation-NLxdyicX/lib/python3.8/site-packages/nornir/core/task.py", line 85, in start
    r = self.task(self, **self.params)
  File "/home/macaktom/.local/share/virtualenvs/network_automation-NLxdyicX/lib/python3.8/site-packages/nornir/plugins/tasks/networking/netmiko_send_config.py", line 24, in netmiko_send_config
    net_connect = task.host.get_connection("netmiko", task.nornir.config)
  File "/home/macaktom/.local/share/virtualenvs/network_automation-NLxdyicX/lib/python3.8/site-packages/nornir/core/inventory.py", line 294, in get_connection
    self.open_connection(
  File "/home/macaktom/.local/share/virtualenvs/network_automation-NLxdyicX/lib/python3.8/site-packages/nornir/core/inventory.py", line 345, in open_connection
    self.connections[connection].open(
  File "/home/macaktom/.local/share/virtualenvs/network_automation-NLxdyicX/lib/python3.8/site-packages/nornir/plugins/connections/netmiko.py", line 58, in open
    self.connection = ConnectHandler(**parameters)
  File "/home/macaktom/.local/share/virtualenvs/network_automation-NLxdyicX/lib/python3.8/site-packages/netmiko/ssh_dispatcher.py", line 246, in ConnectHandler
    return ConnectionClass(*args, **kwargs)
  File "/home/macaktom/.local/share/virtualenvs/network_automation-NLxdyicX/lib/python3.8/site-packages/netmiko/base_connection.py", line 317, in __init__
    self._open()
  File "/home/macaktom/.local/share/virtualenvs/network_automation-NLxdyicX/lib/python3.8/site-packages/netmiko/base_connection.py", line 322, in _open
    self.establish_connection()
  File "/home/macaktom/.local/share/virtualenvs/network_automation-NLxdyicX/lib/python3.8/site-packages/netmiko/base_connection.py", line 890, in establish_connection
    raise NetMikoTimeoutException(msg)
netmiko.ssh_exception.NetMikoTimeoutException: Connection to device timed-out: cisco_ios 10.0.0.2:22

2020-05-17 19:05:29,653 - nornir.core.task -    ERROR -      start() - Host 'SW1': task 'netmiko_send_config' failed with traceback:
Traceback (most recent call last):
  File "/home/macaktom/.local/share/virtualenvs/network_automation-NLxdyicX/lib/python3.8/site-packages/netmiko/base_connection.py", line 884, in establish_connection
    self.remote_conn_pre.connect(**ssh_connect_params)
  File "/home/macaktom/.local/share/virtualenvs/network_automation-NLxdyicX/lib/python3.8/site-packages/paramiko/client.py", line 349, in connect
    retry_on_signal(lambda: sock.connect(addr))
  File "/home/macaktom/.local/share/virtualenvs/network_automation-NLxdyicX/lib/python3.8/site-packages/paramiko/util.py", line 283, in retry_on_signal
    return function()
  File "/home/macaktom/.local/share/virtualenvs/network_automation-NLxdyicX/lib/python3.8/site-packages/paramiko/client.py", line 349, in <lambda>
    retry_on_signal(lambda: sock.connect(addr))
socket.timeout: timed out

During handling of the above exception, another exception occurred:

Traceback (most recent call last):
  File "/home/macaktom/.local/share/virtualenvs/network_automation-NLxdyicX/lib/python3.8/site-packages/nornir/core/task.py", line 85, in start
    r = self.task(self, **self.params)
  File "/home/macaktom/.local/share/virtualenvs/network_automation-NLxdyicX/lib/python3.8/site-packages/nornir/plugins/tasks/networking/netmiko_send_config.py", line 24, in netmiko_send_config
    net_connect = task.host.get_connection("netmiko", task.nornir.config)
  File "/home/macaktom/.local/share/virtualenvs/network_automation-NLxdyicX/lib/python3.8/site-packages/nornir/core/inventory.py", line 294, in get_connection
    self.open_connection(
  File "/home/macaktom/.local/share/virtualenvs/network_automation-NLxdyicX/lib/python3.8/site-packages/nornir/core/inventory.py", line 345, in open_connection
    self.connections[connection].open(
  File "/home/macaktom/.local/share/virtualenvs/network_automation-NLxdyicX/lib/python3.8/site-packages/nornir/plugins/connections/netmiko.py", line 58, in open
    self.connection = ConnectHandler(**parameters)
  File "/home/macaktom/.local/share/virtualenvs/network_automation-NLxdyicX/lib/python3.8/site-packages/netmiko/ssh_dispatcher.py", line 246, in ConnectHandler
    return ConnectionClass(*args, **kwargs)
  File "/home/macaktom/.local/share/virtualenvs/network_automation-NLxdyicX/lib/python3.8/site-packages/netmiko/base_connection.py", line 317, in __init__
    self._open()
  File "/home/macaktom/.local/share/virtualenvs/network_automation-NLxdyicX/lib/python3.8/site-packages/netmiko/base_connection.py", line 322, in _open
    self.establish_connection()
  File "/home/macaktom/.local/share/virtualenvs/network_automation-NLxdyicX/lib/python3.8/site-packages/netmiko/base_connection.py", line 890, in establish_connection
    raise NetMikoTimeoutException(msg)
netmiko.ssh_exception.NetMikoTimeoutException: Connection to device timed-out: cisco_ios 10.0.0.3:22

2020-05-17 19:05:29,656 - nornir.core.task -    ERROR -      start() - Host 'Client2': task 'netmiko_send_config' failed with traceback:
Traceback (most recent call last):
  File "/home/macaktom/.local/share/virtualenvs/network_automation-NLxdyicX/lib/python3.8/site-packages/netmiko/base_connection.py", line 884, in establish_connection
    self.remote_conn_pre.connect(**ssh_connect_params)
  File "/home/macaktom/.local/share/virtualenvs/network_automation-NLxdyicX/lib/python3.8/site-packages/paramiko/client.py", line 349, in connect
    retry_on_signal(lambda: sock.connect(addr))
  File "/home/macaktom/.local/share/virtualenvs/network_automation-NLxdyicX/lib/python3.8/site-packages/paramiko/util.py", line 283, in retry_on_signal
    return function()
  File "/home/macaktom/.local/share/virtualenvs/network_automation-NLxdyicX/lib/python3.8/site-packages/paramiko/client.py", line 349, in <lambda>
    retry_on_signal(lambda: sock.connect(addr))
socket.timeout: timed out

During handling of the above exception, another exception occurred:

Traceback (most recent call last):
  File "/home/macaktom/.local/share/virtualenvs/network_automation-NLxdyicX/lib/python3.8/site-packages/nornir/core/task.py", line 85, in start
    r = self.task(self, **self.params)
  File "/home/macaktom/.local/share/virtualenvs/network_automation-NLxdyicX/lib/python3.8/site-packages/nornir/plugins/tasks/networking/netmiko_send_config.py", line 24, in netmiko_send_config
    net_connect = task.host.get_connection("netmiko", task.nornir.config)
  File "/home/macaktom/.local/share/virtualenvs/network_automation-NLxdyicX/lib/python3.8/site-packages/nornir/core/inventory.py", line 294, in get_connection
    self.open_connection(
  File "/home/macaktom/.local/share/virtualenvs/network_automation-NLxdyicX/lib/python3.8/site-packages/nornir/core/inventory.py", line 345, in open_connection
    self.connections[connection].open(
  File "/home/macaktom/.local/share/virtualenvs/network_automation-NLxdyicX/lib/python3.8/site-packages/nornir/plugins/connections/netmiko.py", line 58, in open
    self.connection = ConnectHandler(**parameters)
  File "/home/macaktom/.local/share/virtualenvs/network_automation-NLxdyicX/lib/python3.8/site-packages/netmiko/ssh_dispatcher.py", line 246, in ConnectHandler
    return ConnectionClass(*args, **kwargs)
  File "/home/macaktom/.local/share/virtualenvs/network_automation-NLxdyicX/lib/python3.8/site-packages/netmiko/base_connection.py", line 317, in __init__
    self._open()
  File "/home/macaktom/.local/share/virtualenvs/network_automation-NLxdyicX/lib/python3.8/site-packages/netmiko/base_connection.py", line 322, in _open
    self.establish_connection()
  File "/home/macaktom/.local/share/virtualenvs/network_automation-NLxdyicX/lib/python3.8/site-packages/netmiko/base_connection.py", line 890, in establish_connection
    raise NetMikoTimeoutException(msg)
netmiko.ssh_exception.NetMikoTimeoutException: Connection to device timed-out: linux 10.0.0.7:22

2020-05-17 19:05:29,657 - nornir.core.task -    ERROR -      start() - Host 'Client1': task 'netmiko_send_config' failed with traceback:
Traceback (most recent call last):
  File "/home/macaktom/.local/share/virtualenvs/network_automation-NLxdyicX/lib/python3.8/site-packages/netmiko/base_connection.py", line 884, in establish_connection
    self.remote_conn_pre.connect(**ssh_connect_params)
  File "/home/macaktom/.local/share/virtualenvs/network_automation-NLxdyicX/lib/python3.8/site-packages/paramiko/client.py", line 349, in connect
    retry_on_signal(lambda: sock.connect(addr))
  File "/home/macaktom/.local/share/virtualenvs/network_automation-NLxdyicX/lib/python3.8/site-packages/paramiko/util.py", line 283, in retry_on_signal
    return function()
  File "/home/macaktom/.local/share/virtualenvs/network_automation-NLxdyicX/lib/python3.8/site-packages/paramiko/client.py", line 349, in <lambda>
    retry_on_signal(lambda: sock.connect(addr))
socket.timeout: timed out

During handling of the above exception, another exception occurred:

Traceback (most recent call last):
  File "/home/macaktom/.local/share/virtualenvs/network_automation-NLxdyicX/lib/python3.8/site-packages/nornir/core/task.py", line 85, in start
    r = self.task(self, **self.params)
  File "/home/macaktom/.local/share/virtualenvs/network_automation-NLxdyicX/lib/python3.8/site-packages/nornir/plugins/tasks/networking/netmiko_send_config.py", line 24, in netmiko_send_config
    net_connect = task.host.get_connection("netmiko", task.nornir.config)
  File "/home/macaktom/.local/share/virtualenvs/network_automation-NLxdyicX/lib/python3.8/site-packages/nornir/core/inventory.py", line 294, in get_connection
    self.open_connection(
  File "/home/macaktom/.local/share/virtualenvs/network_automation-NLxdyicX/lib/python3.8/site-packages/nornir/core/inventory.py", line 345, in open_connection
    self.connections[connection].open(
  File "/home/macaktom/.local/share/virtualenvs/network_automation-NLxdyicX/lib/python3.8/site-packages/nornir/plugins/connections/netmiko.py", line 58, in open
    self.connection = ConnectHandler(**parameters)
  File "/home/macaktom/.local/share/virtualenvs/network_automation-NLxdyicX/lib/python3.8/site-packages/netmiko/ssh_dispatcher.py", line 246, in ConnectHandler
    return ConnectionClass(*args, **kwargs)
  File "/home/macaktom/.local/share/virtualenvs/network_automation-NLxdyicX/lib/python3.8/site-packages/netmiko/base_connection.py", line 317, in __init__
    self._open()
  File "/home/macaktom/.local/share/virtualenvs/network_automation-NLxdyicX/lib/python3.8/site-packages/netmiko/base_connection.py", line 322, in _open
    self.establish_connection()
  File "/home/macaktom/.local/share/virtualenvs/network_automation-NLxdyicX/lib/python3.8/site-packages/netmiko/base_connection.py", line 890, in establish_connection
    raise NetMikoTimeoutException(msg)
netmiko.ssh_exception.NetMikoTimeoutException: Connection to device timed-out: linux 10.0.0.6:22

2020-05-17 19:05:29,659 - nornir.core.task -    ERROR -      start() - Host 'SW2': task 'netmiko_send_config' failed with traceback:
Traceback (most recent call last):
  File "/home/macaktom/.local/share/virtualenvs/network_automation-NLxdyicX/lib/python3.8/site-packages/netmiko/base_connection.py", line 884, in establish_connection
    self.remote_conn_pre.connect(**ssh_connect_params)
  File "/home/macaktom/.local/share/virtualenvs/network_automation-NLxdyicX/lib/python3.8/site-packages/paramiko/client.py", line 349, in connect
    retry_on_signal(lambda: sock.connect(addr))
  File "/home/macaktom/.local/share/virtualenvs/network_automation-NLxdyicX/lib/python3.8/site-packages/paramiko/util.py", line 283, in retry_on_signal
    return function()
  File "/home/macaktom/.local/share/virtualenvs/network_automation-NLxdyicX/lib/python3.8/site-packages/paramiko/client.py", line 349, in <lambda>
    retry_on_signal(lambda: sock.connect(addr))
socket.timeout: timed out

During handling of the above exception, another exception occurred:

Traceback (most recent call last):
  File "/home/macaktom/.local/share/virtualenvs/network_automation-NLxdyicX/lib/python3.8/site-packages/nornir/core/task.py", line 85, in start
    r = self.task(self, **self.params)
  File "/home/macaktom/.local/share/virtualenvs/network_automation-NLxdyicX/lib/python3.8/site-packages/nornir/plugins/tasks/networking/netmiko_send_config.py", line 24, in netmiko_send_config
    net_connect = task.host.get_connection("netmiko", task.nornir.config)
  File "/home/macaktom/.local/share/virtualenvs/network_automation-NLxdyicX/lib/python3.8/site-packages/nornir/core/inventory.py", line 294, in get_connection
    self.open_connection(
  File "/home/macaktom/.local/share/virtualenvs/network_automation-NLxdyicX/lib/python3.8/site-packages/nornir/core/inventory.py", line 345, in open_connection
    self.connections[connection].open(
  File "/home/macaktom/.local/share/virtualenvs/network_automation-NLxdyicX/lib/python3.8/site-packages/nornir/plugins/connections/netmiko.py", line 58, in open
    self.connection = ConnectHandler(**parameters)
  File "/home/macaktom/.local/share/virtualenvs/network_automation-NLxdyicX/lib/python3.8/site-packages/netmiko/ssh_dispatcher.py", line 246, in ConnectHandler
    return ConnectionClass(*args, **kwargs)
  File "/home/macaktom/.local/share/virtualenvs/network_automation-NLxdyicX/lib/python3.8/site-packages/netmiko/base_connection.py", line 317, in __init__
    self._open()
  File "/home/macaktom/.local/share/virtualenvs/network_automation-NLxdyicX/lib/python3.8/site-packages/netmiko/base_connection.py", line 322, in _open
    self.establish_connection()
  File "/home/macaktom/.local/share/virtualenvs/network_automation-NLxdyicX/lib/python3.8/site-packages/netmiko/base_connection.py", line 890, in establish_connection
    raise NetMikoTimeoutException(msg)
netmiko.ssh_exception.NetMikoTimeoutException: Connection to device timed-out: cisco_ios 10.0.0.4:22

2020-05-17 19:05:29,660 - nornir.core.task -    ERROR -      start() - Host 'SW3': task 'netmiko_send_config' failed with traceback:
Traceback (most recent call last):
  File "/home/macaktom/.local/share/virtualenvs/network_automation-NLxdyicX/lib/python3.8/site-packages/netmiko/base_connection.py", line 884, in establish_connection
    self.remote_conn_pre.connect(**ssh_connect_params)
  File "/home/macaktom/.local/share/virtualenvs/network_automation-NLxdyicX/lib/python3.8/site-packages/paramiko/client.py", line 349, in connect
    retry_on_signal(lambda: sock.connect(addr))
  File "/home/macaktom/.local/share/virtualenvs/network_automation-NLxdyicX/lib/python3.8/site-packages/paramiko/util.py", line 283, in retry_on_signal
    return function()
  File "/home/macaktom/.local/share/virtualenvs/network_automation-NLxdyicX/lib/python3.8/site-packages/paramiko/client.py", line 349, in <lambda>
    retry_on_signal(lambda: sock.connect(addr))
socket.timeout: timed out

During handling of the above exception, another exception occurred:

Traceback (most recent call last):
  File "/home/macaktom/.local/share/virtualenvs/network_automation-NLxdyicX/lib/python3.8/site-packages/nornir/core/task.py", line 85, in start
    r = self.task(self, **self.params)
  File "/home/macaktom/.local/share/virtualenvs/network_automation-NLxdyicX/lib/python3.8/site-packages/nornir/plugins/tasks/networking/netmiko_send_config.py", line 24, in netmiko_send_config
    net_connect = task.host.get_connection("netmiko", task.nornir.config)
  File "/home/macaktom/.local/share/virtualenvs/network_automation-NLxdyicX/lib/python3.8/site-packages/nornir/core/inventory.py", line 294, in get_connection
    self.open_connection(
  File "/home/macaktom/.local/share/virtualenvs/network_automation-NLxdyicX/lib/python3.8/site-packages/nornir/core/inventory.py", line 345, in open_connection
    self.connections[connection].open(
  File "/home/macaktom/.local/share/virtualenvs/network_automation-NLxdyicX/lib/python3.8/site-packages/nornir/plugins/connections/netmiko.py", line 58, in open
    self.connection = ConnectHandler(**parameters)
  File "/home/macaktom/.local/share/virtualenvs/network_automation-NLxdyicX/lib/python3.8/site-packages/netmiko/ssh_dispatcher.py", line 246, in ConnectHandler
    return ConnectionClass(*args, **kwargs)
  File "/home/macaktom/.local/share/virtualenvs/network_automation-NLxdyicX/lib/python3.8/site-packages/netmiko/base_connection.py", line 317, in __init__
    self._open()
  File "/home/macaktom/.local/share/virtualenvs/network_automation-NLxdyicX/lib/python3.8/site-packages/netmiko/base_connection.py", line 322, in _open
    self.establish_connection()
  File "/home/macaktom/.local/share/virtualenvs/network_automation-NLxdyicX/lib/python3.8/site-packages/netmiko/base_connection.py", line 890, in establish_connection
    raise NetMikoTimeoutException(msg)
netmiko.ssh_exception.NetMikoTimeoutException: Connection to device timed-out: cisco_ios 10.0.0.5:22

2020-05-17 19:05:29,660 - nornir.core.task -    ERROR -      start() - Host 'R2': task 'netmiko_send_config' failed with traceback:
Traceback (most recent call last):
  File "/home/macaktom/.local/share/virtualenvs/network_automation-NLxdyicX/lib/python3.8/site-packages/netmiko/base_connection.py", line 884, in establish_connection
    self.remote_conn_pre.connect(**ssh_connect_params)
  File "/home/macaktom/.local/share/virtualenvs/network_automation-NLxdyicX/lib/python3.8/site-packages/paramiko/client.py", line 349, in connect
    retry_on_signal(lambda: sock.connect(addr))
  File "/home/macaktom/.local/share/virtualenvs/network_automation-NLxdyicX/lib/python3.8/site-packages/paramiko/util.py", line 283, in retry_on_signal
    return function()
  File "/home/macaktom/.local/share/virtualenvs/network_automation-NLxdyicX/lib/python3.8/site-packages/paramiko/client.py", line 349, in <lambda>
    retry_on_signal(lambda: sock.connect(addr))
socket.timeout: timed out

During handling of the above exception, another exception occurred:

Traceback (most recent call last):
  File "/home/macaktom/.local/share/virtualenvs/network_automation-NLxdyicX/lib/python3.8/site-packages/nornir/core/task.py", line 85, in start
    r = self.task(self, **self.params)
  File "/home/macaktom/.local/share/virtualenvs/network_automation-NLxdyicX/lib/python3.8/site-packages/nornir/plugins/tasks/networking/netmiko_send_config.py", line 24, in netmiko_send_config
    net_connect = task.host.get_connection("netmiko", task.nornir.config)
  File "/home/macaktom/.local/share/virtualenvs/network_automation-NLxdyicX/lib/python3.8/site-packages/nornir/core/inventory.py", line 294, in get_connection
    self.open_connection(
  File "/home/macaktom/.local/share/virtualenvs/network_automation-NLxdyicX/lib/python3.8/site-packages/nornir/core/inventory.py", line 345, in open_connection
    self.connections[connection].open(
  File "/home/macaktom/.local/share/virtualenvs/network_automation-NLxdyicX/lib/python3.8/site-packages/nornir/plugins/connections/netmiko.py", line 58, in open
    self.connection = ConnectHandler(**parameters)
  File "/home/macaktom/.local/share/virtualenvs/network_automation-NLxdyicX/lib/python3.8/site-packages/netmiko/ssh_dispatcher.py", line 246, in ConnectHandler
    return ConnectionClass(*args, **kwargs)
  File "/home/macaktom/.local/share/virtualenvs/network_automation-NLxdyicX/lib/python3.8/site-packages/netmiko/base_connection.py", line 317, in __init__
    self._open()
  File "/home/macaktom/.local/share/virtualenvs/network_automation-NLxdyicX/lib/python3.8/site-packages/netmiko/base_connection.py", line 322, in _open
    self.establish_connection()
  File "/home/macaktom/.local/share/virtualenvs/network_automation-NLxdyicX/lib/python3.8/site-packages/netmiko/base_connection.py", line 890, in establish_connection
    raise NetMikoTimeoutException(msg)
netmiko.ssh_exception.NetMikoTimeoutException: Connection to device timed-out: juniper_junos 10.0.1.2:22

2020-05-17 19:45:17,496 -  nornir.core -     INFO -        run() - Running task 'netmiko_send_config' with args {'config_commands': ['ping 10.0.0.1']} on 7 hosts
2020-05-17 19:45:17,508 - nornir.core.task -    ERROR -      start() - Host 'Automation': task 'netmiko_send_config' failed with traceback:
Traceback (most recent call last):
  File "/home/macaktom/.local/share/virtualenvs/network_automation-NLxdyicX/lib/python3.8/site-packages/netmiko/base_connection.py", line 884, in establish_connection
    self.remote_conn_pre.connect(**ssh_connect_params)
  File "/home/macaktom/.local/share/virtualenvs/network_automation-NLxdyicX/lib/python3.8/site-packages/paramiko/client.py", line 368, in connect
    raise NoValidConnectionsError(errors)
paramiko.ssh_exception.NoValidConnectionsError: [Errno None] Unable to connect to port 22 on 10.0.0.1

During handling of the above exception, another exception occurred:

Traceback (most recent call last):
  File "/home/macaktom/.local/share/virtualenvs/network_automation-NLxdyicX/lib/python3.8/site-packages/nornir/core/task.py", line 85, in start
    r = self.task(self, **self.params)
  File "/home/macaktom/.local/share/virtualenvs/network_automation-NLxdyicX/lib/python3.8/site-packages/nornir/plugins/tasks/networking/netmiko_send_config.py", line 24, in netmiko_send_config
    net_connect = task.host.get_connection("netmiko", task.nornir.config)
  File "/home/macaktom/.local/share/virtualenvs/network_automation-NLxdyicX/lib/python3.8/site-packages/nornir/core/inventory.py", line 294, in get_connection
    self.open_connection(
  File "/home/macaktom/.local/share/virtualenvs/network_automation-NLxdyicX/lib/python3.8/site-packages/nornir/core/inventory.py", line 345, in open_connection
    self.connections[connection].open(
  File "/home/macaktom/.local/share/virtualenvs/network_automation-NLxdyicX/lib/python3.8/site-packages/nornir/plugins/connections/netmiko.py", line 58, in open
    self.connection = ConnectHandler(**parameters)
  File "/home/macaktom/.local/share/virtualenvs/network_automation-NLxdyicX/lib/python3.8/site-packages/netmiko/ssh_dispatcher.py", line 246, in ConnectHandler
    return ConnectionClass(*args, **kwargs)
  File "/home/macaktom/.local/share/virtualenvs/network_automation-NLxdyicX/lib/python3.8/site-packages/netmiko/base_connection.py", line 317, in __init__
    self._open()
  File "/home/macaktom/.local/share/virtualenvs/network_automation-NLxdyicX/lib/python3.8/site-packages/netmiko/base_connection.py", line 322, in _open
    self.establish_connection()
  File "/home/macaktom/.local/share/virtualenvs/network_automation-NLxdyicX/lib/python3.8/site-packages/netmiko/base_connection.py", line 890, in establish_connection
    raise NetMikoTimeoutException(msg)
netmiko.ssh_exception.NetMikoTimeoutException: Connection to device timed-out: linux 10.0.0.1:22

2020-05-17 19:45:17,515 - nornir.core.task -    ERROR -      start() - Host 'Client1': task 'netmiko_send_config' failed with traceback:
Traceback (most recent call last):
  File "/home/macaktom/.local/share/virtualenvs/network_automation-NLxdyicX/lib/python3.8/site-packages/netmiko/base_connection.py", line 884, in establish_connection
    self.remote_conn_pre.connect(**ssh_connect_params)
  File "/home/macaktom/.local/share/virtualenvs/network_automation-NLxdyicX/lib/python3.8/site-packages/paramiko/client.py", line 368, in connect
    raise NoValidConnectionsError(errors)
paramiko.ssh_exception.NoValidConnectionsError: [Errno None] Unable to connect to port 22 on 10.0.0.6

During handling of the above exception, another exception occurred:

Traceback (most recent call last):
  File "/home/macaktom/.local/share/virtualenvs/network_automation-NLxdyicX/lib/python3.8/site-packages/nornir/core/task.py", line 85, in start
    r = self.task(self, **self.params)
  File "/home/macaktom/.local/share/virtualenvs/network_automation-NLxdyicX/lib/python3.8/site-packages/nornir/plugins/tasks/networking/netmiko_send_config.py", line 24, in netmiko_send_config
    net_connect = task.host.get_connection("netmiko", task.nornir.config)
  File "/home/macaktom/.local/share/virtualenvs/network_automation-NLxdyicX/lib/python3.8/site-packages/nornir/core/inventory.py", line 294, in get_connection
    self.open_connection(
  File "/home/macaktom/.local/share/virtualenvs/network_automation-NLxdyicX/lib/python3.8/site-packages/nornir/core/inventory.py", line 345, in open_connection
    self.connections[connection].open(
  File "/home/macaktom/.local/share/virtualenvs/network_automation-NLxdyicX/lib/python3.8/site-packages/nornir/plugins/connections/netmiko.py", line 58, in open
    self.connection = ConnectHandler(**parameters)
  File "/home/macaktom/.local/share/virtualenvs/network_automation-NLxdyicX/lib/python3.8/site-packages/netmiko/ssh_dispatcher.py", line 246, in ConnectHandler
    return ConnectionClass(*args, **kwargs)
  File "/home/macaktom/.local/share/virtualenvs/network_automation-NLxdyicX/lib/python3.8/site-packages/netmiko/base_connection.py", line 317, in __init__
    self._open()
  File "/home/macaktom/.local/share/virtualenvs/network_automation-NLxdyicX/lib/python3.8/site-packages/netmiko/base_connection.py", line 322, in _open
    self.establish_connection()
  File "/home/macaktom/.local/share/virtualenvs/network_automation-NLxdyicX/lib/python3.8/site-packages/netmiko/base_connection.py", line 890, in establish_connection
    raise NetMikoTimeoutException(msg)
netmiko.ssh_exception.NetMikoTimeoutException: Connection to device timed-out: linux 10.0.0.6:22

2020-05-17 19:45:17,516 - nornir.core.task -    ERROR -      start() - Host 'Client2': task 'netmiko_send_config' failed with traceback:
Traceback (most recent call last):
  File "/home/macaktom/.local/share/virtualenvs/network_automation-NLxdyicX/lib/python3.8/site-packages/netmiko/base_connection.py", line 884, in establish_connection
    self.remote_conn_pre.connect(**ssh_connect_params)
  File "/home/macaktom/.local/share/virtualenvs/network_automation-NLxdyicX/lib/python3.8/site-packages/paramiko/client.py", line 368, in connect
    raise NoValidConnectionsError(errors)
paramiko.ssh_exception.NoValidConnectionsError: [Errno None] Unable to connect to port 22 on 10.0.0.7

During handling of the above exception, another exception occurred:

Traceback (most recent call last):
  File "/home/macaktom/.local/share/virtualenvs/network_automation-NLxdyicX/lib/python3.8/site-packages/nornir/core/task.py", line 85, in start
    r = self.task(self, **self.params)
  File "/home/macaktom/.local/share/virtualenvs/network_automation-NLxdyicX/lib/python3.8/site-packages/nornir/plugins/tasks/networking/netmiko_send_config.py", line 24, in netmiko_send_config
    net_connect = task.host.get_connection("netmiko", task.nornir.config)
  File "/home/macaktom/.local/share/virtualenvs/network_automation-NLxdyicX/lib/python3.8/site-packages/nornir/core/inventory.py", line 294, in get_connection
    self.open_connection(
  File "/home/macaktom/.local/share/virtualenvs/network_automation-NLxdyicX/lib/python3.8/site-packages/nornir/core/inventory.py", line 345, in open_connection
    self.connections[connection].open(
  File "/home/macaktom/.local/share/virtualenvs/network_automation-NLxdyicX/lib/python3.8/site-packages/nornir/plugins/connections/netmiko.py", line 58, in open
    self.connection = ConnectHandler(**parameters)
  File "/home/macaktom/.local/share/virtualenvs/network_automation-NLxdyicX/lib/python3.8/site-packages/netmiko/ssh_dispatcher.py", line 246, in ConnectHandler
    return ConnectionClass(*args, **kwargs)
  File "/home/macaktom/.local/share/virtualenvs/network_automation-NLxdyicX/lib/python3.8/site-packages/netmiko/base_connection.py", line 317, in __init__
    self._open()
  File "/home/macaktom/.local/share/virtualenvs/network_automation-NLxdyicX/lib/python3.8/site-packages/netmiko/base_connection.py", line 322, in _open
    self.establish_connection()
  File "/home/macaktom/.local/share/virtualenvs/network_automation-NLxdyicX/lib/python3.8/site-packages/netmiko/base_connection.py", line 890, in establish_connection
    raise NetMikoTimeoutException(msg)
netmiko.ssh_exception.NetMikoTimeoutException: Connection to device timed-out: linux 10.0.0.7:22

2020-05-17 19:45:17,517 - nornir.core.task -    ERROR -      start() - Host 'SW1': task 'netmiko_send_config' failed with traceback:
Traceback (most recent call last):
  File "/home/macaktom/.local/share/virtualenvs/network_automation-NLxdyicX/lib/python3.8/site-packages/netmiko/base_connection.py", line 884, in establish_connection
    self.remote_conn_pre.connect(**ssh_connect_params)
  File "/home/macaktom/.local/share/virtualenvs/network_automation-NLxdyicX/lib/python3.8/site-packages/paramiko/client.py", line 368, in connect
    raise NoValidConnectionsError(errors)
paramiko.ssh_exception.NoValidConnectionsError: [Errno None] Unable to connect to port 22 on 10.0.0.3

During handling of the above exception, another exception occurred:

Traceback (most recent call last):
  File "/home/macaktom/.local/share/virtualenvs/network_automation-NLxdyicX/lib/python3.8/site-packages/nornir/core/task.py", line 85, in start
    r = self.task(self, **self.params)
  File "/home/macaktom/.local/share/virtualenvs/network_automation-NLxdyicX/lib/python3.8/site-packages/nornir/plugins/tasks/networking/netmiko_send_config.py", line 24, in netmiko_send_config
    net_connect = task.host.get_connection("netmiko", task.nornir.config)
  File "/home/macaktom/.local/share/virtualenvs/network_automation-NLxdyicX/lib/python3.8/site-packages/nornir/core/inventory.py", line 294, in get_connection
    self.open_connection(
  File "/home/macaktom/.local/share/virtualenvs/network_automation-NLxdyicX/lib/python3.8/site-packages/nornir/core/inventory.py", line 345, in open_connection
    self.connections[connection].open(
  File "/home/macaktom/.local/share/virtualenvs/network_automation-NLxdyicX/lib/python3.8/site-packages/nornir/plugins/connections/netmiko.py", line 58, in open
    self.connection = ConnectHandler(**parameters)
  File "/home/macaktom/.local/share/virtualenvs/network_automation-NLxdyicX/lib/python3.8/site-packages/netmiko/ssh_dispatcher.py", line 246, in ConnectHandler
    return ConnectionClass(*args, **kwargs)
  File "/home/macaktom/.local/share/virtualenvs/network_automation-NLxdyicX/lib/python3.8/site-packages/netmiko/base_connection.py", line 317, in __init__
    self._open()
  File "/home/macaktom/.local/share/virtualenvs/network_automation-NLxdyicX/lib/python3.8/site-packages/netmiko/base_connection.py", line 322, in _open
    self.establish_connection()
  File "/home/macaktom/.local/share/virtualenvs/network_automation-NLxdyicX/lib/python3.8/site-packages/netmiko/base_connection.py", line 890, in establish_connection
    raise NetMikoTimeoutException(msg)
netmiko.ssh_exception.NetMikoTimeoutException: Connection to device timed-out: cisco_ios 10.0.0.3:22

2020-05-17 19:45:17,521 - nornir.core.task -    ERROR -      start() - Host 'SW3': task 'netmiko_send_config' failed with traceback:
Traceback (most recent call last):
  File "/home/macaktom/.local/share/virtualenvs/network_automation-NLxdyicX/lib/python3.8/site-packages/netmiko/base_connection.py", line 884, in establish_connection
    self.remote_conn_pre.connect(**ssh_connect_params)
  File "/home/macaktom/.local/share/virtualenvs/network_automation-NLxdyicX/lib/python3.8/site-packages/paramiko/client.py", line 368, in connect
    raise NoValidConnectionsError(errors)
paramiko.ssh_exception.NoValidConnectionsError: [Errno None] Unable to connect to port 22 on 10.0.0.5

During handling of the above exception, another exception occurred:

Traceback (most recent call last):
  File "/home/macaktom/.local/share/virtualenvs/network_automation-NLxdyicX/lib/python3.8/site-packages/nornir/core/task.py", line 85, in start
    r = self.task(self, **self.params)
  File "/home/macaktom/.local/share/virtualenvs/network_automation-NLxdyicX/lib/python3.8/site-packages/nornir/plugins/tasks/networking/netmiko_send_config.py", line 24, in netmiko_send_config
    net_connect = task.host.get_connection("netmiko", task.nornir.config)
  File "/home/macaktom/.local/share/virtualenvs/network_automation-NLxdyicX/lib/python3.8/site-packages/nornir/core/inventory.py", line 294, in get_connection
    self.open_connection(
  File "/home/macaktom/.local/share/virtualenvs/network_automation-NLxdyicX/lib/python3.8/site-packages/nornir/core/inventory.py", line 345, in open_connection
    self.connections[connection].open(
  File "/home/macaktom/.local/share/virtualenvs/network_automation-NLxdyicX/lib/python3.8/site-packages/nornir/plugins/connections/netmiko.py", line 58, in open
    self.connection = ConnectHandler(**parameters)
  File "/home/macaktom/.local/share/virtualenvs/network_automation-NLxdyicX/lib/python3.8/site-packages/netmiko/ssh_dispatcher.py", line 246, in ConnectHandler
    return ConnectionClass(*args, **kwargs)
  File "/home/macaktom/.local/share/virtualenvs/network_automation-NLxdyicX/lib/python3.8/site-packages/netmiko/base_connection.py", line 317, in __init__
    self._open()
  File "/home/macaktom/.local/share/virtualenvs/network_automation-NLxdyicX/lib/python3.8/site-packages/netmiko/base_connection.py", line 322, in _open
    self.establish_connection()
  File "/home/macaktom/.local/share/virtualenvs/network_automation-NLxdyicX/lib/python3.8/site-packages/netmiko/base_connection.py", line 890, in establish_connection
    raise NetMikoTimeoutException(msg)
netmiko.ssh_exception.NetMikoTimeoutException: Connection to device timed-out: cisco_ios 10.0.0.5:22

2020-05-17 19:45:17,525 - nornir.core.task -    ERROR -      start() - Host 'SW2': task 'netmiko_send_config' failed with traceback:
Traceback (most recent call last):
  File "/home/macaktom/.local/share/virtualenvs/network_automation-NLxdyicX/lib/python3.8/site-packages/netmiko/base_connection.py", line 884, in establish_connection
    self.remote_conn_pre.connect(**ssh_connect_params)
  File "/home/macaktom/.local/share/virtualenvs/network_automation-NLxdyicX/lib/python3.8/site-packages/paramiko/client.py", line 368, in connect
    raise NoValidConnectionsError(errors)
paramiko.ssh_exception.NoValidConnectionsError: [Errno None] Unable to connect to port 22 on 10.0.0.4

During handling of the above exception, another exception occurred:

Traceback (most recent call last):
  File "/home/macaktom/.local/share/virtualenvs/network_automation-NLxdyicX/lib/python3.8/site-packages/nornir/core/task.py", line 85, in start
    r = self.task(self, **self.params)
  File "/home/macaktom/.local/share/virtualenvs/network_automation-NLxdyicX/lib/python3.8/site-packages/nornir/plugins/tasks/networking/netmiko_send_config.py", line 24, in netmiko_send_config
    net_connect = task.host.get_connection("netmiko", task.nornir.config)
  File "/home/macaktom/.local/share/virtualenvs/network_automation-NLxdyicX/lib/python3.8/site-packages/nornir/core/inventory.py", line 294, in get_connection
    self.open_connection(
  File "/home/macaktom/.local/share/virtualenvs/network_automation-NLxdyicX/lib/python3.8/site-packages/nornir/core/inventory.py", line 345, in open_connection
    self.connections[connection].open(
  File "/home/macaktom/.local/share/virtualenvs/network_automation-NLxdyicX/lib/python3.8/site-packages/nornir/plugins/connections/netmiko.py", line 58, in open
    self.connection = ConnectHandler(**parameters)
  File "/home/macaktom/.local/share/virtualenvs/network_automation-NLxdyicX/lib/python3.8/site-packages/netmiko/ssh_dispatcher.py", line 246, in ConnectHandler
    return ConnectionClass(*args, **kwargs)
  File "/home/macaktom/.local/share/virtualenvs/network_automation-NLxdyicX/lib/python3.8/site-packages/netmiko/base_connection.py", line 317, in __init__
    self._open()
  File "/home/macaktom/.local/share/virtualenvs/network_automation-NLxdyicX/lib/python3.8/site-packages/netmiko/base_connection.py", line 322, in _open
    self.establish_connection()
  File "/home/macaktom/.local/share/virtualenvs/network_automation-NLxdyicX/lib/python3.8/site-packages/netmiko/base_connection.py", line 890, in establish_connection
    raise NetMikoTimeoutException(msg)
netmiko.ssh_exception.NetMikoTimeoutException: Connection to device timed-out: cisco_ios 10.0.0.4:22

2020-05-17 19:45:17,528 - nornir.core.task -    ERROR -      start() - Host 'R1': task 'netmiko_send_config' failed with traceback:
Traceback (most recent call last):
  File "/home/macaktom/.local/share/virtualenvs/network_automation-NLxdyicX/lib/python3.8/site-packages/netmiko/base_connection.py", line 884, in establish_connection
    self.remote_conn_pre.connect(**ssh_connect_params)
  File "/home/macaktom/.local/share/virtualenvs/network_automation-NLxdyicX/lib/python3.8/site-packages/paramiko/client.py", line 368, in connect
    raise NoValidConnectionsError(errors)
paramiko.ssh_exception.NoValidConnectionsError: [Errno None] Unable to connect to port 22 on 10.0.0.2

During handling of the above exception, another exception occurred:

Traceback (most recent call last):
  File "/home/macaktom/.local/share/virtualenvs/network_automation-NLxdyicX/lib/python3.8/site-packages/nornir/core/task.py", line 85, in start
    r = self.task(self, **self.params)
  File "/home/macaktom/.local/share/virtualenvs/network_automation-NLxdyicX/lib/python3.8/site-packages/nornir/plugins/tasks/networking/netmiko_send_config.py", line 24, in netmiko_send_config
    net_connect = task.host.get_connection("netmiko", task.nornir.config)
  File "/home/macaktom/.local/share/virtualenvs/network_automation-NLxdyicX/lib/python3.8/site-packages/nornir/core/inventory.py", line 294, in get_connection
    self.open_connection(
  File "/home/macaktom/.local/share/virtualenvs/network_automation-NLxdyicX/lib/python3.8/site-packages/nornir/core/inventory.py", line 345, in open_connection
    self.connections[connection].open(
  File "/home/macaktom/.local/share/virtualenvs/network_automation-NLxdyicX/lib/python3.8/site-packages/nornir/plugins/connections/netmiko.py", line 58, in open
    self.connection = ConnectHandler(**parameters)
  File "/home/macaktom/.local/share/virtualenvs/network_automation-NLxdyicX/lib/python3.8/site-packages/netmiko/ssh_dispatcher.py", line 246, in ConnectHandler
    return ConnectionClass(*args, **kwargs)
  File "/home/macaktom/.local/share/virtualenvs/network_automation-NLxdyicX/lib/python3.8/site-packages/netmiko/base_connection.py", line 317, in __init__
    self._open()
  File "/home/macaktom/.local/share/virtualenvs/network_automation-NLxdyicX/lib/python3.8/site-packages/netmiko/base_connection.py", line 322, in _open
    self.establish_connection()
  File "/home/macaktom/.local/share/virtualenvs/network_automation-NLxdyicX/lib/python3.8/site-packages/netmiko/base_connection.py", line 890, in establish_connection
    raise NetMikoTimeoutException(msg)
netmiko.ssh_exception.NetMikoTimeoutException: Connection to device timed-out: cisco_ios 10.0.0.2:22

2020-05-17 19:47:55,791 -  nornir.core -     INFO -        run() - Running task 'tcp_ping' with args {} on 7 hosts
2020-05-17 19:47:55,798 - nornir.core.task -    ERROR -      start() - Host 'Automation': task 'tcp_ping' failed with traceback:
Traceback (most recent call last):
  File "/home/macaktom/.local/share/virtualenvs/network_automation-NLxdyicX/lib/python3.8/site-packages/nornir/core/task.py", line 85, in start
    r = self.task(self, **self.params)
TypeError: tcp_ping() missing 1 required positional argument: 'ports'

2020-05-17 19:47:55,798 - nornir.core.task -    ERROR -      start() - Host 'SW1': task 'tcp_ping' failed with traceback:
Traceback (most recent call last):
  File "/home/macaktom/.local/share/virtualenvs/network_automation-NLxdyicX/lib/python3.8/site-packages/nornir/core/task.py", line 85, in start
    r = self.task(self, **self.params)
TypeError: tcp_ping() missing 1 required positional argument: 'ports'

2020-05-17 19:47:55,799 - nornir.core.task -    ERROR -      start() - Host 'R1': task 'tcp_ping' failed with traceback:
Traceback (most recent call last):
  File "/home/macaktom/.local/share/virtualenvs/network_automation-NLxdyicX/lib/python3.8/site-packages/nornir/core/task.py", line 85, in start
    r = self.task(self, **self.params)
TypeError: tcp_ping() missing 1 required positional argument: 'ports'

2020-05-17 19:47:55,799 - nornir.core.task -    ERROR -      start() - Host 'SW2': task 'tcp_ping' failed with traceback:
Traceback (most recent call last):
  File "/home/macaktom/.local/share/virtualenvs/network_automation-NLxdyicX/lib/python3.8/site-packages/nornir/core/task.py", line 85, in start
    r = self.task(self, **self.params)
TypeError: tcp_ping() missing 1 required positional argument: 'ports'

2020-05-17 19:47:55,799 - nornir.core.task -    ERROR -      start() - Host 'SW3': task 'tcp_ping' failed with traceback:
Traceback (most recent call last):
  File "/home/macaktom/.local/share/virtualenvs/network_automation-NLxdyicX/lib/python3.8/site-packages/nornir/core/task.py", line 85, in start
    r = self.task(self, **self.params)
TypeError: tcp_ping() missing 1 required positional argument: 'ports'

2020-05-17 19:47:55,800 - nornir.core.task -    ERROR -      start() - Host 'Client1': task 'tcp_ping' failed with traceback:
Traceback (most recent call last):
  File "/home/macaktom/.local/share/virtualenvs/network_automation-NLxdyicX/lib/python3.8/site-packages/nornir/core/task.py", line 85, in start
    r = self.task(self, **self.params)
TypeError: tcp_ping() missing 1 required positional argument: 'ports'

2020-05-17 19:47:55,800 - nornir.core.task -    ERROR -      start() - Host 'Client2': task 'tcp_ping' failed with traceback:
Traceback (most recent call last):
  File "/home/macaktom/.local/share/virtualenvs/network_automation-NLxdyicX/lib/python3.8/site-packages/nornir/core/task.py", line 85, in start
    r = self.task(self, **self.params)
TypeError: tcp_ping() missing 1 required positional argument: 'ports'

2020-05-17 19:49:15,526 -  nornir.core -     INFO -        run() - Running task 'netmiko_send_command' with args {'command_string': 'ping 10.0.0.1'} on 7 hosts
2020-05-17 19:49:15,533 - nornir.core.task -    ERROR -      start() - Host 'Automation': task 'netmiko_send_command' failed with traceback:
Traceback (most recent call last):
  File "/home/macaktom/.local/share/virtualenvs/network_automation-NLxdyicX/lib/python3.8/site-packages/netmiko/base_connection.py", line 884, in establish_connection
    self.remote_conn_pre.connect(**ssh_connect_params)
  File "/home/macaktom/.local/share/virtualenvs/network_automation-NLxdyicX/lib/python3.8/site-packages/paramiko/client.py", line 368, in connect
    raise NoValidConnectionsError(errors)
paramiko.ssh_exception.NoValidConnectionsError: [Errno None] Unable to connect to port 22 on 10.0.0.1

During handling of the above exception, another exception occurred:

Traceback (most recent call last):
  File "/home/macaktom/.local/share/virtualenvs/network_automation-NLxdyicX/lib/python3.8/site-packages/nornir/core/task.py", line 85, in start
    r = self.task(self, **self.params)
  File "/home/macaktom/.local/share/virtualenvs/network_automation-NLxdyicX/lib/python3.8/site-packages/nornir/plugins/tasks/networking/netmiko_send_command.py", line 26, in netmiko_send_command
    net_connect = task.host.get_connection("netmiko", task.nornir.config)
  File "/home/macaktom/.local/share/virtualenvs/network_automation-NLxdyicX/lib/python3.8/site-packages/nornir/core/inventory.py", line 294, in get_connection
    self.open_connection(
  File "/home/macaktom/.local/share/virtualenvs/network_automation-NLxdyicX/lib/python3.8/site-packages/nornir/core/inventory.py", line 345, in open_connection
    self.connections[connection].open(
  File "/home/macaktom/.local/share/virtualenvs/network_automation-NLxdyicX/lib/python3.8/site-packages/nornir/plugins/connections/netmiko.py", line 58, in open
    self.connection = ConnectHandler(**parameters)
  File "/home/macaktom/.local/share/virtualenvs/network_automation-NLxdyicX/lib/python3.8/site-packages/netmiko/ssh_dispatcher.py", line 246, in ConnectHandler
    return ConnectionClass(*args, **kwargs)
  File "/home/macaktom/.local/share/virtualenvs/network_automation-NLxdyicX/lib/python3.8/site-packages/netmiko/base_connection.py", line 317, in __init__
    self._open()
  File "/home/macaktom/.local/share/virtualenvs/network_automation-NLxdyicX/lib/python3.8/site-packages/netmiko/base_connection.py", line 322, in _open
    self.establish_connection()
  File "/home/macaktom/.local/share/virtualenvs/network_automation-NLxdyicX/lib/python3.8/site-packages/netmiko/base_connection.py", line 890, in establish_connection
    raise NetMikoTimeoutException(msg)
netmiko.ssh_exception.NetMikoTimeoutException: Connection to device timed-out: linux 10.0.0.1:22

2020-05-17 19:49:15,534 - nornir.core.task -    ERROR -      start() - Host 'SW2': task 'netmiko_send_command' failed with traceback:
Traceback (most recent call last):
  File "/home/macaktom/.local/share/virtualenvs/network_automation-NLxdyicX/lib/python3.8/site-packages/netmiko/base_connection.py", line 884, in establish_connection
    self.remote_conn_pre.connect(**ssh_connect_params)
  File "/home/macaktom/.local/share/virtualenvs/network_automation-NLxdyicX/lib/python3.8/site-packages/paramiko/client.py", line 368, in connect
    raise NoValidConnectionsError(errors)
paramiko.ssh_exception.NoValidConnectionsError: [Errno None] Unable to connect to port 22 on 10.0.0.4

During handling of the above exception, another exception occurred:

Traceback (most recent call last):
  File "/home/macaktom/.local/share/virtualenvs/network_automation-NLxdyicX/lib/python3.8/site-packages/nornir/core/task.py", line 85, in start
    r = self.task(self, **self.params)
  File "/home/macaktom/.local/share/virtualenvs/network_automation-NLxdyicX/lib/python3.8/site-packages/nornir/plugins/tasks/networking/netmiko_send_command.py", line 26, in netmiko_send_command
    net_connect = task.host.get_connection("netmiko", task.nornir.config)
  File "/home/macaktom/.local/share/virtualenvs/network_automation-NLxdyicX/lib/python3.8/site-packages/nornir/core/inventory.py", line 294, in get_connection
    self.open_connection(
  File "/home/macaktom/.local/share/virtualenvs/network_automation-NLxdyicX/lib/python3.8/site-packages/nornir/core/inventory.py", line 345, in open_connection
    self.connections[connection].open(
  File "/home/macaktom/.local/share/virtualenvs/network_automation-NLxdyicX/lib/python3.8/site-packages/nornir/plugins/connections/netmiko.py", line 58, in open
    self.connection = ConnectHandler(**parameters)
  File "/home/macaktom/.local/share/virtualenvs/network_automation-NLxdyicX/lib/python3.8/site-packages/netmiko/ssh_dispatcher.py", line 246, in ConnectHandler
    return ConnectionClass(*args, **kwargs)
  File "/home/macaktom/.local/share/virtualenvs/network_automation-NLxdyicX/lib/python3.8/site-packages/netmiko/base_connection.py", line 317, in __init__
    self._open()
  File "/home/macaktom/.local/share/virtualenvs/network_automation-NLxdyicX/lib/python3.8/site-packages/netmiko/base_connection.py", line 322, in _open
    self.establish_connection()
  File "/home/macaktom/.local/share/virtualenvs/network_automation-NLxdyicX/lib/python3.8/site-packages/netmiko/base_connection.py", line 890, in establish_connection
    raise NetMikoTimeoutException(msg)
netmiko.ssh_exception.NetMikoTimeoutException: Connection to device timed-out: cisco_ios 10.0.0.4:22

2020-05-17 19:49:15,534 - nornir.core.task -    ERROR -      start() - Host 'SW1': task 'netmiko_send_command' failed with traceback:
Traceback (most recent call last):
  File "/home/macaktom/.local/share/virtualenvs/network_automation-NLxdyicX/lib/python3.8/site-packages/netmiko/base_connection.py", line 884, in establish_connection
    self.remote_conn_pre.connect(**ssh_connect_params)
  File "/home/macaktom/.local/share/virtualenvs/network_automation-NLxdyicX/lib/python3.8/site-packages/paramiko/client.py", line 368, in connect
    raise NoValidConnectionsError(errors)
paramiko.ssh_exception.NoValidConnectionsError: [Errno None] Unable to connect to port 22 on 10.0.0.3

During handling of the above exception, another exception occurred:

Traceback (most recent call last):
  File "/home/macaktom/.local/share/virtualenvs/network_automation-NLxdyicX/lib/python3.8/site-packages/nornir/core/task.py", line 85, in start
    r = self.task(self, **self.params)
  File "/home/macaktom/.local/share/virtualenvs/network_automation-NLxdyicX/lib/python3.8/site-packages/nornir/plugins/tasks/networking/netmiko_send_command.py", line 26, in netmiko_send_command
    net_connect = task.host.get_connection("netmiko", task.nornir.config)
  File "/home/macaktom/.local/share/virtualenvs/network_automation-NLxdyicX/lib/python3.8/site-packages/nornir/core/inventory.py", line 294, in get_connection
    self.open_connection(
  File "/home/macaktom/.local/share/virtualenvs/network_automation-NLxdyicX/lib/python3.8/site-packages/nornir/core/inventory.py", line 345, in open_connection
    self.connections[connection].open(
  File "/home/macaktom/.local/share/virtualenvs/network_automation-NLxdyicX/lib/python3.8/site-packages/nornir/plugins/connections/netmiko.py", line 58, in open
    self.connection = ConnectHandler(**parameters)
  File "/home/macaktom/.local/share/virtualenvs/network_automation-NLxdyicX/lib/python3.8/site-packages/netmiko/ssh_dispatcher.py", line 246, in ConnectHandler
    return ConnectionClass(*args, **kwargs)
  File "/home/macaktom/.local/share/virtualenvs/network_automation-NLxdyicX/lib/python3.8/site-packages/netmiko/base_connection.py", line 317, in __init__
    self._open()
  File "/home/macaktom/.local/share/virtualenvs/network_automation-NLxdyicX/lib/python3.8/site-packages/netmiko/base_connection.py", line 322, in _open
    self.establish_connection()
  File "/home/macaktom/.local/share/virtualenvs/network_automation-NLxdyicX/lib/python3.8/site-packages/netmiko/base_connection.py", line 890, in establish_connection
    raise NetMikoTimeoutException(msg)
netmiko.ssh_exception.NetMikoTimeoutException: Connection to device timed-out: cisco_ios 10.0.0.3:22

2020-05-17 19:49:15,538 - nornir.core.task -    ERROR -      start() - Host 'R1': task 'netmiko_send_command' failed with traceback:
Traceback (most recent call last):
  File "/home/macaktom/.local/share/virtualenvs/network_automation-NLxdyicX/lib/python3.8/site-packages/netmiko/base_connection.py", line 884, in establish_connection
    self.remote_conn_pre.connect(**ssh_connect_params)
  File "/home/macaktom/.local/share/virtualenvs/network_automation-NLxdyicX/lib/python3.8/site-packages/paramiko/client.py", line 368, in connect
    raise NoValidConnectionsError(errors)
paramiko.ssh_exception.NoValidConnectionsError: [Errno None] Unable to connect to port 22 on 10.0.0.2

During handling of the above exception, another exception occurred:

Traceback (most recent call last):
  File "/home/macaktom/.local/share/virtualenvs/network_automation-NLxdyicX/lib/python3.8/site-packages/nornir/core/task.py", line 85, in start
    r = self.task(self, **self.params)
  File "/home/macaktom/.local/share/virtualenvs/network_automation-NLxdyicX/lib/python3.8/site-packages/nornir/plugins/tasks/networking/netmiko_send_command.py", line 26, in netmiko_send_command
    net_connect = task.host.get_connection("netmiko", task.nornir.config)
  File "/home/macaktom/.local/share/virtualenvs/network_automation-NLxdyicX/lib/python3.8/site-packages/nornir/core/inventory.py", line 294, in get_connection
    self.open_connection(
  File "/home/macaktom/.local/share/virtualenvs/network_automation-NLxdyicX/lib/python3.8/site-packages/nornir/core/inventory.py", line 345, in open_connection
    self.connections[connection].open(
  File "/home/macaktom/.local/share/virtualenvs/network_automation-NLxdyicX/lib/python3.8/site-packages/nornir/plugins/connections/netmiko.py", line 58, in open
    self.connection = ConnectHandler(**parameters)
  File "/home/macaktom/.local/share/virtualenvs/network_automation-NLxdyicX/lib/python3.8/site-packages/netmiko/ssh_dispatcher.py", line 246, in ConnectHandler
    return ConnectionClass(*args, **kwargs)
  File "/home/macaktom/.local/share/virtualenvs/network_automation-NLxdyicX/lib/python3.8/site-packages/netmiko/base_connection.py", line 317, in __init__
    self._open()
  File "/home/macaktom/.local/share/virtualenvs/network_automation-NLxdyicX/lib/python3.8/site-packages/netmiko/base_connection.py", line 322, in _open
    self.establish_connection()
  File "/home/macaktom/.local/share/virtualenvs/network_automation-NLxdyicX/lib/python3.8/site-packages/netmiko/base_connection.py", line 890, in establish_connection
    raise NetMikoTimeoutException(msg)
netmiko.ssh_exception.NetMikoTimeoutException: Connection to device timed-out: cisco_ios 10.0.0.2:22

2020-05-17 19:49:15,539 - nornir.core.task -    ERROR -      start() - Host 'SW3': task 'netmiko_send_command' failed with traceback:
Traceback (most recent call last):
  File "/home/macaktom/.local/share/virtualenvs/network_automation-NLxdyicX/lib/python3.8/site-packages/netmiko/base_connection.py", line 884, in establish_connection
    self.remote_conn_pre.connect(**ssh_connect_params)
  File "/home/macaktom/.local/share/virtualenvs/network_automation-NLxdyicX/lib/python3.8/site-packages/paramiko/client.py", line 368, in connect
    raise NoValidConnectionsError(errors)
paramiko.ssh_exception.NoValidConnectionsError: [Errno None] Unable to connect to port 22 on 10.0.0.5

During handling of the above exception, another exception occurred:

Traceback (most recent call last):
  File "/home/macaktom/.local/share/virtualenvs/network_automation-NLxdyicX/lib/python3.8/site-packages/nornir/core/task.py", line 85, in start
    r = self.task(self, **self.params)
  File "/home/macaktom/.local/share/virtualenvs/network_automation-NLxdyicX/lib/python3.8/site-packages/nornir/plugins/tasks/networking/netmiko_send_command.py", line 26, in netmiko_send_command
    net_connect = task.host.get_connection("netmiko", task.nornir.config)
  File "/home/macaktom/.local/share/virtualenvs/network_automation-NLxdyicX/lib/python3.8/site-packages/nornir/core/inventory.py", line 294, in get_connection
    self.open_connection(
  File "/home/macaktom/.local/share/virtualenvs/network_automation-NLxdyicX/lib/python3.8/site-packages/nornir/core/inventory.py", line 345, in open_connection
    self.connections[connection].open(
  File "/home/macaktom/.local/share/virtualenvs/network_automation-NLxdyicX/lib/python3.8/site-packages/nornir/plugins/connections/netmiko.py", line 58, in open
    self.connection = ConnectHandler(**parameters)
  File "/home/macaktom/.local/share/virtualenvs/network_automation-NLxdyicX/lib/python3.8/site-packages/netmiko/ssh_dispatcher.py", line 246, in ConnectHandler
    return ConnectionClass(*args, **kwargs)
  File "/home/macaktom/.local/share/virtualenvs/network_automation-NLxdyicX/lib/python3.8/site-packages/netmiko/base_connection.py", line 317, in __init__
    self._open()
  File "/home/macaktom/.local/share/virtualenvs/network_automation-NLxdyicX/lib/python3.8/site-packages/netmiko/base_connection.py", line 322, in _open
    self.establish_connection()
  File "/home/macaktom/.local/share/virtualenvs/network_automation-NLxdyicX/lib/python3.8/site-packages/netmiko/base_connection.py", line 890, in establish_connection
    raise NetMikoTimeoutException(msg)
netmiko.ssh_exception.NetMikoTimeoutException: Connection to device timed-out: cisco_ios 10.0.0.5:22

2020-05-17 19:49:15,546 - nornir.core.task -    ERROR -      start() - Host 'Client1': task 'netmiko_send_command' failed with traceback:
Traceback (most recent call last):
  File "/home/macaktom/.local/share/virtualenvs/network_automation-NLxdyicX/lib/python3.8/site-packages/netmiko/base_connection.py", line 884, in establish_connection
    self.remote_conn_pre.connect(**ssh_connect_params)
  File "/home/macaktom/.local/share/virtualenvs/network_automation-NLxdyicX/lib/python3.8/site-packages/paramiko/client.py", line 368, in connect
    raise NoValidConnectionsError(errors)
paramiko.ssh_exception.NoValidConnectionsError: [Errno None] Unable to connect to port 22 on 10.0.0.6

During handling of the above exception, another exception occurred:

Traceback (most recent call last):
  File "/home/macaktom/.local/share/virtualenvs/network_automation-NLxdyicX/lib/python3.8/site-packages/nornir/core/task.py", line 85, in start
    r = self.task(self, **self.params)
  File "/home/macaktom/.local/share/virtualenvs/network_automation-NLxdyicX/lib/python3.8/site-packages/nornir/plugins/tasks/networking/netmiko_send_command.py", line 26, in netmiko_send_command
    net_connect = task.host.get_connection("netmiko", task.nornir.config)
  File "/home/macaktom/.local/share/virtualenvs/network_automation-NLxdyicX/lib/python3.8/site-packages/nornir/core/inventory.py", line 294, in get_connection
    self.open_connection(
  File "/home/macaktom/.local/share/virtualenvs/network_automation-NLxdyicX/lib/python3.8/site-packages/nornir/core/inventory.py", line 345, in open_connection
    self.connections[connection].open(
  File "/home/macaktom/.local/share/virtualenvs/network_automation-NLxdyicX/lib/python3.8/site-packages/nornir/plugins/connections/netmiko.py", line 58, in open
    self.connection = ConnectHandler(**parameters)
  File "/home/macaktom/.local/share/virtualenvs/network_automation-NLxdyicX/lib/python3.8/site-packages/netmiko/ssh_dispatcher.py", line 246, in ConnectHandler
    return ConnectionClass(*args, **kwargs)
  File "/home/macaktom/.local/share/virtualenvs/network_automation-NLxdyicX/lib/python3.8/site-packages/netmiko/base_connection.py", line 317, in __init__
    self._open()
  File "/home/macaktom/.local/share/virtualenvs/network_automation-NLxdyicX/lib/python3.8/site-packages/netmiko/base_connection.py", line 322, in _open
    self.establish_connection()
  File "/home/macaktom/.local/share/virtualenvs/network_automation-NLxdyicX/lib/python3.8/site-packages/netmiko/base_connection.py", line 890, in establish_connection
    raise NetMikoTimeoutException(msg)
netmiko.ssh_exception.NetMikoTimeoutException: Connection to device timed-out: linux 10.0.0.6:22

2020-05-17 19:49:15,546 - nornir.core.task -    ERROR -      start() - Host 'Client2': task 'netmiko_send_command' failed with traceback:
Traceback (most recent call last):
  File "/home/macaktom/.local/share/virtualenvs/network_automation-NLxdyicX/lib/python3.8/site-packages/netmiko/base_connection.py", line 884, in establish_connection
    self.remote_conn_pre.connect(**ssh_connect_params)
  File "/home/macaktom/.local/share/virtualenvs/network_automation-NLxdyicX/lib/python3.8/site-packages/paramiko/client.py", line 368, in connect
    raise NoValidConnectionsError(errors)
paramiko.ssh_exception.NoValidConnectionsError: [Errno None] Unable to connect to port 22 on 10.0.0.7

During handling of the above exception, another exception occurred:

Traceback (most recent call last):
  File "/home/macaktom/.local/share/virtualenvs/network_automation-NLxdyicX/lib/python3.8/site-packages/nornir/core/task.py", line 85, in start
    r = self.task(self, **self.params)
  File "/home/macaktom/.local/share/virtualenvs/network_automation-NLxdyicX/lib/python3.8/site-packages/nornir/plugins/tasks/networking/netmiko_send_command.py", line 26, in netmiko_send_command
    net_connect = task.host.get_connection("netmiko", task.nornir.config)
  File "/home/macaktom/.local/share/virtualenvs/network_automation-NLxdyicX/lib/python3.8/site-packages/nornir/core/inventory.py", line 294, in get_connection
    self.open_connection(
  File "/home/macaktom/.local/share/virtualenvs/network_automation-NLxdyicX/lib/python3.8/site-packages/nornir/core/inventory.py", line 345, in open_connection
    self.connections[connection].open(
  File "/home/macaktom/.local/share/virtualenvs/network_automation-NLxdyicX/lib/python3.8/site-packages/nornir/plugins/connections/netmiko.py", line 58, in open
    self.connection = ConnectHandler(**parameters)
  File "/home/macaktom/.local/share/virtualenvs/network_automation-NLxdyicX/lib/python3.8/site-packages/netmiko/ssh_dispatcher.py", line 246, in ConnectHandler
    return ConnectionClass(*args, **kwargs)
  File "/home/macaktom/.local/share/virtualenvs/network_automation-NLxdyicX/lib/python3.8/site-packages/netmiko/base_connection.py", line 317, in __init__
    self._open()
  File "/home/macaktom/.local/share/virtualenvs/network_automation-NLxdyicX/lib/python3.8/site-packages/netmiko/base_connection.py", line 322, in _open
    self.establish_connection()
  File "/home/macaktom/.local/share/virtualenvs/network_automation-NLxdyicX/lib/python3.8/site-packages/netmiko/base_connection.py", line 890, in establish_connection
    raise NetMikoTimeoutException(msg)
netmiko.ssh_exception.NetMikoTimeoutException: Connection to device timed-out: linux 10.0.0.7:22

2020-05-17 20:09:25,999 -  nornir.core -     INFO -        run() - Running task 'netmiko_send_command' with args {'command_string': 'ping 10.0.0.1'} on 7 hosts
2020-05-17 20:09:26,006 - nornir.core.task -    ERROR -      start() - Host 'Automation': task 'netmiko_send_command' failed with traceback:
Traceback (most recent call last):
  File "/home/macaktom/.local/share/virtualenvs/network_automation-NLxdyicX/lib/python3.8/site-packages/netmiko/base_connection.py", line 884, in establish_connection
    self.remote_conn_pre.connect(**ssh_connect_params)
  File "/home/macaktom/.local/share/virtualenvs/network_automation-NLxdyicX/lib/python3.8/site-packages/paramiko/client.py", line 368, in connect
    raise NoValidConnectionsError(errors)
paramiko.ssh_exception.NoValidConnectionsError: [Errno None] Unable to connect to port 22 on 10.0.0.1

During handling of the above exception, another exception occurred:

Traceback (most recent call last):
  File "/home/macaktom/.local/share/virtualenvs/network_automation-NLxdyicX/lib/python3.8/site-packages/nornir/core/task.py", line 85, in start
    r = self.task(self, **self.params)
  File "/home/macaktom/.local/share/virtualenvs/network_automation-NLxdyicX/lib/python3.8/site-packages/nornir/plugins/tasks/networking/netmiko_send_command.py", line 26, in netmiko_send_command
    net_connect = task.host.get_connection("netmiko", task.nornir.config)
  File "/home/macaktom/.local/share/virtualenvs/network_automation-NLxdyicX/lib/python3.8/site-packages/nornir/core/inventory.py", line 294, in get_connection
    self.open_connection(
  File "/home/macaktom/.local/share/virtualenvs/network_automation-NLxdyicX/lib/python3.8/site-packages/nornir/core/inventory.py", line 345, in open_connection
    self.connections[connection].open(
  File "/home/macaktom/.local/share/virtualenvs/network_automation-NLxdyicX/lib/python3.8/site-packages/nornir/plugins/connections/netmiko.py", line 58, in open
    self.connection = ConnectHandler(**parameters)
  File "/home/macaktom/.local/share/virtualenvs/network_automation-NLxdyicX/lib/python3.8/site-packages/netmiko/ssh_dispatcher.py", line 246, in ConnectHandler
    return ConnectionClass(*args, **kwargs)
  File "/home/macaktom/.local/share/virtualenvs/network_automation-NLxdyicX/lib/python3.8/site-packages/netmiko/base_connection.py", line 317, in __init__
    self._open()
  File "/home/macaktom/.local/share/virtualenvs/network_automation-NLxdyicX/lib/python3.8/site-packages/netmiko/base_connection.py", line 322, in _open
    self.establish_connection()
  File "/home/macaktom/.local/share/virtualenvs/network_automation-NLxdyicX/lib/python3.8/site-packages/netmiko/base_connection.py", line 890, in establish_connection
    raise NetMikoTimeoutException(msg)
netmiko.ssh_exception.NetMikoTimeoutException: Connection to device timed-out: linux 10.0.0.1:22

2020-05-17 20:09:26,010 - nornir.core.task -    ERROR -      start() - Host 'Client1': task 'netmiko_send_command' failed with traceback:
Traceback (most recent call last):
  File "/home/macaktom/.local/share/virtualenvs/network_automation-NLxdyicX/lib/python3.8/site-packages/netmiko/base_connection.py", line 884, in establish_connection
    self.remote_conn_pre.connect(**ssh_connect_params)
  File "/home/macaktom/.local/share/virtualenvs/network_automation-NLxdyicX/lib/python3.8/site-packages/paramiko/client.py", line 368, in connect
    raise NoValidConnectionsError(errors)
paramiko.ssh_exception.NoValidConnectionsError: [Errno None] Unable to connect to port 22 on 10.0.0.6

During handling of the above exception, another exception occurred:

Traceback (most recent call last):
  File "/home/macaktom/.local/share/virtualenvs/network_automation-NLxdyicX/lib/python3.8/site-packages/nornir/core/task.py", line 85, in start
    r = self.task(self, **self.params)
  File "/home/macaktom/.local/share/virtualenvs/network_automation-NLxdyicX/lib/python3.8/site-packages/nornir/plugins/tasks/networking/netmiko_send_command.py", line 26, in netmiko_send_command
    net_connect = task.host.get_connection("netmiko", task.nornir.config)
  File "/home/macaktom/.local/share/virtualenvs/network_automation-NLxdyicX/lib/python3.8/site-packages/nornir/core/inventory.py", line 294, in get_connection
    self.open_connection(
  File "/home/macaktom/.local/share/virtualenvs/network_automation-NLxdyicX/lib/python3.8/site-packages/nornir/core/inventory.py", line 345, in open_connection
    self.connections[connection].open(
  File "/home/macaktom/.local/share/virtualenvs/network_automation-NLxdyicX/lib/python3.8/site-packages/nornir/plugins/connections/netmiko.py", line 58, in open
    self.connection = ConnectHandler(**parameters)
  File "/home/macaktom/.local/share/virtualenvs/network_automation-NLxdyicX/lib/python3.8/site-packages/netmiko/ssh_dispatcher.py", line 246, in ConnectHandler
    return ConnectionClass(*args, **kwargs)
  File "/home/macaktom/.local/share/virtualenvs/network_automation-NLxdyicX/lib/python3.8/site-packages/netmiko/base_connection.py", line 317, in __init__
    self._open()
  File "/home/macaktom/.local/share/virtualenvs/network_automation-NLxdyicX/lib/python3.8/site-packages/netmiko/base_connection.py", line 322, in _open
    self.establish_connection()
  File "/home/macaktom/.local/share/virtualenvs/network_automation-NLxdyicX/lib/python3.8/site-packages/netmiko/base_connection.py", line 890, in establish_connection
    raise NetMikoTimeoutException(msg)
netmiko.ssh_exception.NetMikoTimeoutException: Connection to device timed-out: linux 10.0.0.6:22

2020-05-17 20:09:26,012 - nornir.core.task -    ERROR -      start() - Host 'Client2': task 'netmiko_send_command' failed with traceback:
Traceback (most recent call last):
  File "/home/macaktom/.local/share/virtualenvs/network_automation-NLxdyicX/lib/python3.8/site-packages/netmiko/base_connection.py", line 884, in establish_connection
    self.remote_conn_pre.connect(**ssh_connect_params)
  File "/home/macaktom/.local/share/virtualenvs/network_automation-NLxdyicX/lib/python3.8/site-packages/paramiko/client.py", line 368, in connect
    raise NoValidConnectionsError(errors)
paramiko.ssh_exception.NoValidConnectionsError: [Errno None] Unable to connect to port 22 on 10.0.0.7

During handling of the above exception, another exception occurred:

Traceback (most recent call last):
  File "/home/macaktom/.local/share/virtualenvs/network_automation-NLxdyicX/lib/python3.8/site-packages/nornir/core/task.py", line 85, in start
    r = self.task(self, **self.params)
  File "/home/macaktom/.local/share/virtualenvs/network_automation-NLxdyicX/lib/python3.8/site-packages/nornir/plugins/tasks/networking/netmiko_send_command.py", line 26, in netmiko_send_command
    net_connect = task.host.get_connection("netmiko", task.nornir.config)
  File "/home/macaktom/.local/share/virtualenvs/network_automation-NLxdyicX/lib/python3.8/site-packages/nornir/core/inventory.py", line 294, in get_connection
    self.open_connection(
  File "/home/macaktom/.local/share/virtualenvs/network_automation-NLxdyicX/lib/python3.8/site-packages/nornir/core/inventory.py", line 345, in open_connection
    self.connections[connection].open(
  File "/home/macaktom/.local/share/virtualenvs/network_automation-NLxdyicX/lib/python3.8/site-packages/nornir/plugins/connections/netmiko.py", line 58, in open
    self.connection = ConnectHandler(**parameters)
  File "/home/macaktom/.local/share/virtualenvs/network_automation-NLxdyicX/lib/python3.8/site-packages/netmiko/ssh_dispatcher.py", line 246, in ConnectHandler
    return ConnectionClass(*args, **kwargs)
  File "/home/macaktom/.local/share/virtualenvs/network_automation-NLxdyicX/lib/python3.8/site-packages/netmiko/base_connection.py", line 317, in __init__
    self._open()
  File "/home/macaktom/.local/share/virtualenvs/network_automation-NLxdyicX/lib/python3.8/site-packages/netmiko/base_connection.py", line 322, in _open
    self.establish_connection()
  File "/home/macaktom/.local/share/virtualenvs/network_automation-NLxdyicX/lib/python3.8/site-packages/netmiko/base_connection.py", line 890, in establish_connection
    raise NetMikoTimeoutException(msg)
netmiko.ssh_exception.NetMikoTimeoutException: Connection to device timed-out: linux 10.0.0.7:22

2020-05-17 20:14:19,295 -  nornir.core -     INFO -        run() - Running task 'netmiko_send_command' with args {'command_string': 'ping 10.0.0.1'} on 7 hosts
2020-05-17 20:14:19,300 - nornir.core.task -    ERROR -      start() - Host 'Automation': task 'netmiko_send_command' failed with traceback:
Traceback (most recent call last):
  File "/home/macaktom/.local/share/virtualenvs/network_automation-NLxdyicX/lib/python3.8/site-packages/netmiko/base_connection.py", line 884, in establish_connection
    self.remote_conn_pre.connect(**ssh_connect_params)
  File "/home/macaktom/.local/share/virtualenvs/network_automation-NLxdyicX/lib/python3.8/site-packages/paramiko/client.py", line 368, in connect
    raise NoValidConnectionsError(errors)
paramiko.ssh_exception.NoValidConnectionsError: [Errno None] Unable to connect to port 22 on 10.0.0.1

During handling of the above exception, another exception occurred:

Traceback (most recent call last):
  File "/home/macaktom/.local/share/virtualenvs/network_automation-NLxdyicX/lib/python3.8/site-packages/nornir/core/task.py", line 85, in start
    r = self.task(self, **self.params)
  File "/home/macaktom/.local/share/virtualenvs/network_automation-NLxdyicX/lib/python3.8/site-packages/nornir/plugins/tasks/networking/netmiko_send_command.py", line 26, in netmiko_send_command
    net_connect = task.host.get_connection("netmiko", task.nornir.config)
  File "/home/macaktom/.local/share/virtualenvs/network_automation-NLxdyicX/lib/python3.8/site-packages/nornir/core/inventory.py", line 294, in get_connection
    self.open_connection(
  File "/home/macaktom/.local/share/virtualenvs/network_automation-NLxdyicX/lib/python3.8/site-packages/nornir/core/inventory.py", line 345, in open_connection
    self.connections[connection].open(
  File "/home/macaktom/.local/share/virtualenvs/network_automation-NLxdyicX/lib/python3.8/site-packages/nornir/plugins/connections/netmiko.py", line 58, in open
    self.connection = ConnectHandler(**parameters)
  File "/home/macaktom/.local/share/virtualenvs/network_automation-NLxdyicX/lib/python3.8/site-packages/netmiko/ssh_dispatcher.py", line 246, in ConnectHandler
    return ConnectionClass(*args, **kwargs)
  File "/home/macaktom/.local/share/virtualenvs/network_automation-NLxdyicX/lib/python3.8/site-packages/netmiko/base_connection.py", line 317, in __init__
    self._open()
  File "/home/macaktom/.local/share/virtualenvs/network_automation-NLxdyicX/lib/python3.8/site-packages/netmiko/base_connection.py", line 322, in _open
    self.establish_connection()
  File "/home/macaktom/.local/share/virtualenvs/network_automation-NLxdyicX/lib/python3.8/site-packages/netmiko/base_connection.py", line 890, in establish_connection
    raise NetMikoTimeoutException(msg)
netmiko.ssh_exception.NetMikoTimeoutException: Connection to device timed-out: linux 10.0.0.1:22

2020-05-17 20:14:19,307 - nornir.core.task -    ERROR -      start() - Host 'Client2': task 'netmiko_send_command' failed with traceback:
Traceback (most recent call last):
  File "/home/macaktom/.local/share/virtualenvs/network_automation-NLxdyicX/lib/python3.8/site-packages/netmiko/base_connection.py", line 884, in establish_connection
    self.remote_conn_pre.connect(**ssh_connect_params)
  File "/home/macaktom/.local/share/virtualenvs/network_automation-NLxdyicX/lib/python3.8/site-packages/paramiko/client.py", line 368, in connect
    raise NoValidConnectionsError(errors)
paramiko.ssh_exception.NoValidConnectionsError: [Errno None] Unable to connect to port 22 on 10.0.0.7

During handling of the above exception, another exception occurred:

Traceback (most recent call last):
  File "/home/macaktom/.local/share/virtualenvs/network_automation-NLxdyicX/lib/python3.8/site-packages/nornir/core/task.py", line 85, in start
    r = self.task(self, **self.params)
  File "/home/macaktom/.local/share/virtualenvs/network_automation-NLxdyicX/lib/python3.8/site-packages/nornir/plugins/tasks/networking/netmiko_send_command.py", line 26, in netmiko_send_command
    net_connect = task.host.get_connection("netmiko", task.nornir.config)
  File "/home/macaktom/.local/share/virtualenvs/network_automation-NLxdyicX/lib/python3.8/site-packages/nornir/core/inventory.py", line 294, in get_connection
    self.open_connection(
  File "/home/macaktom/.local/share/virtualenvs/network_automation-NLxdyicX/lib/python3.8/site-packages/nornir/core/inventory.py", line 345, in open_connection
    self.connections[connection].open(
  File "/home/macaktom/.local/share/virtualenvs/network_automation-NLxdyicX/lib/python3.8/site-packages/nornir/plugins/connections/netmiko.py", line 58, in open
    self.connection = ConnectHandler(**parameters)
  File "/home/macaktom/.local/share/virtualenvs/network_automation-NLxdyicX/lib/python3.8/site-packages/netmiko/ssh_dispatcher.py", line 246, in ConnectHandler
    return ConnectionClass(*args, **kwargs)
  File "/home/macaktom/.local/share/virtualenvs/network_automation-NLxdyicX/lib/python3.8/site-packages/netmiko/base_connection.py", line 317, in __init__
    self._open()
  File "/home/macaktom/.local/share/virtualenvs/network_automation-NLxdyicX/lib/python3.8/site-packages/netmiko/base_connection.py", line 322, in _open
    self.establish_connection()
  File "/home/macaktom/.local/share/virtualenvs/network_automation-NLxdyicX/lib/python3.8/site-packages/netmiko/base_connection.py", line 890, in establish_connection
    raise NetMikoTimeoutException(msg)
netmiko.ssh_exception.NetMikoTimeoutException: Connection to device timed-out: linux 10.0.0.7:22

2020-05-17 20:14:19,307 - nornir.core.task -    ERROR -      start() - Host 'Client1': task 'netmiko_send_command' failed with traceback:
Traceback (most recent call last):
  File "/home/macaktom/.local/share/virtualenvs/network_automation-NLxdyicX/lib/python3.8/site-packages/netmiko/base_connection.py", line 884, in establish_connection
    self.remote_conn_pre.connect(**ssh_connect_params)
  File "/home/macaktom/.local/share/virtualenvs/network_automation-NLxdyicX/lib/python3.8/site-packages/paramiko/client.py", line 368, in connect
    raise NoValidConnectionsError(errors)
paramiko.ssh_exception.NoValidConnectionsError: [Errno None] Unable to connect to port 22 on 10.0.0.6

During handling of the above exception, another exception occurred:

Traceback (most recent call last):
  File "/home/macaktom/.local/share/virtualenvs/network_automation-NLxdyicX/lib/python3.8/site-packages/nornir/core/task.py", line 85, in start
    r = self.task(self, **self.params)
  File "/home/macaktom/.local/share/virtualenvs/network_automation-NLxdyicX/lib/python3.8/site-packages/nornir/plugins/tasks/networking/netmiko_send_command.py", line 26, in netmiko_send_command
    net_connect = task.host.get_connection("netmiko", task.nornir.config)
  File "/home/macaktom/.local/share/virtualenvs/network_automation-NLxdyicX/lib/python3.8/site-packages/nornir/core/inventory.py", line 294, in get_connection
    self.open_connection(
  File "/home/macaktom/.local/share/virtualenvs/network_automation-NLxdyicX/lib/python3.8/site-packages/nornir/core/inventory.py", line 345, in open_connection
    self.connections[connection].open(
  File "/home/macaktom/.local/share/virtualenvs/network_automation-NLxdyicX/lib/python3.8/site-packages/nornir/plugins/connections/netmiko.py", line 58, in open
    self.connection = ConnectHandler(**parameters)
  File "/home/macaktom/.local/share/virtualenvs/network_automation-NLxdyicX/lib/python3.8/site-packages/netmiko/ssh_dispatcher.py", line 246, in ConnectHandler
    return ConnectionClass(*args, **kwargs)
  File "/home/macaktom/.local/share/virtualenvs/network_automation-NLxdyicX/lib/python3.8/site-packages/netmiko/base_connection.py", line 317, in __init__
    self._open()
  File "/home/macaktom/.local/share/virtualenvs/network_automation-NLxdyicX/lib/python3.8/site-packages/netmiko/base_connection.py", line 322, in _open
    self.establish_connection()
  File "/home/macaktom/.local/share/virtualenvs/network_automation-NLxdyicX/lib/python3.8/site-packages/netmiko/base_connection.py", line 890, in establish_connection
    raise NetMikoTimeoutException(msg)
netmiko.ssh_exception.NetMikoTimeoutException: Connection to device timed-out: linux 10.0.0.6:22

2020-05-17 20:19:51,010 -  nornir.core -     INFO -        run() - Running task 'netmiko_send_command' with args {'command_string': 'ping 10.0.0.1'} on 7 hosts
2020-05-17 20:19:51,043 - nornir.core.task -    ERROR -      start() - Host 'Client2': task 'netmiko_send_command' failed with traceback:
Traceback (most recent call last):
  File "/home/macaktom/.local/share/virtualenvs/network_automation-NLxdyicX/lib/python3.8/site-packages/netmiko/base_connection.py", line 884, in establish_connection
    self.remote_conn_pre.connect(**ssh_connect_params)
  File "/home/macaktom/.local/share/virtualenvs/network_automation-NLxdyicX/lib/python3.8/site-packages/paramiko/client.py", line 368, in connect
    raise NoValidConnectionsError(errors)
paramiko.ssh_exception.NoValidConnectionsError: [Errno None] Unable to connect to port 22 on 10.0.0.7

During handling of the above exception, another exception occurred:

Traceback (most recent call last):
  File "/home/macaktom/.local/share/virtualenvs/network_automation-NLxdyicX/lib/python3.8/site-packages/nornir/core/task.py", line 85, in start
    r = self.task(self, **self.params)
  File "/home/macaktom/.local/share/virtualenvs/network_automation-NLxdyicX/lib/python3.8/site-packages/nornir/plugins/tasks/networking/netmiko_send_command.py", line 26, in netmiko_send_command
    net_connect = task.host.get_connection("netmiko", task.nornir.config)
  File "/home/macaktom/.local/share/virtualenvs/network_automation-NLxdyicX/lib/python3.8/site-packages/nornir/core/inventory.py", line 294, in get_connection
    self.open_connection(
  File "/home/macaktom/.local/share/virtualenvs/network_automation-NLxdyicX/lib/python3.8/site-packages/nornir/core/inventory.py", line 345, in open_connection
    self.connections[connection].open(
  File "/home/macaktom/.local/share/virtualenvs/network_automation-NLxdyicX/lib/python3.8/site-packages/nornir/plugins/connections/netmiko.py", line 58, in open
    self.connection = ConnectHandler(**parameters)
  File "/home/macaktom/.local/share/virtualenvs/network_automation-NLxdyicX/lib/python3.8/site-packages/netmiko/ssh_dispatcher.py", line 246, in ConnectHandler
    return ConnectionClass(*args, **kwargs)
  File "/home/macaktom/.local/share/virtualenvs/network_automation-NLxdyicX/lib/python3.8/site-packages/netmiko/base_connection.py", line 317, in __init__
    self._open()
  File "/home/macaktom/.local/share/virtualenvs/network_automation-NLxdyicX/lib/python3.8/site-packages/netmiko/base_connection.py", line 322, in _open
    self.establish_connection()
  File "/home/macaktom/.local/share/virtualenvs/network_automation-NLxdyicX/lib/python3.8/site-packages/netmiko/base_connection.py", line 890, in establish_connection
    raise NetMikoTimeoutException(msg)
netmiko.ssh_exception.NetMikoTimeoutException: Connection to device timed-out: linux 10.0.0.7:22

2020-05-17 20:19:51,043 - nornir.core.task -    ERROR -      start() - Host 'Client1': task 'netmiko_send_command' failed with traceback:
Traceback (most recent call last):
  File "/home/macaktom/.local/share/virtualenvs/network_automation-NLxdyicX/lib/python3.8/site-packages/netmiko/base_connection.py", line 884, in establish_connection
    self.remote_conn_pre.connect(**ssh_connect_params)
  File "/home/macaktom/.local/share/virtualenvs/network_automation-NLxdyicX/lib/python3.8/site-packages/paramiko/client.py", line 368, in connect
    raise NoValidConnectionsError(errors)
paramiko.ssh_exception.NoValidConnectionsError: [Errno None] Unable to connect to port 22 on 10.0.0.6

During handling of the above exception, another exception occurred:

Traceback (most recent call last):
  File "/home/macaktom/.local/share/virtualenvs/network_automation-NLxdyicX/lib/python3.8/site-packages/nornir/core/task.py", line 85, in start
    r = self.task(self, **self.params)
  File "/home/macaktom/.local/share/virtualenvs/network_automation-NLxdyicX/lib/python3.8/site-packages/nornir/plugins/tasks/networking/netmiko_send_command.py", line 26, in netmiko_send_command
    net_connect = task.host.get_connection("netmiko", task.nornir.config)
  File "/home/macaktom/.local/share/virtualenvs/network_automation-NLxdyicX/lib/python3.8/site-packages/nornir/core/inventory.py", line 294, in get_connection
    self.open_connection(
  File "/home/macaktom/.local/share/virtualenvs/network_automation-NLxdyicX/lib/python3.8/site-packages/nornir/core/inventory.py", line 345, in open_connection
    self.connections[connection].open(
  File "/home/macaktom/.local/share/virtualenvs/network_automation-NLxdyicX/lib/python3.8/site-packages/nornir/plugins/connections/netmiko.py", line 58, in open
    self.connection = ConnectHandler(**parameters)
  File "/home/macaktom/.local/share/virtualenvs/network_automation-NLxdyicX/lib/python3.8/site-packages/netmiko/ssh_dispatcher.py", line 246, in ConnectHandler
    return ConnectionClass(*args, **kwargs)
  File "/home/macaktom/.local/share/virtualenvs/network_automation-NLxdyicX/lib/python3.8/site-packages/netmiko/base_connection.py", line 317, in __init__
    self._open()
  File "/home/macaktom/.local/share/virtualenvs/network_automation-NLxdyicX/lib/python3.8/site-packages/netmiko/base_connection.py", line 322, in _open
    self.establish_connection()
  File "/home/macaktom/.local/share/virtualenvs/network_automation-NLxdyicX/lib/python3.8/site-packages/netmiko/base_connection.py", line 890, in establish_connection
    raise NetMikoTimeoutException(msg)
netmiko.ssh_exception.NetMikoTimeoutException: Connection to device timed-out: linux 10.0.0.6:22

2020-05-17 20:21:35,874 - nornir.core.task -    ERROR -      start() - Host 'Automation': task 'netmiko_send_command' failed with traceback:
Traceback (most recent call last):
  File "/home/macaktom/.local/share/virtualenvs/network_automation-NLxdyicX/lib/python3.8/site-packages/nornir/core/task.py", line 85, in start
    r = self.task(self, **self.params)
  File "/home/macaktom/.local/share/virtualenvs/network_automation-NLxdyicX/lib/python3.8/site-packages/nornir/plugins/tasks/networking/netmiko_send_command.py", line 32, in netmiko_send_command
    result = net_connect.send_command(command_string, **kwargs)
  File "/home/macaktom/.local/share/virtualenvs/network_automation-NLxdyicX/lib/python3.8/site-packages/netmiko/base_connection.py", line 1335, in send_command
    raise IOError(
OSError: Search pattern never detected in send_command_expect: macaktom@macaktom:\~\$

2020-05-17 20:48:47,638 -  nornir.core -     INFO -        run() - Running task 'netmiko_send_config' with args {'config_commands': ['ping 10.0.0.1']} on 7 hosts
2020-05-17 20:48:47,748 - nornir.core.task -    ERROR -      start() - Host 'Client1': task 'netmiko_send_config' failed with traceback:
Traceback (most recent call last):
  File "/home/macaktom/.local/share/virtualenvs/network_automation-NLxdyicX/lib/python3.8/site-packages/netmiko/base_connection.py", line 884, in establish_connection
    self.remote_conn_pre.connect(**ssh_connect_params)
  File "/home/macaktom/.local/share/virtualenvs/network_automation-NLxdyicX/lib/python3.8/site-packages/paramiko/client.py", line 368, in connect
    raise NoValidConnectionsError(errors)
paramiko.ssh_exception.NoValidConnectionsError: [Errno None] Unable to connect to port 22 on 10.0.0.6

During handling of the above exception, another exception occurred:

Traceback (most recent call last):
  File "/home/macaktom/.local/share/virtualenvs/network_automation-NLxdyicX/lib/python3.8/site-packages/nornir/core/task.py", line 85, in start
    r = self.task(self, **self.params)
  File "/home/macaktom/.local/share/virtualenvs/network_automation-NLxdyicX/lib/python3.8/site-packages/nornir/plugins/tasks/networking/netmiko_send_config.py", line 24, in netmiko_send_config
    net_connect = task.host.get_connection("netmiko", task.nornir.config)
  File "/home/macaktom/.local/share/virtualenvs/network_automation-NLxdyicX/lib/python3.8/site-packages/nornir/core/inventory.py", line 294, in get_connection
    self.open_connection(
  File "/home/macaktom/.local/share/virtualenvs/network_automation-NLxdyicX/lib/python3.8/site-packages/nornir/core/inventory.py", line 345, in open_connection
    self.connections[connection].open(
  File "/home/macaktom/.local/share/virtualenvs/network_automation-NLxdyicX/lib/python3.8/site-packages/nornir/plugins/connections/netmiko.py", line 58, in open
    self.connection = ConnectHandler(**parameters)
  File "/home/macaktom/.local/share/virtualenvs/network_automation-NLxdyicX/lib/python3.8/site-packages/netmiko/ssh_dispatcher.py", line 246, in ConnectHandler
    return ConnectionClass(*args, **kwargs)
  File "/home/macaktom/.local/share/virtualenvs/network_automation-NLxdyicX/lib/python3.8/site-packages/netmiko/base_connection.py", line 317, in __init__
    self._open()
  File "/home/macaktom/.local/share/virtualenvs/network_automation-NLxdyicX/lib/python3.8/site-packages/netmiko/base_connection.py", line 322, in _open
    self.establish_connection()
  File "/home/macaktom/.local/share/virtualenvs/network_automation-NLxdyicX/lib/python3.8/site-packages/netmiko/base_connection.py", line 890, in establish_connection
    raise NetMikoTimeoutException(msg)
netmiko.ssh_exception.NetMikoTimeoutException: Connection to device timed-out: linux 10.0.0.6:22

2020-05-17 20:48:47,751 - nornir.core.task -    ERROR -      start() - Host 'Client2': task 'netmiko_send_config' failed with traceback:
Traceback (most recent call last):
  File "/home/macaktom/.local/share/virtualenvs/network_automation-NLxdyicX/lib/python3.8/site-packages/netmiko/base_connection.py", line 884, in establish_connection
    self.remote_conn_pre.connect(**ssh_connect_params)
  File "/home/macaktom/.local/share/virtualenvs/network_automation-NLxdyicX/lib/python3.8/site-packages/paramiko/client.py", line 368, in connect
    raise NoValidConnectionsError(errors)
paramiko.ssh_exception.NoValidConnectionsError: [Errno None] Unable to connect to port 22 on 10.0.0.7

During handling of the above exception, another exception occurred:

Traceback (most recent call last):
  File "/home/macaktom/.local/share/virtualenvs/network_automation-NLxdyicX/lib/python3.8/site-packages/nornir/core/task.py", line 85, in start
    r = self.task(self, **self.params)
  File "/home/macaktom/.local/share/virtualenvs/network_automation-NLxdyicX/lib/python3.8/site-packages/nornir/plugins/tasks/networking/netmiko_send_config.py", line 24, in netmiko_send_config
    net_connect = task.host.get_connection("netmiko", task.nornir.config)
  File "/home/macaktom/.local/share/virtualenvs/network_automation-NLxdyicX/lib/python3.8/site-packages/nornir/core/inventory.py", line 294, in get_connection
    self.open_connection(
  File "/home/macaktom/.local/share/virtualenvs/network_automation-NLxdyicX/lib/python3.8/site-packages/nornir/core/inventory.py", line 345, in open_connection
    self.connections[connection].open(
  File "/home/macaktom/.local/share/virtualenvs/network_automation-NLxdyicX/lib/python3.8/site-packages/nornir/plugins/connections/netmiko.py", line 58, in open
    self.connection = ConnectHandler(**parameters)
  File "/home/macaktom/.local/share/virtualenvs/network_automation-NLxdyicX/lib/python3.8/site-packages/netmiko/ssh_dispatcher.py", line 246, in ConnectHandler
    return ConnectionClass(*args, **kwargs)
  File "/home/macaktom/.local/share/virtualenvs/network_automation-NLxdyicX/lib/python3.8/site-packages/netmiko/base_connection.py", line 317, in __init__
    self._open()
  File "/home/macaktom/.local/share/virtualenvs/network_automation-NLxdyicX/lib/python3.8/site-packages/netmiko/base_connection.py", line 322, in _open
    self.establish_connection()
  File "/home/macaktom/.local/share/virtualenvs/network_automation-NLxdyicX/lib/python3.8/site-packages/netmiko/base_connection.py", line 890, in establish_connection
    raise NetMikoTimeoutException(msg)
netmiko.ssh_exception.NetMikoTimeoutException: Connection to device timed-out: linux 10.0.0.7:22

2020-05-17 20:48:52,951 - nornir.core.task -    ERROR -      start() - Host 'SW1': task 'netmiko_send_config' failed with traceback:
Traceback (most recent call last):
  File "/home/macaktom/.local/share/virtualenvs/network_automation-NLxdyicX/lib/python3.8/site-packages/nornir/core/task.py", line 85, in start
    r = self.task(self, **self.params)
  File "/home/macaktom/.local/share/virtualenvs/network_automation-NLxdyicX/lib/python3.8/site-packages/nornir/plugins/tasks/networking/netmiko_send_config.py", line 25, in netmiko_send_config
    net_connect.enable()
  File "/home/macaktom/.local/share/virtualenvs/network_automation-NLxdyicX/lib/python3.8/site-packages/netmiko/cisco_base_connection.py", line 21, in enable
    return super(CiscoBaseConnection, self).enable(
  File "/home/macaktom/.local/share/virtualenvs/network_automation-NLxdyicX/lib/python3.8/site-packages/netmiko/base_connection.py", line 1470, in enable
    raise ValueError(msg)
ValueError: Failed to enter enable mode. Please ensure you pass the 'secret' argument to ConnectHandler.

2020-05-17 20:48:53,015 - nornir.core.task -    ERROR -      start() - Host 'SW3': task 'netmiko_send_config' failed with traceback:
Traceback (most recent call last):
  File "/home/macaktom/.local/share/virtualenvs/network_automation-NLxdyicX/lib/python3.8/site-packages/nornir/core/task.py", line 85, in start
    r = self.task(self, **self.params)
  File "/home/macaktom/.local/share/virtualenvs/network_automation-NLxdyicX/lib/python3.8/site-packages/nornir/plugins/tasks/networking/netmiko_send_config.py", line 25, in netmiko_send_config
    net_connect.enable()
  File "/home/macaktom/.local/share/virtualenvs/network_automation-NLxdyicX/lib/python3.8/site-packages/netmiko/cisco_base_connection.py", line 21, in enable
    return super(CiscoBaseConnection, self).enable(
  File "/home/macaktom/.local/share/virtualenvs/network_automation-NLxdyicX/lib/python3.8/site-packages/netmiko/base_connection.py", line 1470, in enable
    raise ValueError(msg)
ValueError: Failed to enter enable mode. Please ensure you pass the 'secret' argument to ConnectHandler.

2020-05-17 20:48:53,016 - nornir.core.task -    ERROR -      start() - Host 'R1': task 'netmiko_send_config' failed with traceback:
Traceback (most recent call last):
  File "/home/macaktom/.local/share/virtualenvs/network_automation-NLxdyicX/lib/python3.8/site-packages/nornir/core/task.py", line 85, in start
    r = self.task(self, **self.params)
  File "/home/macaktom/.local/share/virtualenvs/network_automation-NLxdyicX/lib/python3.8/site-packages/nornir/plugins/tasks/networking/netmiko_send_config.py", line 25, in netmiko_send_config
    net_connect.enable()
  File "/home/macaktom/.local/share/virtualenvs/network_automation-NLxdyicX/lib/python3.8/site-packages/netmiko/cisco_base_connection.py", line 21, in enable
    return super(CiscoBaseConnection, self).enable(
  File "/home/macaktom/.local/share/virtualenvs/network_automation-NLxdyicX/lib/python3.8/site-packages/netmiko/base_connection.py", line 1470, in enable
    raise ValueError(msg)
ValueError: Failed to enter enable mode. Please ensure you pass the 'secret' argument to ConnectHandler.

2020-05-17 20:48:53,043 - nornir.core.task -    ERROR -      start() - Host 'SW2': task 'netmiko_send_config' failed with traceback:
Traceback (most recent call last):
  File "/home/macaktom/.local/share/virtualenvs/network_automation-NLxdyicX/lib/python3.8/site-packages/nornir/core/task.py", line 85, in start
    r = self.task(self, **self.params)
  File "/home/macaktom/.local/share/virtualenvs/network_automation-NLxdyicX/lib/python3.8/site-packages/nornir/plugins/tasks/networking/netmiko_send_config.py", line 25, in netmiko_send_config
    net_connect.enable()
  File "/home/macaktom/.local/share/virtualenvs/network_automation-NLxdyicX/lib/python3.8/site-packages/netmiko/cisco_base_connection.py", line 21, in enable
    return super(CiscoBaseConnection, self).enable(
  File "/home/macaktom/.local/share/virtualenvs/network_automation-NLxdyicX/lib/python3.8/site-packages/netmiko/base_connection.py", line 1470, in enable
    raise ValueError(msg)
ValueError: Failed to enter enable mode. Please ensure you pass the 'secret' argument to ConnectHandler.

2020-05-17 20:48:53,484 - nornir.core.task -    ERROR -      start() - Host 'Automation': task 'netmiko_send_config' failed with traceback:
Traceback (most recent call last):
  File "/home/macaktom/.local/share/virtualenvs/network_automation-NLxdyicX/lib/python3.8/site-packages/nornir/core/task.py", line 85, in start
    r = self.task(self, **self.params)
  File "/home/macaktom/.local/share/virtualenvs/network_automation-NLxdyicX/lib/python3.8/site-packages/nornir/plugins/tasks/networking/netmiko_send_config.py", line 25, in netmiko_send_config
    net_connect.enable()
  File "/home/macaktom/.local/share/virtualenvs/network_automation-NLxdyicX/lib/python3.8/site-packages/netmiko/linux/linux_ssh.py", line 94, in enable
    self.set_base_prompt()
  File "/home/macaktom/.local/share/virtualenvs/network_automation-NLxdyicX/lib/python3.8/site-packages/netmiko/linux/linux_ssh.py", line 42, in set_base_prompt
    return super(LinuxSSH, self).set_base_prompt(
  File "/home/macaktom/.local/share/virtualenvs/network_automation-NLxdyicX/lib/python3.8/site-packages/netmiko/base_connection.py", line 1066, in set_base_prompt
    prompt = self.find_prompt(delay_factor=delay_factor)
  File "/home/macaktom/.local/share/virtualenvs/network_automation-NLxdyicX/lib/python3.8/site-packages/netmiko/base_connection.py", line 1107, in find_prompt
    raise ValueError("Unable to find prompt: {}".format(prompt))
ValueError: Unable to find prompt: 

2020-05-17 20:53:18,044 -  nornir.core -     INFO -        run() - Running task 'netmiko_send_config' with args {'config_commands': ['do ping 10.0.0.1']} on 7 hosts
2020-05-17 20:53:18,070 - nornir.core.task -    ERROR -      start() - Host 'Client1': task 'netmiko_send_config' failed with traceback:
Traceback (most recent call last):
  File "/home/macaktom/.local/share/virtualenvs/network_automation-NLxdyicX/lib/python3.8/site-packages/netmiko/base_connection.py", line 884, in establish_connection
    self.remote_conn_pre.connect(**ssh_connect_params)
  File "/home/macaktom/.local/share/virtualenvs/network_automation-NLxdyicX/lib/python3.8/site-packages/paramiko/client.py", line 368, in connect
    raise NoValidConnectionsError(errors)
paramiko.ssh_exception.NoValidConnectionsError: [Errno None] Unable to connect to port 22 on 10.0.0.6

During handling of the above exception, another exception occurred:

Traceback (most recent call last):
  File "/home/macaktom/.local/share/virtualenvs/network_automation-NLxdyicX/lib/python3.8/site-packages/nornir/core/task.py", line 85, in start
    r = self.task(self, **self.params)
  File "/home/macaktom/.local/share/virtualenvs/network_automation-NLxdyicX/lib/python3.8/site-packages/nornir/plugins/tasks/networking/netmiko_send_config.py", line 24, in netmiko_send_config
    net_connect = task.host.get_connection("netmiko", task.nornir.config)
  File "/home/macaktom/.local/share/virtualenvs/network_automation-NLxdyicX/lib/python3.8/site-packages/nornir/core/inventory.py", line 294, in get_connection
    self.open_connection(
  File "/home/macaktom/.local/share/virtualenvs/network_automation-NLxdyicX/lib/python3.8/site-packages/nornir/core/inventory.py", line 345, in open_connection
    self.connections[connection].open(
  File "/home/macaktom/.local/share/virtualenvs/network_automation-NLxdyicX/lib/python3.8/site-packages/nornir/plugins/connections/netmiko.py", line 58, in open
    self.connection = ConnectHandler(**parameters)
  File "/home/macaktom/.local/share/virtualenvs/network_automation-NLxdyicX/lib/python3.8/site-packages/netmiko/ssh_dispatcher.py", line 246, in ConnectHandler
    return ConnectionClass(*args, **kwargs)
  File "/home/macaktom/.local/share/virtualenvs/network_automation-NLxdyicX/lib/python3.8/site-packages/netmiko/base_connection.py", line 317, in __init__
    self._open()
  File "/home/macaktom/.local/share/virtualenvs/network_automation-NLxdyicX/lib/python3.8/site-packages/netmiko/base_connection.py", line 322, in _open
    self.establish_connection()
  File "/home/macaktom/.local/share/virtualenvs/network_automation-NLxdyicX/lib/python3.8/site-packages/netmiko/base_connection.py", line 890, in establish_connection
    raise NetMikoTimeoutException(msg)
netmiko.ssh_exception.NetMikoTimeoutException: Connection to device timed-out: linux 10.0.0.6:22

2020-05-17 20:53:18,070 - nornir.core.task -    ERROR -      start() - Host 'Client2': task 'netmiko_send_config' failed with traceback:
Traceback (most recent call last):
  File "/home/macaktom/.local/share/virtualenvs/network_automation-NLxdyicX/lib/python3.8/site-packages/netmiko/base_connection.py", line 884, in establish_connection
    self.remote_conn_pre.connect(**ssh_connect_params)
  File "/home/macaktom/.local/share/virtualenvs/network_automation-NLxdyicX/lib/python3.8/site-packages/paramiko/client.py", line 368, in connect
    raise NoValidConnectionsError(errors)
paramiko.ssh_exception.NoValidConnectionsError: [Errno None] Unable to connect to port 22 on 10.0.0.7

During handling of the above exception, another exception occurred:

Traceback (most recent call last):
  File "/home/macaktom/.local/share/virtualenvs/network_automation-NLxdyicX/lib/python3.8/site-packages/nornir/core/task.py", line 85, in start
    r = self.task(self, **self.params)
  File "/home/macaktom/.local/share/virtualenvs/network_automation-NLxdyicX/lib/python3.8/site-packages/nornir/plugins/tasks/networking/netmiko_send_config.py", line 24, in netmiko_send_config
    net_connect = task.host.get_connection("netmiko", task.nornir.config)
  File "/home/macaktom/.local/share/virtualenvs/network_automation-NLxdyicX/lib/python3.8/site-packages/nornir/core/inventory.py", line 294, in get_connection
    self.open_connection(
  File "/home/macaktom/.local/share/virtualenvs/network_automation-NLxdyicX/lib/python3.8/site-packages/nornir/core/inventory.py", line 345, in open_connection
    self.connections[connection].open(
  File "/home/macaktom/.local/share/virtualenvs/network_automation-NLxdyicX/lib/python3.8/site-packages/nornir/plugins/connections/netmiko.py", line 58, in open
    self.connection = ConnectHandler(**parameters)
  File "/home/macaktom/.local/share/virtualenvs/network_automation-NLxdyicX/lib/python3.8/site-packages/netmiko/ssh_dispatcher.py", line 246, in ConnectHandler
    return ConnectionClass(*args, **kwargs)
  File "/home/macaktom/.local/share/virtualenvs/network_automation-NLxdyicX/lib/python3.8/site-packages/netmiko/base_connection.py", line 317, in __init__
    self._open()
  File "/home/macaktom/.local/share/virtualenvs/network_automation-NLxdyicX/lib/python3.8/site-packages/netmiko/base_connection.py", line 322, in _open
    self.establish_connection()
  File "/home/macaktom/.local/share/virtualenvs/network_automation-NLxdyicX/lib/python3.8/site-packages/netmiko/base_connection.py", line 890, in establish_connection
    raise NetMikoTimeoutException(msg)
netmiko.ssh_exception.NetMikoTimeoutException: Connection to device timed-out: linux 10.0.0.7:22

2020-05-17 20:53:23,118 - nornir.core.task -    ERROR -      start() - Host 'SW1': task 'netmiko_send_config' failed with traceback:
Traceback (most recent call last):
  File "/home/macaktom/.local/share/virtualenvs/network_automation-NLxdyicX/lib/python3.8/site-packages/nornir/core/task.py", line 85, in start
    r = self.task(self, **self.params)
  File "/home/macaktom/.local/share/virtualenvs/network_automation-NLxdyicX/lib/python3.8/site-packages/nornir/plugins/tasks/networking/netmiko_send_config.py", line 25, in netmiko_send_config
    net_connect.enable()
  File "/home/macaktom/.local/share/virtualenvs/network_automation-NLxdyicX/lib/python3.8/site-packages/netmiko/cisco_base_connection.py", line 21, in enable
    return super(CiscoBaseConnection, self).enable(
  File "/home/macaktom/.local/share/virtualenvs/network_automation-NLxdyicX/lib/python3.8/site-packages/netmiko/base_connection.py", line 1470, in enable
    raise ValueError(msg)
ValueError: Failed to enter enable mode. Please ensure you pass the 'secret' argument to ConnectHandler.

2020-05-17 20:53:23,121 - nornir.core.task -    ERROR -      start() - Host 'SW2': task 'netmiko_send_config' failed with traceback:
Traceback (most recent call last):
  File "/home/macaktom/.local/share/virtualenvs/network_automation-NLxdyicX/lib/python3.8/site-packages/nornir/core/task.py", line 85, in start
    r = self.task(self, **self.params)
  File "/home/macaktom/.local/share/virtualenvs/network_automation-NLxdyicX/lib/python3.8/site-packages/nornir/plugins/tasks/networking/netmiko_send_config.py", line 25, in netmiko_send_config
    net_connect.enable()
  File "/home/macaktom/.local/share/virtualenvs/network_automation-NLxdyicX/lib/python3.8/site-packages/netmiko/cisco_base_connection.py", line 21, in enable
    return super(CiscoBaseConnection, self).enable(
  File "/home/macaktom/.local/share/virtualenvs/network_automation-NLxdyicX/lib/python3.8/site-packages/netmiko/base_connection.py", line 1470, in enable
    raise ValueError(msg)
ValueError: Failed to enter enable mode. Please ensure you pass the 'secret' argument to ConnectHandler.

2020-05-17 20:53:23,293 - nornir.core.task -    ERROR -      start() - Host 'SW3': task 'netmiko_send_config' failed with traceback:
Traceback (most recent call last):
  File "/home/macaktom/.local/share/virtualenvs/network_automation-NLxdyicX/lib/python3.8/site-packages/nornir/core/task.py", line 85, in start
    r = self.task(self, **self.params)
  File "/home/macaktom/.local/share/virtualenvs/network_automation-NLxdyicX/lib/python3.8/site-packages/nornir/plugins/tasks/networking/netmiko_send_config.py", line 25, in netmiko_send_config
    net_connect.enable()
  File "/home/macaktom/.local/share/virtualenvs/network_automation-NLxdyicX/lib/python3.8/site-packages/netmiko/cisco_base_connection.py", line 21, in enable
    return super(CiscoBaseConnection, self).enable(
  File "/home/macaktom/.local/share/virtualenvs/network_automation-NLxdyicX/lib/python3.8/site-packages/netmiko/base_connection.py", line 1470, in enable
    raise ValueError(msg)
ValueError: Failed to enter enable mode. Please ensure you pass the 'secret' argument to ConnectHandler.

2020-05-17 20:53:23,315 - nornir.core.task -    ERROR -      start() - Host 'R1': task 'netmiko_send_config' failed with traceback:
Traceback (most recent call last):
  File "/home/macaktom/.local/share/virtualenvs/network_automation-NLxdyicX/lib/python3.8/site-packages/nornir/core/task.py", line 85, in start
    r = self.task(self, **self.params)
  File "/home/macaktom/.local/share/virtualenvs/network_automation-NLxdyicX/lib/python3.8/site-packages/nornir/plugins/tasks/networking/netmiko_send_config.py", line 25, in netmiko_send_config
    net_connect.enable()
  File "/home/macaktom/.local/share/virtualenvs/network_automation-NLxdyicX/lib/python3.8/site-packages/netmiko/cisco_base_connection.py", line 21, in enable
    return super(CiscoBaseConnection, self).enable(
  File "/home/macaktom/.local/share/virtualenvs/network_automation-NLxdyicX/lib/python3.8/site-packages/netmiko/base_connection.py", line 1470, in enable
    raise ValueError(msg)
ValueError: Failed to enter enable mode. Please ensure you pass the 'secret' argument to ConnectHandler.

2020-05-17 20:53:23,673 - nornir.core.task -    ERROR -      start() - Host 'Automation': task 'netmiko_send_config' failed with traceback:
Traceback (most recent call last):
  File "/home/macaktom/.local/share/virtualenvs/network_automation-NLxdyicX/lib/python3.8/site-packages/nornir/core/task.py", line 85, in start
    r = self.task(self, **self.params)
  File "/home/macaktom/.local/share/virtualenvs/network_automation-NLxdyicX/lib/python3.8/site-packages/nornir/plugins/tasks/networking/netmiko_send_config.py", line 25, in netmiko_send_config
    net_connect.enable()
  File "/home/macaktom/.local/share/virtualenvs/network_automation-NLxdyicX/lib/python3.8/site-packages/netmiko/linux/linux_ssh.py", line 94, in enable
    self.set_base_prompt()
  File "/home/macaktom/.local/share/virtualenvs/network_automation-NLxdyicX/lib/python3.8/site-packages/netmiko/linux/linux_ssh.py", line 42, in set_base_prompt
    return super(LinuxSSH, self).set_base_prompt(
  File "/home/macaktom/.local/share/virtualenvs/network_automation-NLxdyicX/lib/python3.8/site-packages/netmiko/base_connection.py", line 1066, in set_base_prompt
    prompt = self.find_prompt(delay_factor=delay_factor)
  File "/home/macaktom/.local/share/virtualenvs/network_automation-NLxdyicX/lib/python3.8/site-packages/netmiko/base_connection.py", line 1107, in find_prompt
    raise ValueError("Unable to find prompt: {}".format(prompt))
ValueError: Unable to find prompt: 

2020-05-17 20:59:45,215 -  nornir.core -     INFO -        run() - Running task 'netmiko_send_command' with args {'command_string': 'ping 10.0.0.1', 'enable': True, 'use_timing': True} on 7 hosts
2020-05-17 20:59:45,234 - nornir.core.task -    ERROR -      start() - Host 'Client1': task 'netmiko_send_command' failed with traceback:
Traceback (most recent call last):
  File "/home/macaktom/.local/share/virtualenvs/network_automation-NLxdyicX/lib/python3.8/site-packages/netmiko/base_connection.py", line 884, in establish_connection
    self.remote_conn_pre.connect(**ssh_connect_params)
  File "/home/macaktom/.local/share/virtualenvs/network_automation-NLxdyicX/lib/python3.8/site-packages/paramiko/client.py", line 368, in connect
    raise NoValidConnectionsError(errors)
paramiko.ssh_exception.NoValidConnectionsError: [Errno None] Unable to connect to port 22 on 10.0.0.6

During handling of the above exception, another exception occurred:

Traceback (most recent call last):
  File "/home/macaktom/.local/share/virtualenvs/network_automation-NLxdyicX/lib/python3.8/site-packages/nornir/core/task.py", line 85, in start
    r = self.task(self, **self.params)
  File "/home/macaktom/.local/share/virtualenvs/network_automation-NLxdyicX/lib/python3.8/site-packages/nornir/plugins/tasks/networking/netmiko_send_command.py", line 26, in netmiko_send_command
    net_connect = task.host.get_connection("netmiko", task.nornir.config)
  File "/home/macaktom/.local/share/virtualenvs/network_automation-NLxdyicX/lib/python3.8/site-packages/nornir/core/inventory.py", line 294, in get_connection
    self.open_connection(
  File "/home/macaktom/.local/share/virtualenvs/network_automation-NLxdyicX/lib/python3.8/site-packages/nornir/core/inventory.py", line 345, in open_connection
    self.connections[connection].open(
  File "/home/macaktom/.local/share/virtualenvs/network_automation-NLxdyicX/lib/python3.8/site-packages/nornir/plugins/connections/netmiko.py", line 58, in open
    self.connection = ConnectHandler(**parameters)
  File "/home/macaktom/.local/share/virtualenvs/network_automation-NLxdyicX/lib/python3.8/site-packages/netmiko/ssh_dispatcher.py", line 246, in ConnectHandler
    return ConnectionClass(*args, **kwargs)
  File "/home/macaktom/.local/share/virtualenvs/network_automation-NLxdyicX/lib/python3.8/site-packages/netmiko/base_connection.py", line 317, in __init__
    self._open()
  File "/home/macaktom/.local/share/virtualenvs/network_automation-NLxdyicX/lib/python3.8/site-packages/netmiko/base_connection.py", line 322, in _open
    self.establish_connection()
  File "/home/macaktom/.local/share/virtualenvs/network_automation-NLxdyicX/lib/python3.8/site-packages/netmiko/base_connection.py", line 890, in establish_connection
    raise NetMikoTimeoutException(msg)
netmiko.ssh_exception.NetMikoTimeoutException: Connection to device timed-out: linux 10.0.0.6:22

2020-05-17 20:59:45,237 - nornir.core.task -    ERROR -      start() - Host 'Client2': task 'netmiko_send_command' failed with traceback:
Traceback (most recent call last):
  File "/home/macaktom/.local/share/virtualenvs/network_automation-NLxdyicX/lib/python3.8/site-packages/netmiko/base_connection.py", line 884, in establish_connection
    self.remote_conn_pre.connect(**ssh_connect_params)
  File "/home/macaktom/.local/share/virtualenvs/network_automation-NLxdyicX/lib/python3.8/site-packages/paramiko/client.py", line 368, in connect
    raise NoValidConnectionsError(errors)
paramiko.ssh_exception.NoValidConnectionsError: [Errno None] Unable to connect to port 22 on 10.0.0.7

During handling of the above exception, another exception occurred:

Traceback (most recent call last):
  File "/home/macaktom/.local/share/virtualenvs/network_automation-NLxdyicX/lib/python3.8/site-packages/nornir/core/task.py", line 85, in start
    r = self.task(self, **self.params)
  File "/home/macaktom/.local/share/virtualenvs/network_automation-NLxdyicX/lib/python3.8/site-packages/nornir/plugins/tasks/networking/netmiko_send_command.py", line 26, in netmiko_send_command
    net_connect = task.host.get_connection("netmiko", task.nornir.config)
  File "/home/macaktom/.local/share/virtualenvs/network_automation-NLxdyicX/lib/python3.8/site-packages/nornir/core/inventory.py", line 294, in get_connection
    self.open_connection(
  File "/home/macaktom/.local/share/virtualenvs/network_automation-NLxdyicX/lib/python3.8/site-packages/nornir/core/inventory.py", line 345, in open_connection
    self.connections[connection].open(
  File "/home/macaktom/.local/share/virtualenvs/network_automation-NLxdyicX/lib/python3.8/site-packages/nornir/plugins/connections/netmiko.py", line 58, in open
    self.connection = ConnectHandler(**parameters)
  File "/home/macaktom/.local/share/virtualenvs/network_automation-NLxdyicX/lib/python3.8/site-packages/netmiko/ssh_dispatcher.py", line 246, in ConnectHandler
    return ConnectionClass(*args, **kwargs)
  File "/home/macaktom/.local/share/virtualenvs/network_automation-NLxdyicX/lib/python3.8/site-packages/netmiko/base_connection.py", line 317, in __init__
    self._open()
  File "/home/macaktom/.local/share/virtualenvs/network_automation-NLxdyicX/lib/python3.8/site-packages/netmiko/base_connection.py", line 322, in _open
    self.establish_connection()
  File "/home/macaktom/.local/share/virtualenvs/network_automation-NLxdyicX/lib/python3.8/site-packages/netmiko/base_connection.py", line 890, in establish_connection
    raise NetMikoTimeoutException(msg)
netmiko.ssh_exception.NetMikoTimeoutException: Connection to device timed-out: linux 10.0.0.7:22

2020-05-17 20:59:50,271 - nornir.core.task -    ERROR -      start() - Host 'SW3': task 'netmiko_send_command' failed with traceback:
Traceback (most recent call last):
  File "/home/macaktom/.local/share/virtualenvs/network_automation-NLxdyicX/lib/python3.8/site-packages/nornir/core/task.py", line 85, in start
    r = self.task(self, **self.params)
  File "/home/macaktom/.local/share/virtualenvs/network_automation-NLxdyicX/lib/python3.8/site-packages/nornir/plugins/tasks/networking/netmiko_send_command.py", line 28, in netmiko_send_command
    net_connect.enable()
  File "/home/macaktom/.local/share/virtualenvs/network_automation-NLxdyicX/lib/python3.8/site-packages/netmiko/cisco_base_connection.py", line 21, in enable
    return super(CiscoBaseConnection, self).enable(
  File "/home/macaktom/.local/share/virtualenvs/network_automation-NLxdyicX/lib/python3.8/site-packages/netmiko/base_connection.py", line 1470, in enable
    raise ValueError(msg)
ValueError: Failed to enter enable mode. Please ensure you pass the 'secret' argument to ConnectHandler.

2020-05-17 20:59:50,278 - nornir.core.task -    ERROR -      start() - Host 'SW1': task 'netmiko_send_command' failed with traceback:
Traceback (most recent call last):
  File "/home/macaktom/.local/share/virtualenvs/network_automation-NLxdyicX/lib/python3.8/site-packages/nornir/core/task.py", line 85, in start
    r = self.task(self, **self.params)
  File "/home/macaktom/.local/share/virtualenvs/network_automation-NLxdyicX/lib/python3.8/site-packages/nornir/plugins/tasks/networking/netmiko_send_command.py", line 28, in netmiko_send_command
    net_connect.enable()
  File "/home/macaktom/.local/share/virtualenvs/network_automation-NLxdyicX/lib/python3.8/site-packages/netmiko/cisco_base_connection.py", line 21, in enable
    return super(CiscoBaseConnection, self).enable(
  File "/home/macaktom/.local/share/virtualenvs/network_automation-NLxdyicX/lib/python3.8/site-packages/netmiko/base_connection.py", line 1470, in enable
    raise ValueError(msg)
ValueError: Failed to enter enable mode. Please ensure you pass the 'secret' argument to ConnectHandler.

2020-05-17 20:59:50,386 - nornir.core.task -    ERROR -      start() - Host 'R1': task 'netmiko_send_command' failed with traceback:
Traceback (most recent call last):
  File "/home/macaktom/.local/share/virtualenvs/network_automation-NLxdyicX/lib/python3.8/site-packages/nornir/core/task.py", line 85, in start
    r = self.task(self, **self.params)
  File "/home/macaktom/.local/share/virtualenvs/network_automation-NLxdyicX/lib/python3.8/site-packages/nornir/plugins/tasks/networking/netmiko_send_command.py", line 28, in netmiko_send_command
    net_connect.enable()
  File "/home/macaktom/.local/share/virtualenvs/network_automation-NLxdyicX/lib/python3.8/site-packages/netmiko/cisco_base_connection.py", line 21, in enable
    return super(CiscoBaseConnection, self).enable(
  File "/home/macaktom/.local/share/virtualenvs/network_automation-NLxdyicX/lib/python3.8/site-packages/netmiko/base_connection.py", line 1470, in enable
    raise ValueError(msg)
ValueError: Failed to enter enable mode. Please ensure you pass the 'secret' argument to ConnectHandler.

2020-05-17 20:59:50,721 - nornir.core.task -    ERROR -      start() - Host 'SW2': task 'netmiko_send_command' failed with traceback:
Traceback (most recent call last):
  File "/home/macaktom/.local/share/virtualenvs/network_automation-NLxdyicX/lib/python3.8/site-packages/nornir/core/task.py", line 85, in start
    r = self.task(self, **self.params)
  File "/home/macaktom/.local/share/virtualenvs/network_automation-NLxdyicX/lib/python3.8/site-packages/nornir/plugins/tasks/networking/netmiko_send_command.py", line 28, in netmiko_send_command
    net_connect.enable()
  File "/home/macaktom/.local/share/virtualenvs/network_automation-NLxdyicX/lib/python3.8/site-packages/netmiko/cisco_base_connection.py", line 21, in enable
    return super(CiscoBaseConnection, self).enable(
  File "/home/macaktom/.local/share/virtualenvs/network_automation-NLxdyicX/lib/python3.8/site-packages/netmiko/base_connection.py", line 1470, in enable
    raise ValueError(msg)
ValueError: Failed to enter enable mode. Please ensure you pass the 'secret' argument to ConnectHandler.

2020-05-17 20:59:50,916 - nornir.core.task -    ERROR -      start() - Host 'Automation': task 'netmiko_send_command' failed with traceback:
Traceback (most recent call last):
  File "/home/macaktom/.local/share/virtualenvs/network_automation-NLxdyicX/lib/python3.8/site-packages/nornir/core/task.py", line 85, in start
    r = self.task(self, **self.params)
  File "/home/macaktom/.local/share/virtualenvs/network_automation-NLxdyicX/lib/python3.8/site-packages/nornir/plugins/tasks/networking/netmiko_send_command.py", line 28, in netmiko_send_command
    net_connect.enable()
  File "/home/macaktom/.local/share/virtualenvs/network_automation-NLxdyicX/lib/python3.8/site-packages/netmiko/linux/linux_ssh.py", line 94, in enable
    self.set_base_prompt()
  File "/home/macaktom/.local/share/virtualenvs/network_automation-NLxdyicX/lib/python3.8/site-packages/netmiko/linux/linux_ssh.py", line 42, in set_base_prompt
    return super(LinuxSSH, self).set_base_prompt(
  File "/home/macaktom/.local/share/virtualenvs/network_automation-NLxdyicX/lib/python3.8/site-packages/netmiko/base_connection.py", line 1066, in set_base_prompt
    prompt = self.find_prompt(delay_factor=delay_factor)
  File "/home/macaktom/.local/share/virtualenvs/network_automation-NLxdyicX/lib/python3.8/site-packages/netmiko/base_connection.py", line 1107, in find_prompt
    raise ValueError("Unable to find prompt: {}".format(prompt))
ValueError: Unable to find prompt: 

2020-05-17 21:02:44,604 -  nornir.core -     INFO -        run() - Running task 'netmiko_send_command' with args {'command_string': 'ping 10.0.0.1', 'use_timing': True} on 7 hosts
2020-05-17 21:02:44,617 - nornir.core.task -    ERROR -      start() - Host 'Client1': task 'netmiko_send_command' failed with traceback:
Traceback (most recent call last):
  File "/home/macaktom/.local/share/virtualenvs/network_automation-NLxdyicX/lib/python3.8/site-packages/netmiko/base_connection.py", line 884, in establish_connection
    self.remote_conn_pre.connect(**ssh_connect_params)
  File "/home/macaktom/.local/share/virtualenvs/network_automation-NLxdyicX/lib/python3.8/site-packages/paramiko/client.py", line 368, in connect
    raise NoValidConnectionsError(errors)
paramiko.ssh_exception.NoValidConnectionsError: [Errno None] Unable to connect to port 22 on 10.0.0.6

During handling of the above exception, another exception occurred:

Traceback (most recent call last):
  File "/home/macaktom/.local/share/virtualenvs/network_automation-NLxdyicX/lib/python3.8/site-packages/nornir/core/task.py", line 85, in start
    r = self.task(self, **self.params)
  File "/home/macaktom/.local/share/virtualenvs/network_automation-NLxdyicX/lib/python3.8/site-packages/nornir/plugins/tasks/networking/netmiko_send_command.py", line 26, in netmiko_send_command
    net_connect = task.host.get_connection("netmiko", task.nornir.config)
  File "/home/macaktom/.local/share/virtualenvs/network_automation-NLxdyicX/lib/python3.8/site-packages/nornir/core/inventory.py", line 294, in get_connection
    self.open_connection(
  File "/home/macaktom/.local/share/virtualenvs/network_automation-NLxdyicX/lib/python3.8/site-packages/nornir/core/inventory.py", line 345, in open_connection
    self.connections[connection].open(
  File "/home/macaktom/.local/share/virtualenvs/network_automation-NLxdyicX/lib/python3.8/site-packages/nornir/plugins/connections/netmiko.py", line 58, in open
    self.connection = ConnectHandler(**parameters)
  File "/home/macaktom/.local/share/virtualenvs/network_automation-NLxdyicX/lib/python3.8/site-packages/netmiko/ssh_dispatcher.py", line 246, in ConnectHandler
    return ConnectionClass(*args, **kwargs)
  File "/home/macaktom/.local/share/virtualenvs/network_automation-NLxdyicX/lib/python3.8/site-packages/netmiko/base_connection.py", line 317, in __init__
    self._open()
  File "/home/macaktom/.local/share/virtualenvs/network_automation-NLxdyicX/lib/python3.8/site-packages/netmiko/base_connection.py", line 322, in _open
    self.establish_connection()
  File "/home/macaktom/.local/share/virtualenvs/network_automation-NLxdyicX/lib/python3.8/site-packages/netmiko/base_connection.py", line 890, in establish_connection
    raise NetMikoTimeoutException(msg)
netmiko.ssh_exception.NetMikoTimeoutException: Connection to device timed-out: linux 10.0.0.6:22

2020-05-17 21:02:44,623 - nornir.core.task -    ERROR -      start() - Host 'Client2': task 'netmiko_send_command' failed with traceback:
Traceback (most recent call last):
  File "/home/macaktom/.local/share/virtualenvs/network_automation-NLxdyicX/lib/python3.8/site-packages/netmiko/base_connection.py", line 884, in establish_connection
    self.remote_conn_pre.connect(**ssh_connect_params)
  File "/home/macaktom/.local/share/virtualenvs/network_automation-NLxdyicX/lib/python3.8/site-packages/paramiko/client.py", line 368, in connect
    raise NoValidConnectionsError(errors)
paramiko.ssh_exception.NoValidConnectionsError: [Errno None] Unable to connect to port 22 on 10.0.0.7

During handling of the above exception, another exception occurred:

Traceback (most recent call last):
  File "/home/macaktom/.local/share/virtualenvs/network_automation-NLxdyicX/lib/python3.8/site-packages/nornir/core/task.py", line 85, in start
    r = self.task(self, **self.params)
  File "/home/macaktom/.local/share/virtualenvs/network_automation-NLxdyicX/lib/python3.8/site-packages/nornir/plugins/tasks/networking/netmiko_send_command.py", line 26, in netmiko_send_command
    net_connect = task.host.get_connection("netmiko", task.nornir.config)
  File "/home/macaktom/.local/share/virtualenvs/network_automation-NLxdyicX/lib/python3.8/site-packages/nornir/core/inventory.py", line 294, in get_connection
    self.open_connection(
  File "/home/macaktom/.local/share/virtualenvs/network_automation-NLxdyicX/lib/python3.8/site-packages/nornir/core/inventory.py", line 345, in open_connection
    self.connections[connection].open(
  File "/home/macaktom/.local/share/virtualenvs/network_automation-NLxdyicX/lib/python3.8/site-packages/nornir/plugins/connections/netmiko.py", line 58, in open
    self.connection = ConnectHandler(**parameters)
  File "/home/macaktom/.local/share/virtualenvs/network_automation-NLxdyicX/lib/python3.8/site-packages/netmiko/ssh_dispatcher.py", line 246, in ConnectHandler
    return ConnectionClass(*args, **kwargs)
  File "/home/macaktom/.local/share/virtualenvs/network_automation-NLxdyicX/lib/python3.8/site-packages/netmiko/base_connection.py", line 317, in __init__
    self._open()
  File "/home/macaktom/.local/share/virtualenvs/network_automation-NLxdyicX/lib/python3.8/site-packages/netmiko/base_connection.py", line 322, in _open
    self.establish_connection()
  File "/home/macaktom/.local/share/virtualenvs/network_automation-NLxdyicX/lib/python3.8/site-packages/netmiko/base_connection.py", line 890, in establish_connection
    raise NetMikoTimeoutException(msg)
netmiko.ssh_exception.NetMikoTimeoutException: Connection to device timed-out: linux 10.0.0.7:22

2020-05-17 21:12:34,310 -  nornir.core -     INFO -        run() - Running task 'netmiko_send_command' with args {'command_string': 'ping 10.0.0.1', 'use_timing': False} on 7 hosts
2020-05-17 21:12:34,326 - nornir.core.task -    ERROR -      start() - Host 'Client1': task 'netmiko_send_command' failed with traceback:
Traceback (most recent call last):
  File "/home/macaktom/.local/share/virtualenvs/network_automation-NLxdyicX/lib/python3.8/site-packages/netmiko/base_connection.py", line 884, in establish_connection
    self.remote_conn_pre.connect(**ssh_connect_params)
  File "/home/macaktom/.local/share/virtualenvs/network_automation-NLxdyicX/lib/python3.8/site-packages/paramiko/client.py", line 368, in connect
    raise NoValidConnectionsError(errors)
paramiko.ssh_exception.NoValidConnectionsError: [Errno None] Unable to connect to port 22 on 10.0.0.6

During handling of the above exception, another exception occurred:

Traceback (most recent call last):
  File "/home/macaktom/.local/share/virtualenvs/network_automation-NLxdyicX/lib/python3.8/site-packages/nornir/core/task.py", line 85, in start
    r = self.task(self, **self.params)
  File "/home/macaktom/.local/share/virtualenvs/network_automation-NLxdyicX/lib/python3.8/site-packages/nornir/plugins/tasks/networking/netmiko_send_command.py", line 26, in netmiko_send_command
    net_connect = task.host.get_connection("netmiko", task.nornir.config)
  File "/home/macaktom/.local/share/virtualenvs/network_automation-NLxdyicX/lib/python3.8/site-packages/nornir/core/inventory.py", line 294, in get_connection
    self.open_connection(
  File "/home/macaktom/.local/share/virtualenvs/network_automation-NLxdyicX/lib/python3.8/site-packages/nornir/core/inventory.py", line 345, in open_connection
    self.connections[connection].open(
  File "/home/macaktom/.local/share/virtualenvs/network_automation-NLxdyicX/lib/python3.8/site-packages/nornir/plugins/connections/netmiko.py", line 58, in open
    self.connection = ConnectHandler(**parameters)
  File "/home/macaktom/.local/share/virtualenvs/network_automation-NLxdyicX/lib/python3.8/site-packages/netmiko/ssh_dispatcher.py", line 246, in ConnectHandler
    return ConnectionClass(*args, **kwargs)
  File "/home/macaktom/.local/share/virtualenvs/network_automation-NLxdyicX/lib/python3.8/site-packages/netmiko/base_connection.py", line 317, in __init__
    self._open()
  File "/home/macaktom/.local/share/virtualenvs/network_automation-NLxdyicX/lib/python3.8/site-packages/netmiko/base_connection.py", line 322, in _open
    self.establish_connection()
  File "/home/macaktom/.local/share/virtualenvs/network_automation-NLxdyicX/lib/python3.8/site-packages/netmiko/base_connection.py", line 890, in establish_connection
    raise NetMikoTimeoutException(msg)
netmiko.ssh_exception.NetMikoTimeoutException: Connection to device timed-out: linux 10.0.0.6:22

2020-05-17 21:12:34,328 - nornir.core.task -    ERROR -      start() - Host 'Client2': task 'netmiko_send_command' failed with traceback:
Traceback (most recent call last):
  File "/home/macaktom/.local/share/virtualenvs/network_automation-NLxdyicX/lib/python3.8/site-packages/netmiko/base_connection.py", line 884, in establish_connection
    self.remote_conn_pre.connect(**ssh_connect_params)
  File "/home/macaktom/.local/share/virtualenvs/network_automation-NLxdyicX/lib/python3.8/site-packages/paramiko/client.py", line 368, in connect
    raise NoValidConnectionsError(errors)
paramiko.ssh_exception.NoValidConnectionsError: [Errno None] Unable to connect to port 22 on 10.0.0.7

During handling of the above exception, another exception occurred:

Traceback (most recent call last):
  File "/home/macaktom/.local/share/virtualenvs/network_automation-NLxdyicX/lib/python3.8/site-packages/nornir/core/task.py", line 85, in start
    r = self.task(self, **self.params)
  File "/home/macaktom/.local/share/virtualenvs/network_automation-NLxdyicX/lib/python3.8/site-packages/nornir/plugins/tasks/networking/netmiko_send_command.py", line 26, in netmiko_send_command
    net_connect = task.host.get_connection("netmiko", task.nornir.config)
  File "/home/macaktom/.local/share/virtualenvs/network_automation-NLxdyicX/lib/python3.8/site-packages/nornir/core/inventory.py", line 294, in get_connection
    self.open_connection(
  File "/home/macaktom/.local/share/virtualenvs/network_automation-NLxdyicX/lib/python3.8/site-packages/nornir/core/inventory.py", line 345, in open_connection
    self.connections[connection].open(
  File "/home/macaktom/.local/share/virtualenvs/network_automation-NLxdyicX/lib/python3.8/site-packages/nornir/plugins/connections/netmiko.py", line 58, in open
    self.connection = ConnectHandler(**parameters)
  File "/home/macaktom/.local/share/virtualenvs/network_automation-NLxdyicX/lib/python3.8/site-packages/netmiko/ssh_dispatcher.py", line 246, in ConnectHandler
    return ConnectionClass(*args, **kwargs)
  File "/home/macaktom/.local/share/virtualenvs/network_automation-NLxdyicX/lib/python3.8/site-packages/netmiko/base_connection.py", line 317, in __init__
    self._open()
  File "/home/macaktom/.local/share/virtualenvs/network_automation-NLxdyicX/lib/python3.8/site-packages/netmiko/base_connection.py", line 322, in _open
    self.establish_connection()
  File "/home/macaktom/.local/share/virtualenvs/network_automation-NLxdyicX/lib/python3.8/site-packages/netmiko/base_connection.py", line 890, in establish_connection
    raise NetMikoTimeoutException(msg)
netmiko.ssh_exception.NetMikoTimeoutException: Connection to device timed-out: linux 10.0.0.7:22

2020-05-17 21:14:18,963 - nornir.core.task -    ERROR -      start() - Host 'Automation': task 'netmiko_send_command' failed with traceback:
Traceback (most recent call last):
  File "/home/macaktom/.local/share/virtualenvs/network_automation-NLxdyicX/lib/python3.8/site-packages/nornir/core/task.py", line 85, in start
    r = self.task(self, **self.params)
  File "/home/macaktom/.local/share/virtualenvs/network_automation-NLxdyicX/lib/python3.8/site-packages/nornir/plugins/tasks/networking/netmiko_send_command.py", line 32, in netmiko_send_command
    result = net_connect.send_command(command_string, **kwargs)
  File "/home/macaktom/.local/share/virtualenvs/network_automation-NLxdyicX/lib/python3.8/site-packages/netmiko/base_connection.py", line 1335, in send_command
    raise IOError(
OSError: Search pattern never detected in send_command_expect: macaktom@macaktom:\~\$

2020-05-17 21:14:24,791 -  nornir.core -     INFO -        run() - Running task 'netmiko_send_command' with args {'command_string': 'ping 10.0.0.1', 'use_timing': False} on 6 hosts
2020-05-17 21:14:24,802 - nornir.core.task -    ERROR -      start() - Host 'Client1': task 'netmiko_send_command' failed with traceback:
Traceback (most recent call last):
  File "/home/macaktom/.local/share/virtualenvs/network_automation-NLxdyicX/lib/python3.8/site-packages/netmiko/base_connection.py", line 884, in establish_connection
    self.remote_conn_pre.connect(**ssh_connect_params)
  File "/home/macaktom/.local/share/virtualenvs/network_automation-NLxdyicX/lib/python3.8/site-packages/paramiko/client.py", line 368, in connect
    raise NoValidConnectionsError(errors)
paramiko.ssh_exception.NoValidConnectionsError: [Errno None] Unable to connect to port 22 on 10.0.0.6

During handling of the above exception, another exception occurred:

Traceback (most recent call last):
  File "/home/macaktom/.local/share/virtualenvs/network_automation-NLxdyicX/lib/python3.8/site-packages/nornir/core/task.py", line 85, in start
    r = self.task(self, **self.params)
  File "/home/macaktom/.local/share/virtualenvs/network_automation-NLxdyicX/lib/python3.8/site-packages/nornir/plugins/tasks/networking/netmiko_send_command.py", line 26, in netmiko_send_command
    net_connect = task.host.get_connection("netmiko", task.nornir.config)
  File "/home/macaktom/.local/share/virtualenvs/network_automation-NLxdyicX/lib/python3.8/site-packages/nornir/core/inventory.py", line 294, in get_connection
    self.open_connection(
  File "/home/macaktom/.local/share/virtualenvs/network_automation-NLxdyicX/lib/python3.8/site-packages/nornir/core/inventory.py", line 345, in open_connection
    self.connections[connection].open(
  File "/home/macaktom/.local/share/virtualenvs/network_automation-NLxdyicX/lib/python3.8/site-packages/nornir/plugins/connections/netmiko.py", line 58, in open
    self.connection = ConnectHandler(**parameters)
  File "/home/macaktom/.local/share/virtualenvs/network_automation-NLxdyicX/lib/python3.8/site-packages/netmiko/ssh_dispatcher.py", line 246, in ConnectHandler
    return ConnectionClass(*args, **kwargs)
  File "/home/macaktom/.local/share/virtualenvs/network_automation-NLxdyicX/lib/python3.8/site-packages/netmiko/base_connection.py", line 317, in __init__
    self._open()
  File "/home/macaktom/.local/share/virtualenvs/network_automation-NLxdyicX/lib/python3.8/site-packages/netmiko/base_connection.py", line 322, in _open
    self.establish_connection()
  File "/home/macaktom/.local/share/virtualenvs/network_automation-NLxdyicX/lib/python3.8/site-packages/netmiko/base_connection.py", line 890, in establish_connection
    raise NetMikoTimeoutException(msg)
netmiko.ssh_exception.NetMikoTimeoutException: Connection to device timed-out: linux 10.0.0.6:22

2020-05-17 21:14:24,809 - nornir.core.task -    ERROR -      start() - Host 'Client2': task 'netmiko_send_command' failed with traceback:
Traceback (most recent call last):
  File "/home/macaktom/.local/share/virtualenvs/network_automation-NLxdyicX/lib/python3.8/site-packages/netmiko/base_connection.py", line 884, in establish_connection
    self.remote_conn_pre.connect(**ssh_connect_params)
  File "/home/macaktom/.local/share/virtualenvs/network_automation-NLxdyicX/lib/python3.8/site-packages/paramiko/client.py", line 368, in connect
    raise NoValidConnectionsError(errors)
paramiko.ssh_exception.NoValidConnectionsError: [Errno None] Unable to connect to port 22 on 10.0.0.7

During handling of the above exception, another exception occurred:

Traceback (most recent call last):
  File "/home/macaktom/.local/share/virtualenvs/network_automation-NLxdyicX/lib/python3.8/site-packages/nornir/core/task.py", line 85, in start
    r = self.task(self, **self.params)
  File "/home/macaktom/.local/share/virtualenvs/network_automation-NLxdyicX/lib/python3.8/site-packages/nornir/plugins/tasks/networking/netmiko_send_command.py", line 26, in netmiko_send_command
    net_connect = task.host.get_connection("netmiko", task.nornir.config)
  File "/home/macaktom/.local/share/virtualenvs/network_automation-NLxdyicX/lib/python3.8/site-packages/nornir/core/inventory.py", line 294, in get_connection
    self.open_connection(
  File "/home/macaktom/.local/share/virtualenvs/network_automation-NLxdyicX/lib/python3.8/site-packages/nornir/core/inventory.py", line 345, in open_connection
    self.connections[connection].open(
  File "/home/macaktom/.local/share/virtualenvs/network_automation-NLxdyicX/lib/python3.8/site-packages/nornir/plugins/connections/netmiko.py", line 58, in open
    self.connection = ConnectHandler(**parameters)
  File "/home/macaktom/.local/share/virtualenvs/network_automation-NLxdyicX/lib/python3.8/site-packages/netmiko/ssh_dispatcher.py", line 246, in ConnectHandler
    return ConnectionClass(*args, **kwargs)
  File "/home/macaktom/.local/share/virtualenvs/network_automation-NLxdyicX/lib/python3.8/site-packages/netmiko/base_connection.py", line 317, in __init__
    self._open()
  File "/home/macaktom/.local/share/virtualenvs/network_automation-NLxdyicX/lib/python3.8/site-packages/netmiko/base_connection.py", line 322, in _open
    self.establish_connection()
  File "/home/macaktom/.local/share/virtualenvs/network_automation-NLxdyicX/lib/python3.8/site-packages/netmiko/base_connection.py", line 890, in establish_connection
    raise NetMikoTimeoutException(msg)
netmiko.ssh_exception.NetMikoTimeoutException: Connection to device timed-out: linux 10.0.0.7:22

2020-05-17 21:28:56,243 -  nornir.core -     INFO -        run() - Running task 'netmiko_send_command' with args {'command_string': 'ping 10.0.0.1', 'use_timing': False} on 7 hosts
2020-05-17 21:28:56,255 - nornir.core.task -    ERROR -      start() - Host 'Client2': task 'netmiko_send_command' failed with traceback:
Traceback (most recent call last):
  File "/home/macaktom/.local/share/virtualenvs/network_automation-NLxdyicX/lib/python3.8/site-packages/netmiko/base_connection.py", line 884, in establish_connection
    self.remote_conn_pre.connect(**ssh_connect_params)
  File "/home/macaktom/.local/share/virtualenvs/network_automation-NLxdyicX/lib/python3.8/site-packages/paramiko/client.py", line 368, in connect
    raise NoValidConnectionsError(errors)
paramiko.ssh_exception.NoValidConnectionsError: [Errno None] Unable to connect to port 22 on 10.0.0.7

During handling of the above exception, another exception occurred:

Traceback (most recent call last):
  File "/home/macaktom/.local/share/virtualenvs/network_automation-NLxdyicX/lib/python3.8/site-packages/nornir/core/task.py", line 85, in start
    r = self.task(self, **self.params)
  File "/home/macaktom/.local/share/virtualenvs/network_automation-NLxdyicX/lib/python3.8/site-packages/nornir/plugins/tasks/networking/netmiko_send_command.py", line 26, in netmiko_send_command
    net_connect = task.host.get_connection("netmiko", task.nornir.config)
  File "/home/macaktom/.local/share/virtualenvs/network_automation-NLxdyicX/lib/python3.8/site-packages/nornir/core/inventory.py", line 294, in get_connection
    self.open_connection(
  File "/home/macaktom/.local/share/virtualenvs/network_automation-NLxdyicX/lib/python3.8/site-packages/nornir/core/inventory.py", line 345, in open_connection
    self.connections[connection].open(
  File "/home/macaktom/.local/share/virtualenvs/network_automation-NLxdyicX/lib/python3.8/site-packages/nornir/plugins/connections/netmiko.py", line 58, in open
    self.connection = ConnectHandler(**parameters)
  File "/home/macaktom/.local/share/virtualenvs/network_automation-NLxdyicX/lib/python3.8/site-packages/netmiko/ssh_dispatcher.py", line 246, in ConnectHandler
    return ConnectionClass(*args, **kwargs)
  File "/home/macaktom/.local/share/virtualenvs/network_automation-NLxdyicX/lib/python3.8/site-packages/netmiko/base_connection.py", line 317, in __init__
    self._open()
  File "/home/macaktom/.local/share/virtualenvs/network_automation-NLxdyicX/lib/python3.8/site-packages/netmiko/base_connection.py", line 322, in _open
    self.establish_connection()
  File "/home/macaktom/.local/share/virtualenvs/network_automation-NLxdyicX/lib/python3.8/site-packages/netmiko/base_connection.py", line 890, in establish_connection
    raise NetMikoTimeoutException(msg)
netmiko.ssh_exception.NetMikoTimeoutException: Connection to device timed-out: linux 10.0.0.7:22

2020-05-17 21:28:56,258 - nornir.core.task -    ERROR -      start() - Host 'Client1': task 'netmiko_send_command' failed with traceback:
Traceback (most recent call last):
  File "/home/macaktom/.local/share/virtualenvs/network_automation-NLxdyicX/lib/python3.8/site-packages/netmiko/base_connection.py", line 884, in establish_connection
    self.remote_conn_pre.connect(**ssh_connect_params)
  File "/home/macaktom/.local/share/virtualenvs/network_automation-NLxdyicX/lib/python3.8/site-packages/paramiko/client.py", line 368, in connect
    raise NoValidConnectionsError(errors)
paramiko.ssh_exception.NoValidConnectionsError: [Errno None] Unable to connect to port 22 on 10.0.0.6

During handling of the above exception, another exception occurred:

Traceback (most recent call last):
  File "/home/macaktom/.local/share/virtualenvs/network_automation-NLxdyicX/lib/python3.8/site-packages/nornir/core/task.py", line 85, in start
    r = self.task(self, **self.params)
  File "/home/macaktom/.local/share/virtualenvs/network_automation-NLxdyicX/lib/python3.8/site-packages/nornir/plugins/tasks/networking/netmiko_send_command.py", line 26, in netmiko_send_command
    net_connect = task.host.get_connection("netmiko", task.nornir.config)
  File "/home/macaktom/.local/share/virtualenvs/network_automation-NLxdyicX/lib/python3.8/site-packages/nornir/core/inventory.py", line 294, in get_connection
    self.open_connection(
  File "/home/macaktom/.local/share/virtualenvs/network_automation-NLxdyicX/lib/python3.8/site-packages/nornir/core/inventory.py", line 345, in open_connection
    self.connections[connection].open(
  File "/home/macaktom/.local/share/virtualenvs/network_automation-NLxdyicX/lib/python3.8/site-packages/nornir/plugins/connections/netmiko.py", line 58, in open
    self.connection = ConnectHandler(**parameters)
  File "/home/macaktom/.local/share/virtualenvs/network_automation-NLxdyicX/lib/python3.8/site-packages/netmiko/ssh_dispatcher.py", line 246, in ConnectHandler
    return ConnectionClass(*args, **kwargs)
  File "/home/macaktom/.local/share/virtualenvs/network_automation-NLxdyicX/lib/python3.8/site-packages/netmiko/base_connection.py", line 317, in __init__
    self._open()
  File "/home/macaktom/.local/share/virtualenvs/network_automation-NLxdyicX/lib/python3.8/site-packages/netmiko/base_connection.py", line 322, in _open
    self.establish_connection()
  File "/home/macaktom/.local/share/virtualenvs/network_automation-NLxdyicX/lib/python3.8/site-packages/netmiko/base_connection.py", line 890, in establish_connection
    raise NetMikoTimeoutException(msg)
netmiko.ssh_exception.NetMikoTimeoutException: Connection to device timed-out: linux 10.0.0.6:22

2020-05-17 21:30:36,347 - nornir.core.task -    ERROR -      start() - Host 'R2': task 'netmiko_send_command' failed with traceback:
Traceback (most recent call last):
  File "/home/macaktom/.local/share/virtualenvs/network_automation-NLxdyicX/lib/python3.8/site-packages/netmiko/base_connection.py", line 884, in establish_connection
    self.remote_conn_pre.connect(**ssh_connect_params)
  File "/home/macaktom/.local/share/virtualenvs/network_automation-NLxdyicX/lib/python3.8/site-packages/paramiko/client.py", line 349, in connect
    retry_on_signal(lambda: sock.connect(addr))
  File "/home/macaktom/.local/share/virtualenvs/network_automation-NLxdyicX/lib/python3.8/site-packages/paramiko/util.py", line 283, in retry_on_signal
    return function()
  File "/home/macaktom/.local/share/virtualenvs/network_automation-NLxdyicX/lib/python3.8/site-packages/paramiko/client.py", line 349, in <lambda>
    retry_on_signal(lambda: sock.connect(addr))
socket.timeout: timed out

During handling of the above exception, another exception occurred:

Traceback (most recent call last):
  File "/home/macaktom/.local/share/virtualenvs/network_automation-NLxdyicX/lib/python3.8/site-packages/nornir/core/task.py", line 85, in start
    r = self.task(self, **self.params)
  File "/home/macaktom/.local/share/virtualenvs/network_automation-NLxdyicX/lib/python3.8/site-packages/nornir/plugins/tasks/networking/netmiko_send_command.py", line 26, in netmiko_send_command
    net_connect = task.host.get_connection("netmiko", task.nornir.config)
  File "/home/macaktom/.local/share/virtualenvs/network_automation-NLxdyicX/lib/python3.8/site-packages/nornir/core/inventory.py", line 294, in get_connection
    self.open_connection(
  File "/home/macaktom/.local/share/virtualenvs/network_automation-NLxdyicX/lib/python3.8/site-packages/nornir/core/inventory.py", line 345, in open_connection
    self.connections[connection].open(
  File "/home/macaktom/.local/share/virtualenvs/network_automation-NLxdyicX/lib/python3.8/site-packages/nornir/plugins/connections/netmiko.py", line 58, in open
    self.connection = ConnectHandler(**parameters)
  File "/home/macaktom/.local/share/virtualenvs/network_automation-NLxdyicX/lib/python3.8/site-packages/netmiko/ssh_dispatcher.py", line 246, in ConnectHandler
    return ConnectionClass(*args, **kwargs)
  File "/home/macaktom/.local/share/virtualenvs/network_automation-NLxdyicX/lib/python3.8/site-packages/netmiko/base_connection.py", line 317, in __init__
    self._open()
  File "/home/macaktom/.local/share/virtualenvs/network_automation-NLxdyicX/lib/python3.8/site-packages/netmiko/base_connection.py", line 322, in _open
    self.establish_connection()
  File "/home/macaktom/.local/share/virtualenvs/network_automation-NLxdyicX/lib/python3.8/site-packages/netmiko/base_connection.py", line 890, in establish_connection
    raise NetMikoTimeoutException(msg)
netmiko.ssh_exception.NetMikoTimeoutException: Connection to device timed-out: juniper_junos 10.0.1.2:22

2020-05-17 21:30:58,022 -  nornir.core -     INFO -        run() - Running task 'netmiko_send_command' with args {'command_string': 'ping 10.0.0.1', 'use_timing': False} on 6 hosts
2020-05-17 21:30:58,041 - nornir.core.task -    ERROR -      start() - Host 'Client1': task 'netmiko_send_command' failed with traceback:
Traceback (most recent call last):
  File "/home/macaktom/.local/share/virtualenvs/network_automation-NLxdyicX/lib/python3.8/site-packages/netmiko/base_connection.py", line 884, in establish_connection
    self.remote_conn_pre.connect(**ssh_connect_params)
  File "/home/macaktom/.local/share/virtualenvs/network_automation-NLxdyicX/lib/python3.8/site-packages/paramiko/client.py", line 368, in connect
    raise NoValidConnectionsError(errors)
paramiko.ssh_exception.NoValidConnectionsError: [Errno None] Unable to connect to port 22 on 10.0.0.6

During handling of the above exception, another exception occurred:

Traceback (most recent call last):
  File "/home/macaktom/.local/share/virtualenvs/network_automation-NLxdyicX/lib/python3.8/site-packages/nornir/core/task.py", line 85, in start
    r = self.task(self, **self.params)
  File "/home/macaktom/.local/share/virtualenvs/network_automation-NLxdyicX/lib/python3.8/site-packages/nornir/plugins/tasks/networking/netmiko_send_command.py", line 26, in netmiko_send_command
    net_connect = task.host.get_connection("netmiko", task.nornir.config)
  File "/home/macaktom/.local/share/virtualenvs/network_automation-NLxdyicX/lib/python3.8/site-packages/nornir/core/inventory.py", line 294, in get_connection
    self.open_connection(
  File "/home/macaktom/.local/share/virtualenvs/network_automation-NLxdyicX/lib/python3.8/site-packages/nornir/core/inventory.py", line 345, in open_connection
    self.connections[connection].open(
  File "/home/macaktom/.local/share/virtualenvs/network_automation-NLxdyicX/lib/python3.8/site-packages/nornir/plugins/connections/netmiko.py", line 58, in open
    self.connection = ConnectHandler(**parameters)
  File "/home/macaktom/.local/share/virtualenvs/network_automation-NLxdyicX/lib/python3.8/site-packages/netmiko/ssh_dispatcher.py", line 246, in ConnectHandler
    return ConnectionClass(*args, **kwargs)
  File "/home/macaktom/.local/share/virtualenvs/network_automation-NLxdyicX/lib/python3.8/site-packages/netmiko/base_connection.py", line 317, in __init__
    self._open()
  File "/home/macaktom/.local/share/virtualenvs/network_automation-NLxdyicX/lib/python3.8/site-packages/netmiko/base_connection.py", line 322, in _open
    self.establish_connection()
  File "/home/macaktom/.local/share/virtualenvs/network_automation-NLxdyicX/lib/python3.8/site-packages/netmiko/base_connection.py", line 890, in establish_connection
    raise NetMikoTimeoutException(msg)
netmiko.ssh_exception.NetMikoTimeoutException: Connection to device timed-out: linux 10.0.0.6:22

2020-05-17 21:30:58,080 - nornir.core.task -    ERROR -      start() - Host 'Client2': task 'netmiko_send_command' failed with traceback:
Traceback (most recent call last):
  File "/home/macaktom/.local/share/virtualenvs/network_automation-NLxdyicX/lib/python3.8/site-packages/netmiko/base_connection.py", line 884, in establish_connection
    self.remote_conn_pre.connect(**ssh_connect_params)
  File "/home/macaktom/.local/share/virtualenvs/network_automation-NLxdyicX/lib/python3.8/site-packages/paramiko/client.py", line 368, in connect
    raise NoValidConnectionsError(errors)
paramiko.ssh_exception.NoValidConnectionsError: [Errno None] Unable to connect to port 22 on 10.0.0.7

During handling of the above exception, another exception occurred:

Traceback (most recent call last):
  File "/home/macaktom/.local/share/virtualenvs/network_automation-NLxdyicX/lib/python3.8/site-packages/nornir/core/task.py", line 85, in start
    r = self.task(self, **self.params)
  File "/home/macaktom/.local/share/virtualenvs/network_automation-NLxdyicX/lib/python3.8/site-packages/nornir/plugins/tasks/networking/netmiko_send_command.py", line 26, in netmiko_send_command
    net_connect = task.host.get_connection("netmiko", task.nornir.config)
  File "/home/macaktom/.local/share/virtualenvs/network_automation-NLxdyicX/lib/python3.8/site-packages/nornir/core/inventory.py", line 294, in get_connection
    self.open_connection(
  File "/home/macaktom/.local/share/virtualenvs/network_automation-NLxdyicX/lib/python3.8/site-packages/nornir/core/inventory.py", line 345, in open_connection
    self.connections[connection].open(
  File "/home/macaktom/.local/share/virtualenvs/network_automation-NLxdyicX/lib/python3.8/site-packages/nornir/plugins/connections/netmiko.py", line 58, in open
    self.connection = ConnectHandler(**parameters)
  File "/home/macaktom/.local/share/virtualenvs/network_automation-NLxdyicX/lib/python3.8/site-packages/netmiko/ssh_dispatcher.py", line 246, in ConnectHandler
    return ConnectionClass(*args, **kwargs)
  File "/home/macaktom/.local/share/virtualenvs/network_automation-NLxdyicX/lib/python3.8/site-packages/netmiko/base_connection.py", line 317, in __init__
    self._open()
  File "/home/macaktom/.local/share/virtualenvs/network_automation-NLxdyicX/lib/python3.8/site-packages/netmiko/base_connection.py", line 322, in _open
    self.establish_connection()
  File "/home/macaktom/.local/share/virtualenvs/network_automation-NLxdyicX/lib/python3.8/site-packages/netmiko/base_connection.py", line 890, in establish_connection
    raise NetMikoTimeoutException(msg)
netmiko.ssh_exception.NetMikoTimeoutException: Connection to device timed-out: linux 10.0.0.7:22

