2021-04-08 09:36:33,395 -  nornir.core -     INFO -        run() - Running task 'show_device_facts' with args {'json_out': False} on 4 hosts
2021-04-08 09:36:36,457 - nornir.core.task -    ERROR -      start() - Host 'R2': task 'Show device basic facts' failed with traceback:
Traceback (most recent call last):
  File "/home/macaktom/.local/share/virtualenvs/network_automation-NLxdyicX/lib/python3.8/site-packages/jnpr/junos/device.py", line 1347, in open
    self._conn = netconf_ssh.connect(
  File "/home/macaktom/.local/share/virtualenvs/network_automation-NLxdyicX/lib/python3.8/site-packages/ncclient/manager.py", line 168, in connect
    return connect_ssh(*args, **kwds)
  File "/home/macaktom/.local/share/virtualenvs/network_automation-NLxdyicX/lib/python3.8/site-packages/ncclient/manager.py", line 135, in connect_ssh
    session.connect(*args, **kwds)
  File "/home/macaktom/.local/share/virtualenvs/network_automation-NLxdyicX/lib/python3.8/site-packages/ncclient/transport/ssh.py", line 291, in connect
    raise SSHError("Could not open socket to %s:%s" % (host, port))
ncclient.transport.errors.SSHError: Could not open socket to 10.10.10.3:22

During handling of the above exception, another exception occurred:

Traceback (most recent call last):
  File "/home/macaktom/.local/share/virtualenvs/network_automation-NLxdyicX/lib/python3.8/site-packages/napalm/junos/junos.py", line 127, in open
    self.device.open(auto_probe=self.auto_probe)
  File "/home/macaktom/.local/share/virtualenvs/network_automation-NLxdyicX/lib/python3.8/site-packages/jnpr/junos/device.py", line 1385, in open
    raise EzErrors.ConnectTimeoutError(self)
jnpr.junos.exception.ConnectTimeoutError: ConnectTimeoutError(10.10.10.3)

The above exception was the direct cause of the following exception:

Traceback (most recent call last):
  File "/home/macaktom/.local/share/virtualenvs/network_automation-NLxdyicX/lib/python3.8/site-packages/nornir/core/task.py", line 98, in start
    r = self.task(self, **self.params)
  File "/home/macaktom/.local/share/virtualenvs/network_automation-NLxdyicX/lib/python3.8/site-packages/nornir_napalm/plugins/tasks/napalm_get.py", line 32, in napalm_get
    device = task.host.get_connection(CONNECTION_NAME, task.nornir.config)
  File "/home/macaktom/.local/share/virtualenvs/network_automation-NLxdyicX/lib/python3.8/site-packages/nornir/core/inventory.py", line 440, in get_connection
    self.open_connection(
  File "/home/macaktom/.local/share/virtualenvs/network_automation-NLxdyicX/lib/python3.8/site-packages/nornir/core/inventory.py", line 492, in open_connection
    conn_obj.open(
  File "/home/macaktom/.local/share/virtualenvs/network_automation-NLxdyicX/lib/python3.8/site-packages/nornir_napalm/plugins/connections/__init__.py", line 57, in open
    connection.open()
  File "/home/macaktom/.local/share/virtualenvs/network_automation-NLxdyicX/lib/python3.8/site-packages/napalm/junos/junos.py", line 129, in open
    raise ConnectionException(cte.msg) from cte
napalm.base.exceptions.ConnectionException: None

2021-04-08 09:36:36,458 - nornir.core.task -    ERROR -      start() - Host 'R2': task 'show_device_facts' failed with traceback:
Traceback (most recent call last):
  File "/home/macaktom/.local/share/virtualenvs/network_automation-NLxdyicX/lib/python3.8/site-packages/nornir/core/task.py", line 98, in start
    r = self.task(self, **self.params)
  File "/home/macaktom/PycharmProjects/network_automation/modules/utility/network_info_viewer.py", line 236, in show_device_facts
    result = task.run(task=napalm_get, name="Show device basic facts", getters=["facts"])
  File "/home/macaktom/.local/share/virtualenvs/network_automation-NLxdyicX/lib/python3.8/site-packages/nornir/core/task.py", line 168, in run
    raise NornirSubTaskError(task=run_task, result=r)
nornir.core.exceptions.NornirSubTaskError: Subtask: Show device basic facts (failed)


2021-04-08 09:37:23,306 -  nornir.core -     INFO -        run() - Running task 'show_device_facts' with args {'json_out': False} on 4 hosts
2021-04-08 09:37:26,373 - nornir.core.task -    ERROR -      start() - Host 'R2': task 'Show device basic facts' failed with traceback:
Traceback (most recent call last):
  File "/home/macaktom/.local/share/virtualenvs/network_automation-NLxdyicX/lib/python3.8/site-packages/jnpr/junos/device.py", line 1347, in open
    self._conn = netconf_ssh.connect(
  File "/home/macaktom/.local/share/virtualenvs/network_automation-NLxdyicX/lib/python3.8/site-packages/ncclient/manager.py", line 168, in connect
    return connect_ssh(*args, **kwds)
  File "/home/macaktom/.local/share/virtualenvs/network_automation-NLxdyicX/lib/python3.8/site-packages/ncclient/manager.py", line 135, in connect_ssh
    session.connect(*args, **kwds)
  File "/home/macaktom/.local/share/virtualenvs/network_automation-NLxdyicX/lib/python3.8/site-packages/ncclient/transport/ssh.py", line 291, in connect
    raise SSHError("Could not open socket to %s:%s" % (host, port))
ncclient.transport.errors.SSHError: Could not open socket to 10.10.10.3:22

During handling of the above exception, another exception occurred:

Traceback (most recent call last):
  File "/home/macaktom/.local/share/virtualenvs/network_automation-NLxdyicX/lib/python3.8/site-packages/napalm/junos/junos.py", line 127, in open
    self.device.open(auto_probe=self.auto_probe)
  File "/home/macaktom/.local/share/virtualenvs/network_automation-NLxdyicX/lib/python3.8/site-packages/jnpr/junos/device.py", line 1385, in open
    raise EzErrors.ConnectTimeoutError(self)
jnpr.junos.exception.ConnectTimeoutError: ConnectTimeoutError(10.10.10.3)

The above exception was the direct cause of the following exception:

Traceback (most recent call last):
  File "/home/macaktom/.local/share/virtualenvs/network_automation-NLxdyicX/lib/python3.8/site-packages/nornir/core/task.py", line 98, in start
    r = self.task(self, **self.params)
  File "/home/macaktom/.local/share/virtualenvs/network_automation-NLxdyicX/lib/python3.8/site-packages/nornir_napalm/plugins/tasks/napalm_get.py", line 32, in napalm_get
    device = task.host.get_connection(CONNECTION_NAME, task.nornir.config)
  File "/home/macaktom/.local/share/virtualenvs/network_automation-NLxdyicX/lib/python3.8/site-packages/nornir/core/inventory.py", line 440, in get_connection
    self.open_connection(
  File "/home/macaktom/.local/share/virtualenvs/network_automation-NLxdyicX/lib/python3.8/site-packages/nornir/core/inventory.py", line 492, in open_connection
    conn_obj.open(
  File "/home/macaktom/.local/share/virtualenvs/network_automation-NLxdyicX/lib/python3.8/site-packages/nornir_napalm/plugins/connections/__init__.py", line 57, in open
    connection.open()
  File "/home/macaktom/.local/share/virtualenvs/network_automation-NLxdyicX/lib/python3.8/site-packages/napalm/junos/junos.py", line 129, in open
    raise ConnectionException(cte.msg) from cte
napalm.base.exceptions.ConnectionException: None

2021-04-08 09:37:26,374 - nornir.core.task -    ERROR -      start() - Host 'R2': task 'show_device_facts' failed with traceback:
Traceback (most recent call last):
  File "/home/macaktom/.local/share/virtualenvs/network_automation-NLxdyicX/lib/python3.8/site-packages/nornir/core/task.py", line 98, in start
    r = self.task(self, **self.params)
  File "/home/macaktom/PycharmProjects/network_automation/modules/utility/network_info_viewer.py", line 236, in show_device_facts
    result = task.run(task=napalm_get, name="Show device basic facts", getters=["facts"])
  File "/home/macaktom/.local/share/virtualenvs/network_automation-NLxdyicX/lib/python3.8/site-packages/nornir/core/task.py", line 168, in run
    raise NornirSubTaskError(task=run_task, result=r)
nornir.core.exceptions.NornirSubTaskError: Subtask: Show device basic facts (failed)


2021-04-08 09:37:46,862 -  nornir.core -     INFO -        run() - Running task 'show_device_facts' with args {'json_out': False} on 4 hosts
2021-04-08 13:59:59,354 -  nornir.core -     INFO -        run() - Running task 'show_device_facts' with args {'json_out': False} on 4 hosts
2021-04-08 14:21:59,087 -  nornir.core -     INFO -        run() - Running task 'show_device_facts' with args {'json_out': False} on 4 hosts
2021-04-08 14:22:03,722 -  nornir.core -     INFO -        run() - Running task 'show_ospf_neighbors' with args {'ipv6': True} on 4 hosts
2021-04-08 14:22:03,726 - nornir.core.task -    ERROR -      start() - Host 'MLS1': task 'show_ospf_neighbors' failed with traceback:
Traceback (most recent call last):
  File "/home/macaktom/.local/share/virtualenvs/network_automation-NLxdyicX/lib/python3.8/site-packages/nornir/core/task.py", line 98, in start
    r = self.task(self, **self.params)
  File "/home/macaktom/PycharmProjects/network_automation/modules/utility/network_info_viewer.py", line 321, in show_ospf_neighbors
    raise NornirSubTaskError("Function was not implemented for particular device.", task)
nornir.core.exceptions.NornirSubTaskError: Subtask: Function was not implemented for particular device. (failed)


2021-04-08 14:22:16,473 -  nornir.core -     INFO -        run() - Running task 'IPv4 interfaces config' with args {'dry_run': False} on 4 hosts
2021-04-08 14:22:34,576 - nornir.core.task -    ERROR -      start() - Host 'R3': task 'Loading IPv4 interfaces Configuration on the device' failed with traceback:
Traceback (most recent call last):
  File "/home/macaktom/.local/share/virtualenvs/network_automation-NLxdyicX/lib/python3.8/site-packages/nornir/core/task.py", line 98, in start
    r = self.task(self, **self.params)
  File "/home/macaktom/.local/share/virtualenvs/network_automation-NLxdyicX/lib/python3.8/site-packages/nornir_napalm/plugins/tasks/napalm_configure.py", line 39, in napalm_configure
    device.commit_config()
  File "/home/macaktom/.local/share/virtualenvs/network_automation-NLxdyicX/lib/python3.8/site-packages/napalm/ios/ios.py", line 556, in commit_config
    output += self.device.save_config()
  File "/home/macaktom/.local/share/virtualenvs/network_automation-NLxdyicX/lib/python3.8/site-packages/netmiko/cisco/cisco_ios.py", line 36, in save_config
    return super().save_config(
  File "/home/macaktom/.local/share/virtualenvs/network_automation-NLxdyicX/lib/python3.8/site-packages/netmiko/cisco_base_connection.py", line 232, in save_config
    output = self.send_command(
  File "/home/macaktom/.local/share/virtualenvs/network_automation-NLxdyicX/lib/python3.8/site-packages/netmiko/utilities.py", line 429, in wrapper_decorator
    return func(self, *args, **kwargs)
  File "/home/macaktom/.local/share/virtualenvs/network_automation-NLxdyicX/lib/python3.8/site-packages/netmiko/base_connection.py", line 1523, in send_command
    raise IOError(
OSError: Search pattern never detected in send_command: R3\#

2021-04-08 14:22:34,577 - nornir.core.task -    ERROR -      start() - Host 'R3': task 'IPv4 interfaces config' failed with traceback:
Traceback (most recent call last):
  File "/home/macaktom/.local/share/virtualenvs/network_automation-NLxdyicX/lib/python3.8/site-packages/nornir/core/task.py", line 98, in start
    r = self.task(self, **self.params)
  File "/home/macaktom/PycharmProjects/network_automation/modules/tasks/interfaces_configuration.py", line 44, in configure_ipv4_interfaces
    task.run(task=napalm_configure,
  File "/home/macaktom/.local/share/virtualenvs/network_automation-NLxdyicX/lib/python3.8/site-packages/nornir/core/task.py", line 168, in run
    raise NornirSubTaskError(task=run_task, result=r)
nornir.core.exceptions.NornirSubTaskError: Subtask: Loading IPv4 interfaces Configuration on the device (failed)


2021-04-08 14:22:34,639 - nornir.core.task -    ERROR -      start() - Host 'R1': task 'Loading IPv4 interfaces Configuration on the device' failed with traceback:
Traceback (most recent call last):
  File "/home/macaktom/.local/share/virtualenvs/network_automation-NLxdyicX/lib/python3.8/site-packages/nornir/core/task.py", line 98, in start
    r = self.task(self, **self.params)
  File "/home/macaktom/.local/share/virtualenvs/network_automation-NLxdyicX/lib/python3.8/site-packages/nornir_napalm/plugins/tasks/napalm_configure.py", line 39, in napalm_configure
    device.commit_config()
  File "/home/macaktom/.local/share/virtualenvs/network_automation-NLxdyicX/lib/python3.8/site-packages/napalm/ios/ios.py", line 556, in commit_config
    output += self.device.save_config()
  File "/home/macaktom/.local/share/virtualenvs/network_automation-NLxdyicX/lib/python3.8/site-packages/netmiko/cisco/cisco_ios.py", line 36, in save_config
    return super().save_config(
  File "/home/macaktom/.local/share/virtualenvs/network_automation-NLxdyicX/lib/python3.8/site-packages/netmiko/cisco_base_connection.py", line 232, in save_config
    output = self.send_command(
  File "/home/macaktom/.local/share/virtualenvs/network_automation-NLxdyicX/lib/python3.8/site-packages/netmiko/utilities.py", line 429, in wrapper_decorator
    return func(self, *args, **kwargs)
  File "/home/macaktom/.local/share/virtualenvs/network_automation-NLxdyicX/lib/python3.8/site-packages/netmiko/base_connection.py", line 1523, in send_command
    raise IOError(
OSError: Search pattern never detected in send_command: R1\#

2021-04-08 14:22:34,640 - nornir.core.task -    ERROR -      start() - Host 'R1': task 'IPv4 interfaces config' failed with traceback:
Traceback (most recent call last):
  File "/home/macaktom/.local/share/virtualenvs/network_automation-NLxdyicX/lib/python3.8/site-packages/nornir/core/task.py", line 98, in start
    r = self.task(self, **self.params)
  File "/home/macaktom/PycharmProjects/network_automation/modules/tasks/interfaces_configuration.py", line 44, in configure_ipv4_interfaces
    task.run(task=napalm_configure,
  File "/home/macaktom/.local/share/virtualenvs/network_automation-NLxdyicX/lib/python3.8/site-packages/nornir/core/task.py", line 168, in run
    raise NornirSubTaskError(task=run_task, result=r)
nornir.core.exceptions.NornirSubTaskError: Subtask: Loading IPv4 interfaces Configuration on the device (failed)


2021-04-08 14:22:34,641 -  nornir.core -     INFO -        run() - Running task 'IPv6 interfaces config' with args {'dry_run': False} on 4 hosts
2021-04-08 14:23:04,943 -  nornir.core -     INFO -        run() - Running task 'IPv4 interfaces config' with args {'dry_run': False} on 4 hosts
2021-04-08 14:23:14,009 -  nornir.core -     INFO -        run() - Running task 'IPv6 interfaces config' with args {'dry_run': False} on 4 hosts
2021-04-08 14:23:32,293 -  nornir.core -     INFO -        run() - Running task 'Switching interfaces config' with args {'dry_run': False} on 1 hosts
2021-04-08 14:24:51,203 -  nornir.core -     INFO -        run() - Running task 'Switching interfaces config' with args {'dry_run': False} on 1 hosts
2021-04-08 14:25:37,228 -  nornir.core -     INFO -        run() - Running task 'OSPFv2 config' with args {'dry_run': False} on 3 hosts
2021-04-08 14:25:46,506 -  nornir.core -     INFO -        run() - Running task 'OSPFv3 config' with args {'dry_run': False} on 3 hosts
2021-04-08 14:27:55,653 -  nornir.core -     INFO -        run() - Running task 'OSPFv2 config' with args {'dry_run': False} on 3 hosts
2021-04-08 14:28:03,509 -  nornir.core -     INFO -        run() - Running task 'OSPFv3 config' with args {'dry_run': False} on 3 hosts
2021-04-08 14:30:36,039 -  nornir.core -     INFO -        run() - Running task 'EIGRP config' with args {'dry_run': False} on 2 hosts
2021-04-08 14:30:37,111 - nornir.core.task -    ERROR -      start() - Host 'R3': task 'Loading EIGRP IPv4 Configuration on the device' failed with traceback:
Traceback (most recent call last):
  File "/home/macaktom/.local/share/virtualenvs/network_automation-NLxdyicX/lib/python3.8/site-packages/nornir/core/task.py", line 98, in start
    r = self.task(self, **self.params)
  File "/home/macaktom/.local/share/virtualenvs/network_automation-NLxdyicX/lib/python3.8/site-packages/nornir_napalm/plugins/tasks/napalm_configure.py", line 34, in napalm_configure
    device.load_merge_candidate(filename=filename, config=configuration)
  File "/home/macaktom/.local/share/virtualenvs/network_automation-NLxdyicX/lib/python3.8/site-packages/napalm/ios/ios.py", line 323, in load_merge_candidate
    raise MergeConfigException(msg)
napalm.base.exceptions.MergeConfigException: Transfer to remote device failed

2021-04-08 14:30:37,111 - nornir.core.task -    ERROR -      start() - Host 'R3': task 'EIGRP config' failed with traceback:
Traceback (most recent call last):
  File "/home/macaktom/.local/share/virtualenvs/network_automation-NLxdyicX/lib/python3.8/site-packages/nornir/core/task.py", line 98, in start
    r = self.task(self, **self.params)
  File "/home/macaktom/PycharmProjects/network_automation/modules/tasks/eigrp_configuration.py", line 49, in configure_eigrp_ipv4
    task.run(task=napalm_configure,
  File "/home/macaktom/.local/share/virtualenvs/network_automation-NLxdyicX/lib/python3.8/site-packages/nornir/core/task.py", line 168, in run
    raise NornirSubTaskError(task=run_task, result=r)
nornir.core.exceptions.NornirSubTaskError: Subtask: Loading EIGRP IPv4 Configuration on the device (failed)


2021-04-08 14:30:37,374 - nornir.core.task -    ERROR -      start() - Host 'MLS1': task 'Loading EIGRP IPv4 Configuration on the device' failed with traceback:
Traceback (most recent call last):
  File "/home/macaktom/.local/share/virtualenvs/network_automation-NLxdyicX/lib/python3.8/site-packages/nornir/core/task.py", line 98, in start
    r = self.task(self, **self.params)
  File "/home/macaktom/.local/share/virtualenvs/network_automation-NLxdyicX/lib/python3.8/site-packages/nornir_napalm/plugins/tasks/napalm_configure.py", line 34, in napalm_configure
    device.load_merge_candidate(filename=filename, config=configuration)
  File "/home/macaktom/.local/share/virtualenvs/network_automation-NLxdyicX/lib/python3.8/site-packages/napalm/ios/ios.py", line 323, in load_merge_candidate
    raise MergeConfigException(msg)
napalm.base.exceptions.MergeConfigException: Transfer to remote device failed

2021-04-08 14:30:37,375 - nornir.core.task -    ERROR -      start() - Host 'MLS1': task 'EIGRP config' failed with traceback:
Traceback (most recent call last):
  File "/home/macaktom/.local/share/virtualenvs/network_automation-NLxdyicX/lib/python3.8/site-packages/nornir/core/task.py", line 98, in start
    r = self.task(self, **self.params)
  File "/home/macaktom/PycharmProjects/network_automation/modules/tasks/eigrp_configuration.py", line 49, in configure_eigrp_ipv4
    task.run(task=napalm_configure,
  File "/home/macaktom/.local/share/virtualenvs/network_automation-NLxdyicX/lib/python3.8/site-packages/nornir/core/task.py", line 168, in run
    raise NornirSubTaskError(task=run_task, result=r)
nornir.core.exceptions.NornirSubTaskError: Subtask: Loading EIGRP IPv4 Configuration on the device (failed)


2021-04-08 14:30:37,376 -  nornir.core -     INFO -        run() - Running task 'EIGRP IPV6 config' with args {'dry_run': False} on 2 hosts
2021-04-08 14:30:37,376 -  nornir.core -     INFO -        run() - Running task 'IPv4 packet filter config' with args {'dry_run': False} on 1 hosts
2021-04-08 14:30:37,376 -  nornir.core -     INFO -        run() - Running task 'IPv6 packet filter config' with args {'dry_run': False} on 1 hosts
2021-04-08 14:31:16,443 -  nornir.core -     INFO -        run() - Running task 'EIGRP config' with args {'dry_run': False} on 2 hosts
2021-04-08 14:31:17,488 - nornir.core.task -    ERROR -      start() - Host 'R3': task 'Loading EIGRP IPv4 Configuration on the device' failed with traceback:
Traceback (most recent call last):
  File "/home/macaktom/.local/share/virtualenvs/network_automation-NLxdyicX/lib/python3.8/site-packages/nornir/core/task.py", line 98, in start
    r = self.task(self, **self.params)
  File "/home/macaktom/.local/share/virtualenvs/network_automation-NLxdyicX/lib/python3.8/site-packages/nornir_napalm/plugins/tasks/napalm_configure.py", line 34, in napalm_configure
    device.load_merge_candidate(filename=filename, config=configuration)
  File "/home/macaktom/.local/share/virtualenvs/network_automation-NLxdyicX/lib/python3.8/site-packages/napalm/ios/ios.py", line 323, in load_merge_candidate
    raise MergeConfigException(msg)
napalm.base.exceptions.MergeConfigException: Transfer to remote device failed

2021-04-08 14:31:17,489 - nornir.core.task -    ERROR -      start() - Host 'R3': task 'EIGRP config' failed with traceback:
Traceback (most recent call last):
  File "/home/macaktom/.local/share/virtualenvs/network_automation-NLxdyicX/lib/python3.8/site-packages/nornir/core/task.py", line 98, in start
    r = self.task(self, **self.params)
  File "/home/macaktom/PycharmProjects/network_automation/modules/tasks/eigrp_configuration.py", line 49, in configure_eigrp_ipv4
    task.run(task=napalm_configure,
  File "/home/macaktom/.local/share/virtualenvs/network_automation-NLxdyicX/lib/python3.8/site-packages/nornir/core/task.py", line 168, in run
    raise NornirSubTaskError(task=run_task, result=r)
nornir.core.exceptions.NornirSubTaskError: Subtask: Loading EIGRP IPv4 Configuration on the device (failed)


2021-04-08 14:31:17,566 - nornir.core.task -    ERROR -      start() - Host 'MLS1': task 'Loading EIGRP IPv4 Configuration on the device' failed with traceback:
Traceback (most recent call last):
  File "/home/macaktom/.local/share/virtualenvs/network_automation-NLxdyicX/lib/python3.8/site-packages/nornir/core/task.py", line 98, in start
    r = self.task(self, **self.params)
  File "/home/macaktom/.local/share/virtualenvs/network_automation-NLxdyicX/lib/python3.8/site-packages/nornir_napalm/plugins/tasks/napalm_configure.py", line 34, in napalm_configure
    device.load_merge_candidate(filename=filename, config=configuration)
  File "/home/macaktom/.local/share/virtualenvs/network_automation-NLxdyicX/lib/python3.8/site-packages/napalm/ios/ios.py", line 323, in load_merge_candidate
    raise MergeConfigException(msg)
napalm.base.exceptions.MergeConfigException: Transfer to remote device failed

2021-04-08 14:31:17,567 - nornir.core.task -    ERROR -      start() - Host 'MLS1': task 'EIGRP config' failed with traceback:
Traceback (most recent call last):
  File "/home/macaktom/.local/share/virtualenvs/network_automation-NLxdyicX/lib/python3.8/site-packages/nornir/core/task.py", line 98, in start
    r = self.task(self, **self.params)
  File "/home/macaktom/PycharmProjects/network_automation/modules/tasks/eigrp_configuration.py", line 49, in configure_eigrp_ipv4
    task.run(task=napalm_configure,
  File "/home/macaktom/.local/share/virtualenvs/network_automation-NLxdyicX/lib/python3.8/site-packages/nornir/core/task.py", line 168, in run
    raise NornirSubTaskError(task=run_task, result=r)
nornir.core.exceptions.NornirSubTaskError: Subtask: Loading EIGRP IPv4 Configuration on the device (failed)


2021-04-08 14:31:17,567 -  nornir.core -     INFO -        run() - Running task 'EIGRP IPV6 config' with args {'dry_run': False} on 2 hosts
2021-04-08 14:31:17,568 -  nornir.core -     INFO -        run() - Running task 'IPv4 packet filter config' with args {'dry_run': False} on 1 hosts
2021-04-08 14:31:17,568 -  nornir.core -     INFO -        run() - Running task 'IPv6 packet filter config' with args {'dry_run': False} on 1 hosts
2021-04-08 14:31:49,723 -  nornir.core -     INFO -        run() - Running task 'EIGRP config' with args {'dry_run': False} on 2 hosts
2021-04-08 14:31:50,749 - nornir.core.task -    ERROR -      start() - Host 'R3': task 'Loading EIGRP IPv4 Configuration on the device' failed with traceback:
Traceback (most recent call last):
  File "/home/macaktom/.local/share/virtualenvs/network_automation-NLxdyicX/lib/python3.8/site-packages/nornir/core/task.py", line 98, in start
    r = self.task(self, **self.params)
  File "/home/macaktom/.local/share/virtualenvs/network_automation-NLxdyicX/lib/python3.8/site-packages/nornir_napalm/plugins/tasks/napalm_configure.py", line 34, in napalm_configure
    device.load_merge_candidate(filename=filename, config=configuration)
  File "/home/macaktom/.local/share/virtualenvs/network_automation-NLxdyicX/lib/python3.8/site-packages/napalm/ios/ios.py", line 323, in load_merge_candidate
    raise MergeConfigException(msg)
napalm.base.exceptions.MergeConfigException: Transfer to remote device failed

2021-04-08 14:31:50,749 - nornir.core.task -    ERROR -      start() - Host 'R3': task 'EIGRP config' failed with traceback:
Traceback (most recent call last):
  File "/home/macaktom/.local/share/virtualenvs/network_automation-NLxdyicX/lib/python3.8/site-packages/nornir/core/task.py", line 98, in start
    r = self.task(self, **self.params)
  File "/home/macaktom/PycharmProjects/network_automation/modules/tasks/eigrp_configuration.py", line 49, in configure_eigrp_ipv4
    task.run(task=napalm_configure,
  File "/home/macaktom/.local/share/virtualenvs/network_automation-NLxdyicX/lib/python3.8/site-packages/nornir/core/task.py", line 168, in run
    raise NornirSubTaskError(task=run_task, result=r)
nornir.core.exceptions.NornirSubTaskError: Subtask: Loading EIGRP IPv4 Configuration on the device (failed)


2021-04-08 14:31:50,857 - nornir.core.task -    ERROR -      start() - Host 'MLS1': task 'Loading EIGRP IPv4 Configuration on the device' failed with traceback:
Traceback (most recent call last):
  File "/home/macaktom/.local/share/virtualenvs/network_automation-NLxdyicX/lib/python3.8/site-packages/nornir/core/task.py", line 98, in start
    r = self.task(self, **self.params)
  File "/home/macaktom/.local/share/virtualenvs/network_automation-NLxdyicX/lib/python3.8/site-packages/nornir_napalm/plugins/tasks/napalm_configure.py", line 34, in napalm_configure
    device.load_merge_candidate(filename=filename, config=configuration)
  File "/home/macaktom/.local/share/virtualenvs/network_automation-NLxdyicX/lib/python3.8/site-packages/napalm/ios/ios.py", line 323, in load_merge_candidate
    raise MergeConfigException(msg)
napalm.base.exceptions.MergeConfigException: Transfer to remote device failed

2021-04-08 14:31:50,857 - nornir.core.task -    ERROR -      start() - Host 'MLS1': task 'EIGRP config' failed with traceback:
Traceback (most recent call last):
  File "/home/macaktom/.local/share/virtualenvs/network_automation-NLxdyicX/lib/python3.8/site-packages/nornir/core/task.py", line 98, in start
    r = self.task(self, **self.params)
  File "/home/macaktom/PycharmProjects/network_automation/modules/tasks/eigrp_configuration.py", line 49, in configure_eigrp_ipv4
    task.run(task=napalm_configure,
  File "/home/macaktom/.local/share/virtualenvs/network_automation-NLxdyicX/lib/python3.8/site-packages/nornir/core/task.py", line 168, in run
    raise NornirSubTaskError(task=run_task, result=r)
nornir.core.exceptions.NornirSubTaskError: Subtask: Loading EIGRP IPv4 Configuration on the device (failed)


2021-04-08 14:31:50,859 -  nornir.core -     INFO -        run() - Running task 'EIGRP IPV6 config' with args {'dry_run': False} on 2 hosts
2021-04-08 14:31:50,859 -  nornir.core -     INFO -        run() - Running task 'IPv4 packet filter config' with args {'dry_run': False} on 1 hosts
2021-04-08 14:31:50,860 -  nornir.core -     INFO -        run() - Running task 'IPv6 packet filter config' with args {'dry_run': False} on 1 hosts
2021-04-08 14:32:01,279 -  nornir.core -     INFO -        run() - Running task 'IPv4 packet filter config' with args {'dry_run': False} on 1 hosts
2021-04-08 14:32:10,118 -  nornir.core -     INFO -        run() - Running task 'IPv6 packet filter config' with args {'dry_run': False} on 1 hosts
2021-04-08 14:32:28,997 -  nornir.core -     INFO -        run() - Running task 'IPv4 packet filter config' with args {'dry_run': False} on 1 hosts
2021-04-08 14:32:35,936 -  nornir.core -     INFO -        run() - Running task 'IPv6 packet filter config' with args {'dry_run': False} on 1 hosts
2021-04-08 14:33:39,777 -  nornir.core -     INFO -        run() - Running task 'EIGRP config' with args {'dry_run': False} on 2 hosts
2021-04-08 14:33:40,910 - nornir.core.task -    ERROR -      start() - Host 'MLS1': task 'Loading EIGRP IPv4 Configuration on the device' failed with traceback:
Traceback (most recent call last):
  File "/home/macaktom/.local/share/virtualenvs/network_automation-NLxdyicX/lib/python3.8/site-packages/nornir/core/task.py", line 98, in start
    r = self.task(self, **self.params)
  File "/home/macaktom/.local/share/virtualenvs/network_automation-NLxdyicX/lib/python3.8/site-packages/nornir_napalm/plugins/tasks/napalm_configure.py", line 34, in napalm_configure
    device.load_merge_candidate(filename=filename, config=configuration)
  File "/home/macaktom/.local/share/virtualenvs/network_automation-NLxdyicX/lib/python3.8/site-packages/napalm/ios/ios.py", line 323, in load_merge_candidate
    raise MergeConfigException(msg)
napalm.base.exceptions.MergeConfigException: Transfer to remote device failed

2021-04-08 14:33:40,911 - nornir.core.task -    ERROR -      start() - Host 'MLS1': task 'EIGRP config' failed with traceback:
Traceback (most recent call last):
  File "/home/macaktom/.local/share/virtualenvs/network_automation-NLxdyicX/lib/python3.8/site-packages/nornir/core/task.py", line 98, in start
    r = self.task(self, **self.params)
  File "/home/macaktom/PycharmProjects/network_automation/modules/tasks/eigrp_configuration.py", line 49, in configure_eigrp_ipv4
    task.run(task=napalm_configure,
  File "/home/macaktom/.local/share/virtualenvs/network_automation-NLxdyicX/lib/python3.8/site-packages/nornir/core/task.py", line 168, in run
    raise NornirSubTaskError(task=run_task, result=r)
nornir.core.exceptions.NornirSubTaskError: Subtask: Loading EIGRP IPv4 Configuration on the device (failed)


2021-04-08 14:33:40,954 - nornir.core.task -    ERROR -      start() - Host 'R3': task 'Loading EIGRP IPv4 Configuration on the device' failed with traceback:
Traceback (most recent call last):
  File "/home/macaktom/.local/share/virtualenvs/network_automation-NLxdyicX/lib/python3.8/site-packages/nornir/core/task.py", line 98, in start
    r = self.task(self, **self.params)
  File "/home/macaktom/.local/share/virtualenvs/network_automation-NLxdyicX/lib/python3.8/site-packages/nornir_napalm/plugins/tasks/napalm_configure.py", line 34, in napalm_configure
    device.load_merge_candidate(filename=filename, config=configuration)
  File "/home/macaktom/.local/share/virtualenvs/network_automation-NLxdyicX/lib/python3.8/site-packages/napalm/ios/ios.py", line 323, in load_merge_candidate
    raise MergeConfigException(msg)
napalm.base.exceptions.MergeConfigException: Transfer to remote device failed

2021-04-08 14:33:40,955 - nornir.core.task -    ERROR -      start() - Host 'R3': task 'EIGRP config' failed with traceback:
Traceback (most recent call last):
  File "/home/macaktom/.local/share/virtualenvs/network_automation-NLxdyicX/lib/python3.8/site-packages/nornir/core/task.py", line 98, in start
    r = self.task(self, **self.params)
  File "/home/macaktom/PycharmProjects/network_automation/modules/tasks/eigrp_configuration.py", line 49, in configure_eigrp_ipv4
    task.run(task=napalm_configure,
  File "/home/macaktom/.local/share/virtualenvs/network_automation-NLxdyicX/lib/python3.8/site-packages/nornir/core/task.py", line 168, in run
    raise NornirSubTaskError(task=run_task, result=r)
nornir.core.exceptions.NornirSubTaskError: Subtask: Loading EIGRP IPv4 Configuration on the device (failed)


2021-04-08 14:33:40,956 -  nornir.core -     INFO -        run() - Running task 'EIGRP IPV6 config' with args {'dry_run': False} on 2 hosts
2021-04-08 14:34:38,951 -  nornir.core -     INFO -        run() - Running task 'EIGRP config' with args {'dry_run': False} on 2 hosts
2021-04-08 14:34:40,139 - nornir.core.task -    ERROR -      start() - Host 'MLS1': task 'Loading EIGRP IPv4 Configuration on the device' failed with traceback:
Traceback (most recent call last):
  File "/home/macaktom/.local/share/virtualenvs/network_automation-NLxdyicX/lib/python3.8/site-packages/nornir/core/task.py", line 98, in start
    r = self.task(self, **self.params)
  File "/home/macaktom/.local/share/virtualenvs/network_automation-NLxdyicX/lib/python3.8/site-packages/nornir_napalm/plugins/tasks/napalm_configure.py", line 34, in napalm_configure
    device.load_merge_candidate(filename=filename, config=configuration)
  File "/home/macaktom/.local/share/virtualenvs/network_automation-NLxdyicX/lib/python3.8/site-packages/napalm/ios/ios.py", line 323, in load_merge_candidate
    raise MergeConfigException(msg)
napalm.base.exceptions.MergeConfigException: Transfer to remote device failed

2021-04-08 14:34:40,139 - nornir.core.task -    ERROR -      start() - Host 'MLS1': task 'EIGRP config' failed with traceback:
Traceback (most recent call last):
  File "/home/macaktom/.local/share/virtualenvs/network_automation-NLxdyicX/lib/python3.8/site-packages/nornir/core/task.py", line 98, in start
    r = self.task(self, **self.params)
  File "/home/macaktom/PycharmProjects/network_automation/modules/tasks/eigrp_configuration.py", line 49, in configure_eigrp_ipv4
    task.run(task=napalm_configure,
  File "/home/macaktom/.local/share/virtualenvs/network_automation-NLxdyicX/lib/python3.8/site-packages/nornir/core/task.py", line 168, in run
    raise NornirSubTaskError(task=run_task, result=r)
nornir.core.exceptions.NornirSubTaskError: Subtask: Loading EIGRP IPv4 Configuration on the device (failed)


2021-04-08 14:34:40,196 - nornir.core.task -    ERROR -      start() - Host 'R3': task 'Loading EIGRP IPv4 Configuration on the device' failed with traceback:
Traceback (most recent call last):
  File "/home/macaktom/.local/share/virtualenvs/network_automation-NLxdyicX/lib/python3.8/site-packages/nornir/core/task.py", line 98, in start
    r = self.task(self, **self.params)
  File "/home/macaktom/.local/share/virtualenvs/network_automation-NLxdyicX/lib/python3.8/site-packages/nornir_napalm/plugins/tasks/napalm_configure.py", line 34, in napalm_configure
    device.load_merge_candidate(filename=filename, config=configuration)
  File "/home/macaktom/.local/share/virtualenvs/network_automation-NLxdyicX/lib/python3.8/site-packages/napalm/ios/ios.py", line 323, in load_merge_candidate
    raise MergeConfigException(msg)
napalm.base.exceptions.MergeConfigException: Transfer to remote device failed

2021-04-08 14:34:40,196 - nornir.core.task -    ERROR -      start() - Host 'R3': task 'EIGRP config' failed with traceback:
Traceback (most recent call last):
  File "/home/macaktom/.local/share/virtualenvs/network_automation-NLxdyicX/lib/python3.8/site-packages/nornir/core/task.py", line 98, in start
    r = self.task(self, **self.params)
  File "/home/macaktom/PycharmProjects/network_automation/modules/tasks/eigrp_configuration.py", line 49, in configure_eigrp_ipv4
    task.run(task=napalm_configure,
  File "/home/macaktom/.local/share/virtualenvs/network_automation-NLxdyicX/lib/python3.8/site-packages/nornir/core/task.py", line 168, in run
    raise NornirSubTaskError(task=run_task, result=r)
nornir.core.exceptions.NornirSubTaskError: Subtask: Loading EIGRP IPv4 Configuration on the device (failed)


2021-04-08 14:38:49,543 -  nornir.core -     INFO -        run() - Running task 'EIGRP config' with args {'dry_run': False} on 2 hosts
2021-04-08 14:38:58,507 -  nornir.core -     INFO -        run() - Running task 'EIGRP IPV6 config' with args {'dry_run': False} on 2 hosts
2021-04-08 14:40:34,842 -  nornir.core -     INFO -        run() - Running task 'EIGRP config' with args {'dry_run': False} on 2 hosts
2021-04-08 14:40:42,755 -  nornir.core -     INFO -        run() - Running task 'EIGRP IPV6 config' with args {'dry_run': False} on 2 hosts
2021-04-08 14:41:56,375 -  nornir.core -     INFO -        run() - Running task 'EIGRP config' with args {'dry_run': False} on 2 hosts
2021-04-08 14:43:44,608 -  nornir.core -     INFO -        run() - Running task 'EIGRP config' with args {'dry_run': False} on 2 hosts
2021-04-08 14:43:52,475 -  nornir.core -     INFO -        run() - Running task 'EIGRP IPV6 config' with args {'dry_run': False} on 2 hosts
2021-04-08 14:44:49,202 -  nornir.core -     INFO -        run() - Running task 'EIGRP config' with args {'dry_run': False} on 2 hosts
2021-04-08 14:45:10,936 -  nornir.core -     INFO -        run() - Running task 'EIGRP config' with args {'dry_run': False} on 2 hosts
2021-04-08 14:45:19,375 -  nornir.core -     INFO -        run() - Running task 'EIGRP IPV6 config' with args {'dry_run': False} on 2 hosts
2021-04-08 14:45:32,613 -  nornir.core -     INFO -        run() - Running task 'EIGRP config' with args {'dry_run': False} on 2 hosts
2021-04-08 14:45:41,073 -  nornir.core -     INFO -        run() - Running task 'EIGRP IPV6 config' with args {'dry_run': False} on 2 hosts
2021-04-08 14:45:52,880 -  nornir.core -     INFO -        run() - Running task 'EIGRP config' with args {'dry_run': False} on 2 hosts
2021-04-08 14:46:01,059 -  nornir.core -     INFO -        run() - Running task 'EIGRP IPV6 config' with args {'dry_run': False} on 2 hosts
2021-04-08 14:47:23,919 -  nornir.core -     INFO -        run() - Running task 'export_device_configuration' with args {} on 4 hosts
2021-04-08 14:47:26,807 -  nornir.core -     INFO -        run() - Running task 'export_packet_filter_info' with args {} on 4 hosts
2021-04-08 14:47:32,555 -  nornir.core -     INFO -        run() - Running task 'export_ipv4_routes' with args {} on 4 hosts
2021-04-08 14:47:33,565 -  nornir.core -     INFO -        run() - Running task 'export_ipv6_routes' with args {} on 4 hosts
2021-04-08 14:47:34,373 -  nornir.core -     INFO -        run() - Running task 'get_conn_state_and_device_facts' with args {} on 4 hosts
2021-04-08 14:47:37,672 -  nornir.core -     INFO -        run() - Running task 'Get interfaces packet counters' with args {'getters': ['interfaces_counters']} on 4 hosts
2021-04-08 14:50:36,134 -  nornir.core -     INFO -        run() - Running task 'IPv4 interfaces config' with args {'dry_run': False} on 4 hosts
2021-04-08 14:51:01,196 -  nornir.core -     INFO -        run() - Running task 'IPv4 interfaces config' with args {'dry_run': False} on 4 hosts
2021-04-08 14:51:09,416 -  nornir.core -     INFO -        run() - Running task 'IPv6 interfaces config' with args {'dry_run': False} on 4 hosts
2021-04-08 14:51:17,383 -  nornir.core -     INFO -        run() - Running task 'Switching interfaces config' with args {'dry_run': False} on 1 hosts
2021-04-08 14:51:25,169 -  nornir.core -     INFO -        run() - Running task 'EIGRP config' with args {'dry_run': False} on 2 hosts
2021-04-08 14:51:33,357 -  nornir.core -     INFO -        run() - Running task 'EIGRP IPV6 config' with args {'dry_run': False} on 2 hosts
2021-04-08 14:51:40,392 -  nornir.core -     INFO -        run() - Running task 'IPv4 packet filter config' with args {'dry_run': False} on 1 hosts
2021-04-08 14:51:44,650 -  nornir.core -     INFO -        run() - Running task 'IPv6 packet filter config' with args {'dry_run': False} on 1 hosts
2021-04-08 14:51:49,039 -  nornir.core -     INFO -        run() - Running task 'export_device_configuration' with args {} on 4 hosts
2021-04-08 14:51:50,120 -  nornir.core -     INFO -        run() - Running task 'export_packet_filter_info' with args {} on 4 hosts
2021-04-08 14:57:16,924 -  nornir.core -     INFO -        run() - Running task 'IPv4 interfaces config' with args {'dry_run': False} on 4 hosts
2021-04-08 14:57:26,098 -  nornir.core -     INFO -        run() - Running task 'IPv6 interfaces config' with args {'dry_run': False} on 4 hosts
2021-04-08 14:57:34,673 -  nornir.core -     INFO -        run() - Running task 'Switching interfaces config' with args {'dry_run': False} on 1 hosts
2021-04-08 14:57:42,137 -  nornir.core -     INFO -        run() - Running task 'EIGRP config' with args {'dry_run': False} on 2 hosts
2021-04-08 14:57:49,989 -  nornir.core -     INFO -        run() - Running task 'EIGRP IPV6 config' with args {'dry_run': False} on 2 hosts
2021-04-08 14:57:56,768 -  nornir.core -     INFO -        run() - Running task 'IPv4 packet filter config' with args {'dry_run': False} on 1 hosts
2021-04-08 14:58:01,122 -  nornir.core -     INFO -        run() - Running task 'IPv6 packet filter config' with args {'dry_run': False} on 1 hosts
2021-04-08 14:58:05,769 -  nornir.core -     INFO -        run() - Running task 'export_device_configuration' with args {} on 4 hosts
2021-04-08 14:58:06,810 -  nornir.core -     INFO -        run() - Running task 'export_packet_filter_info' with args {} on 4 hosts
2021-04-08 14:58:12,516 -  nornir.core -     INFO -        run() - Running task 'export_ipv4_routes' with args {} on 4 hosts
2021-04-08 14:58:13,325 -  nornir.core -     INFO -        run() - Running task 'export_ipv6_routes' with args {} on 4 hosts
2021-04-08 15:12:57,558 -  nornir.core -     INFO -        run() - Running task 'IPv4 interfaces config' with args {'dry_run': False} on 4 hosts
2021-04-08 15:13:07,188 -  nornir.core -     INFO -        run() - Running task 'IPv6 interfaces config' with args {'dry_run': False} on 4 hosts
2021-04-08 15:13:15,737 -  nornir.core -     INFO -        run() - Running task 'Switching interfaces config' with args {'dry_run': False} on 1 hosts
2021-04-08 15:13:23,091 -  nornir.core -     INFO -        run() - Running task 'EIGRP config' with args {'dry_run': False} on 2 hosts
2021-04-08 15:13:31,285 -  nornir.core -     INFO -        run() - Running task 'EIGRP IPV6 config' with args {'dry_run': False} on 2 hosts
2021-04-08 15:13:38,170 -  nornir.core -     INFO -        run() - Running task 'IPv4 packet filter config' with args {'dry_run': False} on 1 hosts
2021-04-08 15:13:42,567 -  nornir.core -     INFO -        run() - Running task 'IPv6 packet filter config' with args {'dry_run': False} on 1 hosts
2021-04-08 15:13:46,870 -  nornir.core -     INFO -        run() - Running task 'export_device_configuration' with args {} on 4 hosts
2021-04-08 15:13:48,007 -  nornir.core -     INFO -        run() - Running task 'export_packet_filter_info' with args {} on 4 hosts
2021-04-08 15:13:53,714 -  nornir.core -     INFO -        run() - Running task 'export_ipv4_routes' with args {} on 4 hosts
2021-04-08 15:13:54,521 -  nornir.core -     INFO -        run() - Running task 'export_ipv6_routes' with args {} on 4 hosts
2021-04-08 15:52:53,094 -  nornir.core -     INFO -        run() - Running task 'IPv4 interfaces config' with args {'dry_run': False} on 4 hosts
2021-04-08 15:53:12,322 -  nornir.core -     INFO -        run() - Running task 'IPv4 interfaces config' with args {'dry_run': False} on 4 hosts
2021-04-08 15:53:30,358 - nornir.core.task -    ERROR -      start() - Host 'R3': task 'Loading IPv4 interfaces Configuration on the device' failed with traceback:
Traceback (most recent call last):
  File "/home/macaktom/.local/share/virtualenvs/network_automation-NLxdyicX/lib/python3.8/site-packages/nornir/core/task.py", line 98, in start
    r = self.task(self, **self.params)
  File "/home/macaktom/.local/share/virtualenvs/network_automation-NLxdyicX/lib/python3.8/site-packages/nornir_napalm/plugins/tasks/napalm_configure.py", line 39, in napalm_configure
    device.commit_config()
  File "/home/macaktom/.local/share/virtualenvs/network_automation-NLxdyicX/lib/python3.8/site-packages/napalm/ios/ios.py", line 556, in commit_config
    output += self.device.save_config()
  File "/home/macaktom/.local/share/virtualenvs/network_automation-NLxdyicX/lib/python3.8/site-packages/netmiko/cisco/cisco_ios.py", line 36, in save_config
    return super().save_config(
  File "/home/macaktom/.local/share/virtualenvs/network_automation-NLxdyicX/lib/python3.8/site-packages/netmiko/cisco_base_connection.py", line 232, in save_config
    output = self.send_command(
  File "/home/macaktom/.local/share/virtualenvs/network_automation-NLxdyicX/lib/python3.8/site-packages/netmiko/utilities.py", line 429, in wrapper_decorator
    return func(self, *args, **kwargs)
  File "/home/macaktom/.local/share/virtualenvs/network_automation-NLxdyicX/lib/python3.8/site-packages/netmiko/base_connection.py", line 1523, in send_command
    raise IOError(
OSError: Search pattern never detected in send_command: R3\#

2021-04-08 15:53:30,359 - nornir.core.task -    ERROR -      start() - Host 'R3': task 'IPv4 interfaces config' failed with traceback:
Traceback (most recent call last):
  File "/home/macaktom/.local/share/virtualenvs/network_automation-NLxdyicX/lib/python3.8/site-packages/nornir/core/task.py", line 98, in start
    r = self.task(self, **self.params)
  File "/home/macaktom/PycharmProjects/network_automation/modules/tasks/interfaces_configuration.py", line 44, in configure_ipv4_interfaces
    task.run(task=napalm_configure,
  File "/home/macaktom/.local/share/virtualenvs/network_automation-NLxdyicX/lib/python3.8/site-packages/nornir/core/task.py", line 168, in run
    raise NornirSubTaskError(task=run_task, result=r)
nornir.core.exceptions.NornirSubTaskError: Subtask: Loading IPv4 interfaces Configuration on the device (failed)


2021-04-08 15:53:30,361 -  nornir.core -     INFO -        run() - Running task 'IPv6 interfaces config' with args {'dry_run': False} on 4 hosts
2021-04-08 15:53:38,659 -  nornir.core -     INFO -        run() - Running task 'Switching interfaces config' with args {'dry_run': False} on 1 hosts
2021-04-08 15:53:46,133 -  nornir.core -     INFO -        run() - Running task 'OSPFv2 config' with args {'dry_run': False} on 3 hosts
2021-04-08 15:53:52,723 -  nornir.core -     INFO -        run() - Running task 'OSPFv3 config' with args {'dry_run': False} on 3 hosts
2021-04-08 15:53:57,565 -  nornir.core -     INFO -        run() - Running task 'EIGRP config' with args {'dry_run': False} on 2 hosts
2021-04-08 15:54:05,007 -  nornir.core -     INFO -        run() - Running task 'EIGRP IPV6 config' with args {'dry_run': False} on 2 hosts
2021-04-08 15:54:10,680 -  nornir.core -     INFO -        run() - Running task 'IPv4 packet filter config' with args {'dry_run': False} on 1 hosts
2021-04-08 15:54:14,995 -  nornir.core -     INFO -        run() - Running task 'IPv6 packet filter config' with args {'dry_run': False} on 1 hosts
2021-04-08 15:54:19,604 -  nornir.core -     INFO -        run() - Running task 'export_device_configuration' with args {} on 4 hosts
2021-04-08 15:54:20,683 -  nornir.core -     INFO -        run() - Running task 'export_packet_filter_info' with args {} on 4 hosts
2021-04-08 15:54:26,333 -  nornir.core -     INFO -        run() - Running task 'export_ipv4_routes' with args {} on 4 hosts
2021-04-08 15:54:27,144 -  nornir.core -     INFO -        run() - Running task 'export_ipv6_routes' with args {} on 4 hosts
2021-04-08 15:55:13,252 -  nornir.core -     INFO -        run() - Running task 'IPv4 interfaces config' with args {'dry_run': False} on 4 hosts
2021-04-08 15:55:22,034 -  nornir.core -     INFO -        run() - Running task 'IPv6 interfaces config' with args {'dry_run': False} on 4 hosts
2021-04-08 15:55:30,422 -  nornir.core -     INFO -        run() - Running task 'Switching interfaces config' with args {'dry_run': False} on 1 hosts
2021-04-08 15:55:37,880 -  nornir.core -     INFO -        run() - Running task 'OSPFv2 config' with args {'dry_run': False} on 3 hosts
2021-04-08 15:55:44,398 -  nornir.core -     INFO -        run() - Running task 'OSPFv3 config' with args {'dry_run': False} on 3 hosts
2021-04-08 15:55:49,308 -  nornir.core -     INFO -        run() - Running task 'EIGRP config' with args {'dry_run': False} on 2 hosts
2021-04-08 15:55:56,806 -  nornir.core -     INFO -        run() - Running task 'EIGRP IPV6 config' with args {'dry_run': False} on 2 hosts
2021-04-08 15:56:03,481 -  nornir.core -     INFO -        run() - Running task 'IPv4 packet filter config' with args {'dry_run': False} on 1 hosts
2021-04-08 15:56:07,892 -  nornir.core -     INFO -        run() - Running task 'IPv6 packet filter config' with args {'dry_run': False} on 1 hosts
2021-04-08 15:56:12,175 -  nornir.core -     INFO -        run() - Running task 'export_device_configuration' with args {} on 4 hosts
2021-04-08 15:56:13,208 -  nornir.core -     INFO -        run() - Running task 'export_packet_filter_info' with args {} on 4 hosts
2021-04-08 15:56:18,904 -  nornir.core -     INFO -        run() - Running task 'export_ipv4_routes' with args {} on 4 hosts
2021-04-08 15:56:19,712 -  nornir.core -     INFO -        run() - Running task 'export_ipv6_routes' with args {} on 4 hosts
2021-04-08 16:00:02,804 -  nornir.core -     INFO -        run() - Running task 'IPv4 interfaces config' with args {'dry_run': False} on 4 hosts
2021-04-08 16:00:22,662 - nornir.core.task -    ERROR -      start() - Host 'R3': task 'Loading IPv4 interfaces Configuration on the device' failed with traceback:
Traceback (most recent call last):
  File "/home/macaktom/.local/share/virtualenvs/network_automation-NLxdyicX/lib/python3.8/site-packages/nornir/core/task.py", line 98, in start
    r = self.task(self, **self.params)
  File "/home/macaktom/.local/share/virtualenvs/network_automation-NLxdyicX/lib/python3.8/site-packages/nornir_napalm/plugins/tasks/napalm_configure.py", line 39, in napalm_configure
    device.commit_config()
  File "/home/macaktom/.local/share/virtualenvs/network_automation-NLxdyicX/lib/python3.8/site-packages/napalm/ios/ios.py", line 556, in commit_config
    output += self.device.save_config()
  File "/home/macaktom/.local/share/virtualenvs/network_automation-NLxdyicX/lib/python3.8/site-packages/netmiko/cisco/cisco_ios.py", line 36, in save_config
    return super().save_config(
  File "/home/macaktom/.local/share/virtualenvs/network_automation-NLxdyicX/lib/python3.8/site-packages/netmiko/cisco_base_connection.py", line 232, in save_config
    output = self.send_command(
  File "/home/macaktom/.local/share/virtualenvs/network_automation-NLxdyicX/lib/python3.8/site-packages/netmiko/utilities.py", line 429, in wrapper_decorator
    return func(self, *args, **kwargs)
  File "/home/macaktom/.local/share/virtualenvs/network_automation-NLxdyicX/lib/python3.8/site-packages/netmiko/base_connection.py", line 1523, in send_command
    raise IOError(
OSError: Search pattern never detected in send_command: R3\#

2021-04-08 16:00:22,662 - nornir.core.task -    ERROR -      start() - Host 'R3': task 'IPv4 interfaces config' failed with traceback:
Traceback (most recent call last):
  File "/home/macaktom/.local/share/virtualenvs/network_automation-NLxdyicX/lib/python3.8/site-packages/nornir/core/task.py", line 98, in start
    r = self.task(self, **self.params)
  File "/home/macaktom/PycharmProjects/network_automation/modules/tasks/interfaces_configuration.py", line 44, in configure_ipv4_interfaces
    task.run(task=napalm_configure,
  File "/home/macaktom/.local/share/virtualenvs/network_automation-NLxdyicX/lib/python3.8/site-packages/nornir/core/task.py", line 168, in run
    raise NornirSubTaskError(task=run_task, result=r)
nornir.core.exceptions.NornirSubTaskError: Subtask: Loading IPv4 interfaces Configuration on the device (failed)


2021-04-08 16:00:22,665 -  nornir.core -     INFO -        run() - Running task 'IPv6 interfaces config' with args {'dry_run': False} on 4 hosts
2021-04-08 16:00:31,223 -  nornir.core -     INFO -        run() - Running task 'Switching interfaces config' with args {'dry_run': False} on 1 hosts
2021-04-08 16:00:39,070 -  nornir.core -     INFO -        run() - Running task 'OSPFv2 config' with args {'dry_run': False} on 3 hosts
2021-04-08 16:00:45,589 -  nornir.core -     INFO -        run() - Running task 'OSPFv3 config' with args {'dry_run': False} on 3 hosts
2021-04-08 16:00:50,534 -  nornir.core -     INFO -        run() - Running task 'EIGRP config' with args {'dry_run': False} on 2 hosts
2021-04-08 16:00:58,011 -  nornir.core -     INFO -        run() - Running task 'EIGRP IPV6 config' with args {'dry_run': False} on 2 hosts
2021-04-08 16:01:04,074 -  nornir.core -     INFO -        run() - Running task 'IPv4 packet filter config' with args {'dry_run': False} on 1 hosts
2021-04-08 16:01:08,905 -  nornir.core -     INFO -        run() - Running task 'IPv6 packet filter config' with args {'dry_run': False} on 1 hosts
2021-04-08 16:01:13,826 -  nornir.core -     INFO -        run() - Running task 'export_device_configuration' with args {} on 4 hosts
2021-04-08 16:01:15,202 -  nornir.core -     INFO -        run() - Running task 'export_packet_filter_info' with args {} on 4 hosts
2021-04-08 16:01:20,997 -  nornir.core -     INFO -        run() - Running task 'export_ipv4_routes' with args {} on 4 hosts
2021-04-08 16:01:21,804 -  nornir.core -     INFO -        run() - Running task 'export_ipv6_routes' with args {} on 4 hosts
2021-04-08 16:04:15,426 -  nornir.core -     INFO -        run() - Running task 'IPv4 interfaces config' with args {'dry_run': False} on 4 hosts
2021-04-08 16:04:35,494 - nornir.core.task -    ERROR -      start() - Host 'R3': task 'Loading IPv4 interfaces Configuration on the device' failed with traceback:
Traceback (most recent call last):
  File "/home/macaktom/.local/share/virtualenvs/network_automation-NLxdyicX/lib/python3.8/site-packages/nornir/core/task.py", line 98, in start
    r = self.task(self, **self.params)
  File "/home/macaktom/.local/share/virtualenvs/network_automation-NLxdyicX/lib/python3.8/site-packages/nornir_napalm/plugins/tasks/napalm_configure.py", line 39, in napalm_configure
    device.commit_config()
  File "/home/macaktom/.local/share/virtualenvs/network_automation-NLxdyicX/lib/python3.8/site-packages/napalm/ios/ios.py", line 556, in commit_config
    output += self.device.save_config()
  File "/home/macaktom/.local/share/virtualenvs/network_automation-NLxdyicX/lib/python3.8/site-packages/netmiko/cisco/cisco_ios.py", line 36, in save_config
    return super().save_config(
  File "/home/macaktom/.local/share/virtualenvs/network_automation-NLxdyicX/lib/python3.8/site-packages/netmiko/cisco_base_connection.py", line 232, in save_config
    output = self.send_command(
  File "/home/macaktom/.local/share/virtualenvs/network_automation-NLxdyicX/lib/python3.8/site-packages/netmiko/utilities.py", line 429, in wrapper_decorator
    return func(self, *args, **kwargs)
  File "/home/macaktom/.local/share/virtualenvs/network_automation-NLxdyicX/lib/python3.8/site-packages/netmiko/base_connection.py", line 1523, in send_command
    raise IOError(
OSError: Search pattern never detected in send_command: R3\#

2021-04-08 16:04:35,495 - nornir.core.task -    ERROR -      start() - Host 'R3': task 'IPv4 interfaces config' failed with traceback:
Traceback (most recent call last):
  File "/home/macaktom/.local/share/virtualenvs/network_automation-NLxdyicX/lib/python3.8/site-packages/nornir/core/task.py", line 98, in start
    r = self.task(self, **self.params)
  File "/home/macaktom/PycharmProjects/network_automation/modules/tasks/interfaces_configuration.py", line 44, in configure_ipv4_interfaces
    task.run(task=napalm_configure,
  File "/home/macaktom/.local/share/virtualenvs/network_automation-NLxdyicX/lib/python3.8/site-packages/nornir/core/task.py", line 168, in run
    raise NornirSubTaskError(task=run_task, result=r)
nornir.core.exceptions.NornirSubTaskError: Subtask: Loading IPv4 interfaces Configuration on the device (failed)


2021-04-08 16:04:35,497 -  nornir.core -     INFO -        run() - Running task 'IPv6 interfaces config' with args {'dry_run': False} on 4 hosts
2021-04-08 16:04:43,964 -  nornir.core -     INFO -        run() - Running task 'Switching interfaces config' with args {'dry_run': False} on 1 hosts
2021-04-08 16:04:51,697 -  nornir.core -     INFO -        run() - Running task 'OSPFv2 config' with args {'dry_run': False} on 3 hosts
2021-04-08 16:04:58,400 -  nornir.core -     INFO -        run() - Running task 'OSPFv3 config' with args {'dry_run': False} on 3 hosts
2021-04-08 16:05:03,450 -  nornir.core -     INFO -        run() - Running task 'EIGRP config' with args {'dry_run': False} on 2 hosts
2021-04-08 16:05:10,900 -  nornir.core -     INFO -        run() - Running task 'EIGRP IPV6 config' with args {'dry_run': False} on 2 hosts
2021-04-08 16:05:16,707 -  nornir.core -     INFO -        run() - Running task 'IPv4 packet filter config' with args {'dry_run': False} on 1 hosts
2021-04-08 16:05:21,226 -  nornir.core -     INFO -        run() - Running task 'IPv6 packet filter config' with args {'dry_run': False} on 1 hosts
2021-04-08 16:05:25,807 -  nornir.core -     INFO -        run() - Running task 'export_device_configuration' with args {} on 4 hosts
2021-04-08 16:05:26,911 -  nornir.core -     INFO -        run() - Running task 'export_packet_filter_info' with args {} on 4 hosts
2021-04-08 16:05:32,607 -  nornir.core -     INFO -        run() - Running task 'export_ipv4_routes' with args {} on 4 hosts
2021-04-08 16:05:33,417 -  nornir.core -     INFO -        run() - Running task 'export_ipv6_routes' with args {} on 4 hosts
2021-04-08 16:06:19,945 -  nornir.core -     INFO -        run() - Running task 'IPv4 interfaces config' with args {'dry_run': False} on 4 hosts
2021-04-08 16:06:29,274 -  nornir.core -     INFO -        run() - Running task 'IPv6 interfaces config' with args {'dry_run': False} on 4 hosts
2021-04-08 16:06:37,883 -  nornir.core -     INFO -        run() - Running task 'Switching interfaces config' with args {'dry_run': False} on 1 hosts
2021-04-08 16:06:45,569 -  nornir.core -     INFO -        run() - Running task 'OSPFv2 config' with args {'dry_run': False} on 3 hosts
2021-04-08 16:06:53,794 -  nornir.core -     INFO -        run() - Running task 'OSPFv3 config' with args {'dry_run': False} on 3 hosts
2021-04-08 16:07:02,034 -  nornir.core -     INFO -        run() - Running task 'EIGRP config' with args {'dry_run': False} on 2 hosts
2021-04-08 16:07:10,407 -  nornir.core -     INFO -        run() - Running task 'EIGRP IPV6 config' with args {'dry_run': False} on 2 hosts
2021-04-08 16:07:18,893 -  nornir.core -     INFO -        run() - Running task 'IPv4 packet filter config' with args {'dry_run': False} on 1 hosts
2021-04-08 16:07:23,399 -  nornir.core -     INFO -        run() - Running task 'IPv6 packet filter config' with args {'dry_run': False} on 1 hosts
2021-04-08 16:07:27,918 -  nornir.core -     INFO -        run() - Running task 'export_device_configuration' with args {} on 4 hosts
2021-04-08 16:07:29,219 -  nornir.core -     INFO -        run() - Running task 'export_packet_filter_info' with args {} on 4 hosts
2021-04-08 16:07:34,927 -  nornir.core -     INFO -        run() - Running task 'export_ipv4_routes' with args {} on 4 hosts
2021-04-08 16:07:35,734 -  nornir.core -     INFO -        run() - Running task 'export_ipv6_routes' with args {} on 4 hosts
2021-04-08 16:22:54,560 -  nornir.core -     INFO -        run() - Running task 'Backup running configuration' with args {} on 4 hosts
2021-04-08 16:25:39,111 -  nornir.core -     INFO -        run() - Running task 'show_ospf_neighbors' with args {'ipv6': True} on 4 hosts
2021-04-08 16:25:39,115 - nornir.core.task -    ERROR -      start() - Host 'MLS1': task 'show_ospf_neighbors' failed with traceback:
Traceback (most recent call last):
  File "/home/macaktom/.local/share/virtualenvs/network_automation-NLxdyicX/lib/python3.8/site-packages/nornir/core/task.py", line 98, in start
    r = self.task(self, **self.params)
  File "/home/macaktom/PycharmProjects/network_automation/modules/utility/network_info_viewer.py", line 321, in show_ospf_neighbors
    raise NornirSubTaskError("Function was not implemented for particular device.", task)
nornir.core.exceptions.NornirSubTaskError: Subtask: Function was not implemented for particular device. (failed)


2021-04-08 16:26:50,432 -  nornir.core -     INFO -        run() - Running task 'show_vlans' with args {'json_out': False} on 1 hosts
2021-04-08 16:27:49,802 -  nornir.core -     INFO -        run() - Running task 'show_vlans' with args {'json_out': True} on 1 hosts
2021-04-08 16:30:09,777 -  nornir.core -     INFO -        run() - Running task 'IPv4 interfaces config' with args {'dry_run': False} on 4 hosts
2021-04-08 16:30:19,322 -  nornir.core -     INFO -        run() - Running task 'IPv6 interfaces config' with args {'dry_run': False} on 4 hosts
2021-04-08 16:30:28,120 -  nornir.core -     INFO -        run() - Running task 'Switching interfaces config' with args {'dry_run': False} on 1 hosts
2021-04-08 16:32:56,378 -  nornir.core -     INFO -        run() - Running task 'show_vlans' with args {'json_out': False} on 1 hosts
2021-04-08 16:33:50,060 -  nornir.core -     INFO -        run() - Running task 'show_vlans' with args {'json_out': True} on 1 hosts
2021-04-17 21:20:04,545 -  nornir.core -     INFO -        run() - Running task 'send_commands' with args {'enable': True} on 1 hosts
2021-04-17 21:22:04,593 -  nornir.core -     INFO -        run() - Running task 'send_commands' with args {'enable': True} on 1 hosts
2021-04-17 21:23:26,445 -  nornir.core -     INFO -        run() - Running task 'send_commands' with args {'enable': True} on 1 hosts
2021-04-17 21:24:15,679 -  nornir.core -     INFO -        run() - Running task 'send_commands' with args {'enable': True} on 1 hosts
2021-04-17 21:24:53,077 -  nornir.core -     INFO -        run() - Running task 'send_commands' with args {'enable': True} on 1 hosts
2021-04-17 21:26:55,190 -  nornir.core -     INFO -        run() - Running task 'send_commands' with args {'enable': True} on 1 hosts
2021-04-18 08:04:36,694 -  nornir.core -     INFO -        run() - Running task 'send_commands' with args {'enable': True} on 1 hosts
2021-04-18 08:07:17,715 -  nornir.core -     INFO -        run() - Running task 'Send commands' with args {'enable': True} on 1 hosts
2021-04-18 08:08:09,175 -  nornir.core -     INFO -        run() - Running task 'send_commands' with args {'enable': True} on 1 hosts
