2020-09-28 16:33:38,090 -  nornir.core -     INFO -        run() - Running task 'napalm_get' with args {'getters': ['facts']} on 6 hosts
2020-09-28 16:33:41,178 - nornir.core.task -    ERROR -      start() - Host 'SW1': task 'napalm_get' failed with traceback:
Traceback (most recent call last):
  File "/home/macaktom/.local/share/virtualenvs/network_automation-NLxdyicX/lib/python3.8/site-packages/netmiko/base_connection.py", line 918, in establish_connection
    self.remote_conn_pre.connect(**ssh_connect_params)
  File "/home/macaktom/.local/share/virtualenvs/network_automation-NLxdyicX/lib/python3.8/site-packages/paramiko/client.py", line 368, in connect
    raise NoValidConnectionsError(errors)
paramiko.ssh_exception.NoValidConnectionsError: [Errno None] Unable to connect to port 22 on 10.10.10.5

During handling of the above exception, another exception occurred:

Traceback (most recent call last):
  File "/home/macaktom/.local/share/virtualenvs/network_automation-NLxdyicX/lib/python3.8/site-packages/napalm/base/base.py", line 86, in _netmiko_open
    self._netmiko_device = ConnectHandler(
  File "/home/macaktom/.local/share/virtualenvs/network_automation-NLxdyicX/lib/python3.8/site-packages/netmiko/ssh_dispatcher.py", line 302, in ConnectHandler
    return ConnectionClass(*args, **kwargs)
  File "/home/macaktom/.local/share/virtualenvs/network_automation-NLxdyicX/lib/python3.8/site-packages/netmiko/cisco/cisco_ios.py", line 17, in __init__
    return super().__init__(*args, **kwargs)
  File "/home/macaktom/.local/share/virtualenvs/network_automation-NLxdyicX/lib/python3.8/site-packages/netmiko/base_connection.py", line 344, in __init__
    self._open()
  File "/home/macaktom/.local/share/virtualenvs/network_automation-NLxdyicX/lib/python3.8/site-packages/netmiko/base_connection.py", line 349, in _open
    self.establish_connection()
  File "/home/macaktom/.local/share/virtualenvs/network_automation-NLxdyicX/lib/python3.8/site-packages/netmiko/base_connection.py", line 940, in establish_connection
    raise NetmikoTimeoutException(msg)
netmiko.ssh_exception.NetmikoTimeoutException: TCP connection to device failed.

Common causes of this problem are:
1. Incorrect hostname or IP address.
2. Wrong TCP port.
3. Intermediate firewall blocking access.

Device settings: cisco_ios 10.10.10.5:22



During handling of the above exception, another exception occurred:

Traceback (most recent call last):
  File "/home/macaktom/.local/share/virtualenvs/network_automation-NLxdyicX/lib/python3.8/site-packages/nornir/core/task.py", line 98, in start
    r = self.task(self, **self.params)
  File "/home/macaktom/.local/share/virtualenvs/network_automation-NLxdyicX/lib/python3.8/site-packages/nornir_napalm/plugins/tasks/napalm_get.py", line 32, in napalm_get
    device = task.host.get_connection(CONNECTION_NAME, task.nornir.config)
  File "/home/macaktom/.local/share/virtualenvs/network_automation-NLxdyicX/lib/python3.8/site-packages/nornir/core/inventory.py", line 440, in get_connection
    self.open_connection(
  File "/home/macaktom/.local/share/virtualenvs/network_automation-NLxdyicX/lib/python3.8/site-packages/nornir/core/inventory.py", line 492, in open_connection
    conn_obj.open(
  File "/home/macaktom/.local/share/virtualenvs/network_automation-NLxdyicX/lib/python3.8/site-packages/nornir_napalm/plugins/connections/__init__.py", line 57, in open
    connection.open()
  File "/home/macaktom/.local/share/virtualenvs/network_automation-NLxdyicX/lib/python3.8/site-packages/napalm/ios/ios.py", line 169, in open
    self.device = self._netmiko_open(
  File "/home/macaktom/.local/share/virtualenvs/network_automation-NLxdyicX/lib/python3.8/site-packages/napalm/base/base.py", line 95, in _netmiko_open
    raise ConnectionException("Cannot connect to {}".format(self.hostname))
napalm.base.exceptions.ConnectionException: Cannot connect to 10.10.10.5

2020-09-28 16:33:41,178 - nornir.core.task -    ERROR -      start() - Host 'SW2': task 'napalm_get' failed with traceback:
Traceback (most recent call last):
  File "/home/macaktom/.local/share/virtualenvs/network_automation-NLxdyicX/lib/python3.8/site-packages/netmiko/base_connection.py", line 918, in establish_connection
    self.remote_conn_pre.connect(**ssh_connect_params)
  File "/home/macaktom/.local/share/virtualenvs/network_automation-NLxdyicX/lib/python3.8/site-packages/paramiko/client.py", line 368, in connect
    raise NoValidConnectionsError(errors)
paramiko.ssh_exception.NoValidConnectionsError: [Errno None] Unable to connect to port 22 on 10.10.10.6

During handling of the above exception, another exception occurred:

Traceback (most recent call last):
  File "/home/macaktom/.local/share/virtualenvs/network_automation-NLxdyicX/lib/python3.8/site-packages/napalm/base/base.py", line 86, in _netmiko_open
    self._netmiko_device = ConnectHandler(
  File "/home/macaktom/.local/share/virtualenvs/network_automation-NLxdyicX/lib/python3.8/site-packages/netmiko/ssh_dispatcher.py", line 302, in ConnectHandler
    return ConnectionClass(*args, **kwargs)
  File "/home/macaktom/.local/share/virtualenvs/network_automation-NLxdyicX/lib/python3.8/site-packages/netmiko/cisco/cisco_ios.py", line 17, in __init__
    return super().__init__(*args, **kwargs)
  File "/home/macaktom/.local/share/virtualenvs/network_automation-NLxdyicX/lib/python3.8/site-packages/netmiko/base_connection.py", line 344, in __init__
    self._open()
  File "/home/macaktom/.local/share/virtualenvs/network_automation-NLxdyicX/lib/python3.8/site-packages/netmiko/base_connection.py", line 349, in _open
    self.establish_connection()
  File "/home/macaktom/.local/share/virtualenvs/network_automation-NLxdyicX/lib/python3.8/site-packages/netmiko/base_connection.py", line 940, in establish_connection
    raise NetmikoTimeoutException(msg)
netmiko.ssh_exception.NetmikoTimeoutException: TCP connection to device failed.

Common causes of this problem are:
1. Incorrect hostname or IP address.
2. Wrong TCP port.
3. Intermediate firewall blocking access.

Device settings: cisco_ios 10.10.10.6:22



During handling of the above exception, another exception occurred:

Traceback (most recent call last):
  File "/home/macaktom/.local/share/virtualenvs/network_automation-NLxdyicX/lib/python3.8/site-packages/nornir/core/task.py", line 98, in start
    r = self.task(self, **self.params)
  File "/home/macaktom/.local/share/virtualenvs/network_automation-NLxdyicX/lib/python3.8/site-packages/nornir_napalm/plugins/tasks/napalm_get.py", line 32, in napalm_get
    device = task.host.get_connection(CONNECTION_NAME, task.nornir.config)
  File "/home/macaktom/.local/share/virtualenvs/network_automation-NLxdyicX/lib/python3.8/site-packages/nornir/core/inventory.py", line 440, in get_connection
    self.open_connection(
  File "/home/macaktom/.local/share/virtualenvs/network_automation-NLxdyicX/lib/python3.8/site-packages/nornir/core/inventory.py", line 492, in open_connection
    conn_obj.open(
  File "/home/macaktom/.local/share/virtualenvs/network_automation-NLxdyicX/lib/python3.8/site-packages/nornir_napalm/plugins/connections/__init__.py", line 57, in open
    connection.open()
  File "/home/macaktom/.local/share/virtualenvs/network_automation-NLxdyicX/lib/python3.8/site-packages/napalm/ios/ios.py", line 169, in open
    self.device = self._netmiko_open(
  File "/home/macaktom/.local/share/virtualenvs/network_automation-NLxdyicX/lib/python3.8/site-packages/napalm/base/base.py", line 95, in _netmiko_open
    raise ConnectionException("Cannot connect to {}".format(self.hostname))
napalm.base.exceptions.ConnectionException: Cannot connect to 10.10.10.6

2020-09-28 16:33:41,179 - nornir.core.task -    ERROR -      start() - Host 'SW4': task 'napalm_get' failed with traceback:
Traceback (most recent call last):
  File "/home/macaktom/.local/share/virtualenvs/network_automation-NLxdyicX/lib/python3.8/site-packages/netmiko/base_connection.py", line 918, in establish_connection
    self.remote_conn_pre.connect(**ssh_connect_params)
  File "/home/macaktom/.local/share/virtualenvs/network_automation-NLxdyicX/lib/python3.8/site-packages/paramiko/client.py", line 368, in connect
    raise NoValidConnectionsError(errors)
paramiko.ssh_exception.NoValidConnectionsError: [Errno None] Unable to connect to port 22 on 10.10.10.8

During handling of the above exception, another exception occurred:

Traceback (most recent call last):
  File "/home/macaktom/.local/share/virtualenvs/network_automation-NLxdyicX/lib/python3.8/site-packages/napalm/base/base.py", line 86, in _netmiko_open
    self._netmiko_device = ConnectHandler(
  File "/home/macaktom/.local/share/virtualenvs/network_automation-NLxdyicX/lib/python3.8/site-packages/netmiko/ssh_dispatcher.py", line 302, in ConnectHandler
    return ConnectionClass(*args, **kwargs)
  File "/home/macaktom/.local/share/virtualenvs/network_automation-NLxdyicX/lib/python3.8/site-packages/netmiko/cisco/cisco_ios.py", line 17, in __init__
    return super().__init__(*args, **kwargs)
  File "/home/macaktom/.local/share/virtualenvs/network_automation-NLxdyicX/lib/python3.8/site-packages/netmiko/base_connection.py", line 344, in __init__
    self._open()
  File "/home/macaktom/.local/share/virtualenvs/network_automation-NLxdyicX/lib/python3.8/site-packages/netmiko/base_connection.py", line 349, in _open
    self.establish_connection()
  File "/home/macaktom/.local/share/virtualenvs/network_automation-NLxdyicX/lib/python3.8/site-packages/netmiko/base_connection.py", line 940, in establish_connection
    raise NetmikoTimeoutException(msg)
netmiko.ssh_exception.NetmikoTimeoutException: TCP connection to device failed.

Common causes of this problem are:
1. Incorrect hostname or IP address.
2. Wrong TCP port.
3. Intermediate firewall blocking access.

Device settings: cisco_ios 10.10.10.8:22



During handling of the above exception, another exception occurred:

Traceback (most recent call last):
  File "/home/macaktom/.local/share/virtualenvs/network_automation-NLxdyicX/lib/python3.8/site-packages/nornir/core/task.py", line 98, in start
    r = self.task(self, **self.params)
  File "/home/macaktom/.local/share/virtualenvs/network_automation-NLxdyicX/lib/python3.8/site-packages/nornir_napalm/plugins/tasks/napalm_get.py", line 32, in napalm_get
    device = task.host.get_connection(CONNECTION_NAME, task.nornir.config)
  File "/home/macaktom/.local/share/virtualenvs/network_automation-NLxdyicX/lib/python3.8/site-packages/nornir/core/inventory.py", line 440, in get_connection
    self.open_connection(
  File "/home/macaktom/.local/share/virtualenvs/network_automation-NLxdyicX/lib/python3.8/site-packages/nornir/core/inventory.py", line 492, in open_connection
    conn_obj.open(
  File "/home/macaktom/.local/share/virtualenvs/network_automation-NLxdyicX/lib/python3.8/site-packages/nornir_napalm/plugins/connections/__init__.py", line 57, in open
    connection.open()
  File "/home/macaktom/.local/share/virtualenvs/network_automation-NLxdyicX/lib/python3.8/site-packages/napalm/ios/ios.py", line 169, in open
    self.device = self._netmiko_open(
  File "/home/macaktom/.local/share/virtualenvs/network_automation-NLxdyicX/lib/python3.8/site-packages/napalm/base/base.py", line 95, in _netmiko_open
    raise ConnectionException("Cannot connect to {}".format(self.hostname))
napalm.base.exceptions.ConnectionException: Cannot connect to 10.10.10.8

2020-09-28 16:33:41,179 - nornir.core.task -    ERROR -      start() - Host 'SW3': task 'napalm_get' failed with traceback:
Traceback (most recent call last):
  File "/home/macaktom/.local/share/virtualenvs/network_automation-NLxdyicX/lib/python3.8/site-packages/netmiko/base_connection.py", line 918, in establish_connection
    self.remote_conn_pre.connect(**ssh_connect_params)
  File "/home/macaktom/.local/share/virtualenvs/network_automation-NLxdyicX/lib/python3.8/site-packages/paramiko/client.py", line 368, in connect
    raise NoValidConnectionsError(errors)
paramiko.ssh_exception.NoValidConnectionsError: [Errno None] Unable to connect to port 22 on 10.10.10.7

During handling of the above exception, another exception occurred:

Traceback (most recent call last):
  File "/home/macaktom/.local/share/virtualenvs/network_automation-NLxdyicX/lib/python3.8/site-packages/napalm/base/base.py", line 86, in _netmiko_open
    self._netmiko_device = ConnectHandler(
  File "/home/macaktom/.local/share/virtualenvs/network_automation-NLxdyicX/lib/python3.8/site-packages/netmiko/ssh_dispatcher.py", line 302, in ConnectHandler
    return ConnectionClass(*args, **kwargs)
  File "/home/macaktom/.local/share/virtualenvs/network_automation-NLxdyicX/lib/python3.8/site-packages/netmiko/cisco/cisco_ios.py", line 17, in __init__
    return super().__init__(*args, **kwargs)
  File "/home/macaktom/.local/share/virtualenvs/network_automation-NLxdyicX/lib/python3.8/site-packages/netmiko/base_connection.py", line 344, in __init__
    self._open()
  File "/home/macaktom/.local/share/virtualenvs/network_automation-NLxdyicX/lib/python3.8/site-packages/netmiko/base_connection.py", line 349, in _open
    self.establish_connection()
  File "/home/macaktom/.local/share/virtualenvs/network_automation-NLxdyicX/lib/python3.8/site-packages/netmiko/base_connection.py", line 940, in establish_connection
    raise NetmikoTimeoutException(msg)
netmiko.ssh_exception.NetmikoTimeoutException: TCP connection to device failed.

Common causes of this problem are:
1. Incorrect hostname or IP address.
2. Wrong TCP port.
3. Intermediate firewall blocking access.

Device settings: cisco_ios 10.10.10.7:22



During handling of the above exception, another exception occurred:

Traceback (most recent call last):
  File "/home/macaktom/.local/share/virtualenvs/network_automation-NLxdyicX/lib/python3.8/site-packages/nornir/core/task.py", line 98, in start
    r = self.task(self, **self.params)
  File "/home/macaktom/.local/share/virtualenvs/network_automation-NLxdyicX/lib/python3.8/site-packages/nornir_napalm/plugins/tasks/napalm_get.py", line 32, in napalm_get
    device = task.host.get_connection(CONNECTION_NAME, task.nornir.config)
  File "/home/macaktom/.local/share/virtualenvs/network_automation-NLxdyicX/lib/python3.8/site-packages/nornir/core/inventory.py", line 440, in get_connection
    self.open_connection(
  File "/home/macaktom/.local/share/virtualenvs/network_automation-NLxdyicX/lib/python3.8/site-packages/nornir/core/inventory.py", line 492, in open_connection
    conn_obj.open(
  File "/home/macaktom/.local/share/virtualenvs/network_automation-NLxdyicX/lib/python3.8/site-packages/nornir_napalm/plugins/connections/__init__.py", line 57, in open
    connection.open()
  File "/home/macaktom/.local/share/virtualenvs/network_automation-NLxdyicX/lib/python3.8/site-packages/napalm/ios/ios.py", line 169, in open
    self.device = self._netmiko_open(
  File "/home/macaktom/.local/share/virtualenvs/network_automation-NLxdyicX/lib/python3.8/site-packages/napalm/base/base.py", line 95, in _netmiko_open
    raise ConnectionException("Cannot connect to {}".format(self.hostname))
napalm.base.exceptions.ConnectionException: Cannot connect to 10.10.10.7

2020-09-28 16:37:38,546 -  nornir.core -     INFO -        run() - Running task 'napalm_get' with args {'getters': ['facts']} on 6 hosts
2020-09-28 16:45:11,770 -  nornir.core -     INFO -        run() - Running task 'napalm_get' with args {'getters': ['facts']} on 1 hosts
2020-09-28 16:45:28,962 -  nornir.core -     INFO -        run() - Running task 'napalm_get' with args {'getters': ['facts']} on 6 hosts
2020-09-28 18:17:36,783 -  nornir.core -     INFO -        run() - Running task 'napalm_get' with args {'getters': ['facts']} on 6 hosts
2020-09-29 16:01:18,723 -  nornir.core -     INFO -        run() - Running task 'napalm_get' with args {'getters': ['facts']} on 6 hosts
2020-09-29 16:01:21,794 - nornir.core.task -    ERROR -      start() - Host 'SW3': task 'napalm_get' failed with traceback:
Traceback (most recent call last):
  File "/home/macaktom/.local/share/virtualenvs/network_automation-NLxdyicX/lib/python3.8/site-packages/netmiko/base_connection.py", line 918, in establish_connection
    self.remote_conn_pre.connect(**ssh_connect_params)
  File "/home/macaktom/.local/share/virtualenvs/network_automation-NLxdyicX/lib/python3.8/site-packages/paramiko/client.py", line 368, in connect
    raise NoValidConnectionsError(errors)
paramiko.ssh_exception.NoValidConnectionsError: [Errno None] Unable to connect to port 22 on 10.10.10.7

During handling of the above exception, another exception occurred:

Traceback (most recent call last):
  File "/home/macaktom/.local/share/virtualenvs/network_automation-NLxdyicX/lib/python3.8/site-packages/napalm/base/base.py", line 86, in _netmiko_open
    self._netmiko_device = ConnectHandler(
  File "/home/macaktom/.local/share/virtualenvs/network_automation-NLxdyicX/lib/python3.8/site-packages/netmiko/ssh_dispatcher.py", line 302, in ConnectHandler
    return ConnectionClass(*args, **kwargs)
  File "/home/macaktom/.local/share/virtualenvs/network_automation-NLxdyicX/lib/python3.8/site-packages/netmiko/cisco/cisco_ios.py", line 17, in __init__
    return super().__init__(*args, **kwargs)
  File "/home/macaktom/.local/share/virtualenvs/network_automation-NLxdyicX/lib/python3.8/site-packages/netmiko/base_connection.py", line 344, in __init__
    self._open()
  File "/home/macaktom/.local/share/virtualenvs/network_automation-NLxdyicX/lib/python3.8/site-packages/netmiko/base_connection.py", line 349, in _open
    self.establish_connection()
  File "/home/macaktom/.local/share/virtualenvs/network_automation-NLxdyicX/lib/python3.8/site-packages/netmiko/base_connection.py", line 940, in establish_connection
    raise NetmikoTimeoutException(msg)
netmiko.ssh_exception.NetmikoTimeoutException: TCP connection to device failed.

Common causes of this problem are:
1. Incorrect hostname or IP address.
2. Wrong TCP port.
3. Intermediate firewall blocking access.

Device settings: cisco_ios 10.10.10.7:22



During handling of the above exception, another exception occurred:

Traceback (most recent call last):
  File "/home/macaktom/.local/share/virtualenvs/network_automation-NLxdyicX/lib/python3.8/site-packages/nornir/core/task.py", line 98, in start
    r = self.task(self, **self.params)
  File "/home/macaktom/.local/share/virtualenvs/network_automation-NLxdyicX/lib/python3.8/site-packages/nornir_napalm/plugins/tasks/napalm_get.py", line 32, in napalm_get
    device = task.host.get_connection(CONNECTION_NAME, task.nornir.config)
  File "/home/macaktom/.local/share/virtualenvs/network_automation-NLxdyicX/lib/python3.8/site-packages/nornir/core/inventory.py", line 440, in get_connection
    self.open_connection(
  File "/home/macaktom/.local/share/virtualenvs/network_automation-NLxdyicX/lib/python3.8/site-packages/nornir/core/inventory.py", line 492, in open_connection
    conn_obj.open(
  File "/home/macaktom/.local/share/virtualenvs/network_automation-NLxdyicX/lib/python3.8/site-packages/nornir_napalm/plugins/connections/__init__.py", line 57, in open
    connection.open()
  File "/home/macaktom/.local/share/virtualenvs/network_automation-NLxdyicX/lib/python3.8/site-packages/napalm/ios/ios.py", line 169, in open
    self.device = self._netmiko_open(
  File "/home/macaktom/.local/share/virtualenvs/network_automation-NLxdyicX/lib/python3.8/site-packages/napalm/base/base.py", line 95, in _netmiko_open
    raise ConnectionException("Cannot connect to {}".format(self.hostname))
napalm.base.exceptions.ConnectionException: Cannot connect to 10.10.10.7

2020-09-29 16:02:30,984 -  nornir.core -     INFO -        run() - Running task 'napalm_get' with args {'getters': ['facts']} on 6 hosts
2020-11-02 10:49:47,424 -  nornir.core -     INFO -        run() - Running task 'napalm_get' with args {'getters': ['facts']} on 6 hosts
2020-11-02 10:49:52,458 - nornir.core.task -    ERROR -      start() - Host 'SW3': task 'napalm_get' failed with traceback:
Traceback (most recent call last):
  File "/home/macaktom/.local/share/virtualenvs/network_automation-NLxdyicX/lib/python3.8/site-packages/netmiko/base_connection.py", line 918, in establish_connection
    self.remote_conn_pre.connect(**ssh_connect_params)
  File "/home/macaktom/.local/share/virtualenvs/network_automation-NLxdyicX/lib/python3.8/site-packages/paramiko/client.py", line 349, in connect
    retry_on_signal(lambda: sock.connect(addr))
  File "/home/macaktom/.local/share/virtualenvs/network_automation-NLxdyicX/lib/python3.8/site-packages/paramiko/util.py", line 283, in retry_on_signal
    return function()
  File "/home/macaktom/.local/share/virtualenvs/network_automation-NLxdyicX/lib/python3.8/site-packages/paramiko/client.py", line 349, in <lambda>
    retry_on_signal(lambda: sock.connect(addr))
socket.timeout: timed out

During handling of the above exception, another exception occurred:

Traceback (most recent call last):
  File "/home/macaktom/.local/share/virtualenvs/network_automation-NLxdyicX/lib/python3.8/site-packages/napalm/base/base.py", line 86, in _netmiko_open
    self._netmiko_device = ConnectHandler(
  File "/home/macaktom/.local/share/virtualenvs/network_automation-NLxdyicX/lib/python3.8/site-packages/netmiko/ssh_dispatcher.py", line 302, in ConnectHandler
    return ConnectionClass(*args, **kwargs)
  File "/home/macaktom/.local/share/virtualenvs/network_automation-NLxdyicX/lib/python3.8/site-packages/netmiko/cisco/cisco_ios.py", line 17, in __init__
    return super().__init__(*args, **kwargs)
  File "/home/macaktom/.local/share/virtualenvs/network_automation-NLxdyicX/lib/python3.8/site-packages/netmiko/base_connection.py", line 344, in __init__
    self._open()
  File "/home/macaktom/.local/share/virtualenvs/network_automation-NLxdyicX/lib/python3.8/site-packages/netmiko/base_connection.py", line 349, in _open
    self.establish_connection()
  File "/home/macaktom/.local/share/virtualenvs/network_automation-NLxdyicX/lib/python3.8/site-packages/netmiko/base_connection.py", line 940, in establish_connection
    raise NetmikoTimeoutException(msg)
netmiko.ssh_exception.NetmikoTimeoutException: TCP connection to device failed.

Common causes of this problem are:
1. Incorrect hostname or IP address.
2. Wrong TCP port.
3. Intermediate firewall blocking access.

Device settings: cisco_ios 10.10.10.7:22



During handling of the above exception, another exception occurred:

Traceback (most recent call last):
  File "/home/macaktom/.local/share/virtualenvs/network_automation-NLxdyicX/lib/python3.8/site-packages/nornir/core/task.py", line 98, in start
    r = self.task(self, **self.params)
  File "/home/macaktom/.local/share/virtualenvs/network_automation-NLxdyicX/lib/python3.8/site-packages/nornir_napalm/plugins/tasks/napalm_get.py", line 32, in napalm_get
    device = task.host.get_connection(CONNECTION_NAME, task.nornir.config)
  File "/home/macaktom/.local/share/virtualenvs/network_automation-NLxdyicX/lib/python3.8/site-packages/nornir/core/inventory.py", line 440, in get_connection
    self.open_connection(
  File "/home/macaktom/.local/share/virtualenvs/network_automation-NLxdyicX/lib/python3.8/site-packages/nornir/core/inventory.py", line 492, in open_connection
    conn_obj.open(
  File "/home/macaktom/.local/share/virtualenvs/network_automation-NLxdyicX/lib/python3.8/site-packages/nornir_napalm/plugins/connections/__init__.py", line 57, in open
    connection.open()
  File "/home/macaktom/.local/share/virtualenvs/network_automation-NLxdyicX/lib/python3.8/site-packages/napalm/ios/ios.py", line 169, in open
    self.device = self._netmiko_open(
  File "/home/macaktom/.local/share/virtualenvs/network_automation-NLxdyicX/lib/python3.8/site-packages/napalm/base/base.py", line 95, in _netmiko_open
    raise ConnectionException("Cannot connect to {}".format(self.hostname))
napalm.base.exceptions.ConnectionException: Cannot connect to 10.10.10.7

2020-11-02 10:49:52,459 - nornir.core.task -    ERROR -      start() - Host 'cisco_R1': task 'napalm_get' failed with traceback:
Traceback (most recent call last):
  File "/home/macaktom/.local/share/virtualenvs/network_automation-NLxdyicX/lib/python3.8/site-packages/netmiko/base_connection.py", line 918, in establish_connection
    self.remote_conn_pre.connect(**ssh_connect_params)
  File "/home/macaktom/.local/share/virtualenvs/network_automation-NLxdyicX/lib/python3.8/site-packages/paramiko/client.py", line 349, in connect
    retry_on_signal(lambda: sock.connect(addr))
  File "/home/macaktom/.local/share/virtualenvs/network_automation-NLxdyicX/lib/python3.8/site-packages/paramiko/util.py", line 283, in retry_on_signal
    return function()
  File "/home/macaktom/.local/share/virtualenvs/network_automation-NLxdyicX/lib/python3.8/site-packages/paramiko/client.py", line 349, in <lambda>
    retry_on_signal(lambda: sock.connect(addr))
socket.timeout: timed out

During handling of the above exception, another exception occurred:

Traceback (most recent call last):
  File "/home/macaktom/.local/share/virtualenvs/network_automation-NLxdyicX/lib/python3.8/site-packages/napalm/base/base.py", line 86, in _netmiko_open
    self._netmiko_device = ConnectHandler(
  File "/home/macaktom/.local/share/virtualenvs/network_automation-NLxdyicX/lib/python3.8/site-packages/netmiko/ssh_dispatcher.py", line 302, in ConnectHandler
    return ConnectionClass(*args, **kwargs)
  File "/home/macaktom/.local/share/virtualenvs/network_automation-NLxdyicX/lib/python3.8/site-packages/netmiko/cisco/cisco_ios.py", line 17, in __init__
    return super().__init__(*args, **kwargs)
  File "/home/macaktom/.local/share/virtualenvs/network_automation-NLxdyicX/lib/python3.8/site-packages/netmiko/base_connection.py", line 344, in __init__
    self._open()
  File "/home/macaktom/.local/share/virtualenvs/network_automation-NLxdyicX/lib/python3.8/site-packages/netmiko/base_connection.py", line 349, in _open
    self.establish_connection()
  File "/home/macaktom/.local/share/virtualenvs/network_automation-NLxdyicX/lib/python3.8/site-packages/netmiko/base_connection.py", line 940, in establish_connection
    raise NetmikoTimeoutException(msg)
netmiko.ssh_exception.NetmikoTimeoutException: TCP connection to device failed.

Common causes of this problem are:
1. Incorrect hostname or IP address.
2. Wrong TCP port.
3. Intermediate firewall blocking access.

Device settings: cisco_ios 10.10.10.2:22



During handling of the above exception, another exception occurred:

Traceback (most recent call last):
  File "/home/macaktom/.local/share/virtualenvs/network_automation-NLxdyicX/lib/python3.8/site-packages/nornir/core/task.py", line 98, in start
    r = self.task(self, **self.params)
  File "/home/macaktom/.local/share/virtualenvs/network_automation-NLxdyicX/lib/python3.8/site-packages/nornir_napalm/plugins/tasks/napalm_get.py", line 32, in napalm_get
    device = task.host.get_connection(CONNECTION_NAME, task.nornir.config)
  File "/home/macaktom/.local/share/virtualenvs/network_automation-NLxdyicX/lib/python3.8/site-packages/nornir/core/inventory.py", line 440, in get_connection
    self.open_connection(
  File "/home/macaktom/.local/share/virtualenvs/network_automation-NLxdyicX/lib/python3.8/site-packages/nornir/core/inventory.py", line 492, in open_connection
    conn_obj.open(
  File "/home/macaktom/.local/share/virtualenvs/network_automation-NLxdyicX/lib/python3.8/site-packages/nornir_napalm/plugins/connections/__init__.py", line 57, in open
    connection.open()
  File "/home/macaktom/.local/share/virtualenvs/network_automation-NLxdyicX/lib/python3.8/site-packages/napalm/ios/ios.py", line 169, in open
    self.device = self._netmiko_open(
  File "/home/macaktom/.local/share/virtualenvs/network_automation-NLxdyicX/lib/python3.8/site-packages/napalm/base/base.py", line 95, in _netmiko_open
    raise ConnectionException("Cannot connect to {}".format(self.hostname))
napalm.base.exceptions.ConnectionException: Cannot connect to 10.10.10.2

2020-11-02 10:49:52,459 - nornir.core.task -    ERROR -      start() - Host 'SW1': task 'napalm_get' failed with traceback:
Traceback (most recent call last):
  File "/home/macaktom/.local/share/virtualenvs/network_automation-NLxdyicX/lib/python3.8/site-packages/netmiko/base_connection.py", line 918, in establish_connection
    self.remote_conn_pre.connect(**ssh_connect_params)
  File "/home/macaktom/.local/share/virtualenvs/network_automation-NLxdyicX/lib/python3.8/site-packages/paramiko/client.py", line 349, in connect
    retry_on_signal(lambda: sock.connect(addr))
  File "/home/macaktom/.local/share/virtualenvs/network_automation-NLxdyicX/lib/python3.8/site-packages/paramiko/util.py", line 283, in retry_on_signal
    return function()
  File "/home/macaktom/.local/share/virtualenvs/network_automation-NLxdyicX/lib/python3.8/site-packages/paramiko/client.py", line 349, in <lambda>
    retry_on_signal(lambda: sock.connect(addr))
socket.timeout: timed out

During handling of the above exception, another exception occurred:

Traceback (most recent call last):
  File "/home/macaktom/.local/share/virtualenvs/network_automation-NLxdyicX/lib/python3.8/site-packages/napalm/base/base.py", line 86, in _netmiko_open
    self._netmiko_device = ConnectHandler(
  File "/home/macaktom/.local/share/virtualenvs/network_automation-NLxdyicX/lib/python3.8/site-packages/netmiko/ssh_dispatcher.py", line 302, in ConnectHandler
    return ConnectionClass(*args, **kwargs)
  File "/home/macaktom/.local/share/virtualenvs/network_automation-NLxdyicX/lib/python3.8/site-packages/netmiko/cisco/cisco_ios.py", line 17, in __init__
    return super().__init__(*args, **kwargs)
  File "/home/macaktom/.local/share/virtualenvs/network_automation-NLxdyicX/lib/python3.8/site-packages/netmiko/base_connection.py", line 344, in __init__
    self._open()
  File "/home/macaktom/.local/share/virtualenvs/network_automation-NLxdyicX/lib/python3.8/site-packages/netmiko/base_connection.py", line 349, in _open
    self.establish_connection()
  File "/home/macaktom/.local/share/virtualenvs/network_automation-NLxdyicX/lib/python3.8/site-packages/netmiko/base_connection.py", line 940, in establish_connection
    raise NetmikoTimeoutException(msg)
netmiko.ssh_exception.NetmikoTimeoutException: TCP connection to device failed.

Common causes of this problem are:
1. Incorrect hostname or IP address.
2. Wrong TCP port.
3. Intermediate firewall blocking access.

Device settings: cisco_ios 10.10.10.5:22



During handling of the above exception, another exception occurred:

Traceback (most recent call last):
  File "/home/macaktom/.local/share/virtualenvs/network_automation-NLxdyicX/lib/python3.8/site-packages/nornir/core/task.py", line 98, in start
    r = self.task(self, **self.params)
  File "/home/macaktom/.local/share/virtualenvs/network_automation-NLxdyicX/lib/python3.8/site-packages/nornir_napalm/plugins/tasks/napalm_get.py", line 32, in napalm_get
    device = task.host.get_connection(CONNECTION_NAME, task.nornir.config)
  File "/home/macaktom/.local/share/virtualenvs/network_automation-NLxdyicX/lib/python3.8/site-packages/nornir/core/inventory.py", line 440, in get_connection
    self.open_connection(
  File "/home/macaktom/.local/share/virtualenvs/network_automation-NLxdyicX/lib/python3.8/site-packages/nornir/core/inventory.py", line 492, in open_connection
    conn_obj.open(
  File "/home/macaktom/.local/share/virtualenvs/network_automation-NLxdyicX/lib/python3.8/site-packages/nornir_napalm/plugins/connections/__init__.py", line 57, in open
    connection.open()
  File "/home/macaktom/.local/share/virtualenvs/network_automation-NLxdyicX/lib/python3.8/site-packages/napalm/ios/ios.py", line 169, in open
    self.device = self._netmiko_open(
  File "/home/macaktom/.local/share/virtualenvs/network_automation-NLxdyicX/lib/python3.8/site-packages/napalm/base/base.py", line 95, in _netmiko_open
    raise ConnectionException("Cannot connect to {}".format(self.hostname))
napalm.base.exceptions.ConnectionException: Cannot connect to 10.10.10.5

2020-11-02 10:49:52,460 - nornir.core.task -    ERROR -      start() - Host 'SW4': task 'napalm_get' failed with traceback:
Traceback (most recent call last):
  File "/home/macaktom/.local/share/virtualenvs/network_automation-NLxdyicX/lib/python3.8/site-packages/netmiko/base_connection.py", line 918, in establish_connection
    self.remote_conn_pre.connect(**ssh_connect_params)
  File "/home/macaktom/.local/share/virtualenvs/network_automation-NLxdyicX/lib/python3.8/site-packages/paramiko/client.py", line 349, in connect
    retry_on_signal(lambda: sock.connect(addr))
  File "/home/macaktom/.local/share/virtualenvs/network_automation-NLxdyicX/lib/python3.8/site-packages/paramiko/util.py", line 283, in retry_on_signal
    return function()
  File "/home/macaktom/.local/share/virtualenvs/network_automation-NLxdyicX/lib/python3.8/site-packages/paramiko/client.py", line 349, in <lambda>
    retry_on_signal(lambda: sock.connect(addr))
socket.timeout: timed out

During handling of the above exception, another exception occurred:

Traceback (most recent call last):
  File "/home/macaktom/.local/share/virtualenvs/network_automation-NLxdyicX/lib/python3.8/site-packages/napalm/base/base.py", line 86, in _netmiko_open
    self._netmiko_device = ConnectHandler(
  File "/home/macaktom/.local/share/virtualenvs/network_automation-NLxdyicX/lib/python3.8/site-packages/netmiko/ssh_dispatcher.py", line 302, in ConnectHandler
    return ConnectionClass(*args, **kwargs)
  File "/home/macaktom/.local/share/virtualenvs/network_automation-NLxdyicX/lib/python3.8/site-packages/netmiko/cisco/cisco_ios.py", line 17, in __init__
    return super().__init__(*args, **kwargs)
  File "/home/macaktom/.local/share/virtualenvs/network_automation-NLxdyicX/lib/python3.8/site-packages/netmiko/base_connection.py", line 344, in __init__
    self._open()
  File "/home/macaktom/.local/share/virtualenvs/network_automation-NLxdyicX/lib/python3.8/site-packages/netmiko/base_connection.py", line 349, in _open
    self.establish_connection()
  File "/home/macaktom/.local/share/virtualenvs/network_automation-NLxdyicX/lib/python3.8/site-packages/netmiko/base_connection.py", line 940, in establish_connection
    raise NetmikoTimeoutException(msg)
netmiko.ssh_exception.NetmikoTimeoutException: TCP connection to device failed.

Common causes of this problem are:
1. Incorrect hostname or IP address.
2. Wrong TCP port.
3. Intermediate firewall blocking access.

Device settings: cisco_ios 10.10.10.8:22



During handling of the above exception, another exception occurred:

Traceback (most recent call last):
  File "/home/macaktom/.local/share/virtualenvs/network_automation-NLxdyicX/lib/python3.8/site-packages/nornir/core/task.py", line 98, in start
    r = self.task(self, **self.params)
  File "/home/macaktom/.local/share/virtualenvs/network_automation-NLxdyicX/lib/python3.8/site-packages/nornir_napalm/plugins/tasks/napalm_get.py", line 32, in napalm_get
    device = task.host.get_connection(CONNECTION_NAME, task.nornir.config)
  File "/home/macaktom/.local/share/virtualenvs/network_automation-NLxdyicX/lib/python3.8/site-packages/nornir/core/inventory.py", line 440, in get_connection
    self.open_connection(
  File "/home/macaktom/.local/share/virtualenvs/network_automation-NLxdyicX/lib/python3.8/site-packages/nornir/core/inventory.py", line 492, in open_connection
    conn_obj.open(
  File "/home/macaktom/.local/share/virtualenvs/network_automation-NLxdyicX/lib/python3.8/site-packages/nornir_napalm/plugins/connections/__init__.py", line 57, in open
    connection.open()
  File "/home/macaktom/.local/share/virtualenvs/network_automation-NLxdyicX/lib/python3.8/site-packages/napalm/ios/ios.py", line 169, in open
    self.device = self._netmiko_open(
  File "/home/macaktom/.local/share/virtualenvs/network_automation-NLxdyicX/lib/python3.8/site-packages/napalm/base/base.py", line 95, in _netmiko_open
    raise ConnectionException("Cannot connect to {}".format(self.hostname))
napalm.base.exceptions.ConnectionException: Cannot connect to 10.10.10.8

2020-11-02 10:49:52,460 - nornir.core.task -    ERROR -      start() - Host 'cisco_R2': task 'napalm_get' failed with traceback:
Traceback (most recent call last):
  File "/home/macaktom/.local/share/virtualenvs/network_automation-NLxdyicX/lib/python3.8/site-packages/netmiko/base_connection.py", line 918, in establish_connection
    self.remote_conn_pre.connect(**ssh_connect_params)
  File "/home/macaktom/.local/share/virtualenvs/network_automation-NLxdyicX/lib/python3.8/site-packages/paramiko/client.py", line 349, in connect
    retry_on_signal(lambda: sock.connect(addr))
  File "/home/macaktom/.local/share/virtualenvs/network_automation-NLxdyicX/lib/python3.8/site-packages/paramiko/util.py", line 283, in retry_on_signal
    return function()
  File "/home/macaktom/.local/share/virtualenvs/network_automation-NLxdyicX/lib/python3.8/site-packages/paramiko/client.py", line 349, in <lambda>
    retry_on_signal(lambda: sock.connect(addr))
socket.timeout: timed out

During handling of the above exception, another exception occurred:

Traceback (most recent call last):
  File "/home/macaktom/.local/share/virtualenvs/network_automation-NLxdyicX/lib/python3.8/site-packages/napalm/base/base.py", line 86, in _netmiko_open
    self._netmiko_device = ConnectHandler(
  File "/home/macaktom/.local/share/virtualenvs/network_automation-NLxdyicX/lib/python3.8/site-packages/netmiko/ssh_dispatcher.py", line 302, in ConnectHandler
    return ConnectionClass(*args, **kwargs)
  File "/home/macaktom/.local/share/virtualenvs/network_automation-NLxdyicX/lib/python3.8/site-packages/netmiko/cisco/cisco_ios.py", line 17, in __init__
    return super().__init__(*args, **kwargs)
  File "/home/macaktom/.local/share/virtualenvs/network_automation-NLxdyicX/lib/python3.8/site-packages/netmiko/base_connection.py", line 344, in __init__
    self._open()
  File "/home/macaktom/.local/share/virtualenvs/network_automation-NLxdyicX/lib/python3.8/site-packages/netmiko/base_connection.py", line 349, in _open
    self.establish_connection()
  File "/home/macaktom/.local/share/virtualenvs/network_automation-NLxdyicX/lib/python3.8/site-packages/netmiko/base_connection.py", line 940, in establish_connection
    raise NetmikoTimeoutException(msg)
netmiko.ssh_exception.NetmikoTimeoutException: TCP connection to device failed.

Common causes of this problem are:
1. Incorrect hostname or IP address.
2. Wrong TCP port.
3. Intermediate firewall blocking access.

Device settings: cisco_ios 10.10.10.3:22



During handling of the above exception, another exception occurred:

Traceback (most recent call last):
  File "/home/macaktom/.local/share/virtualenvs/network_automation-NLxdyicX/lib/python3.8/site-packages/nornir/core/task.py", line 98, in start
    r = self.task(self, **self.params)
  File "/home/macaktom/.local/share/virtualenvs/network_automation-NLxdyicX/lib/python3.8/site-packages/nornir_napalm/plugins/tasks/napalm_get.py", line 32, in napalm_get
    device = task.host.get_connection(CONNECTION_NAME, task.nornir.config)
  File "/home/macaktom/.local/share/virtualenvs/network_automation-NLxdyicX/lib/python3.8/site-packages/nornir/core/inventory.py", line 440, in get_connection
    self.open_connection(
  File "/home/macaktom/.local/share/virtualenvs/network_automation-NLxdyicX/lib/python3.8/site-packages/nornir/core/inventory.py", line 492, in open_connection
    conn_obj.open(
  File "/home/macaktom/.local/share/virtualenvs/network_automation-NLxdyicX/lib/python3.8/site-packages/nornir_napalm/plugins/connections/__init__.py", line 57, in open
    connection.open()
  File "/home/macaktom/.local/share/virtualenvs/network_automation-NLxdyicX/lib/python3.8/site-packages/napalm/ios/ios.py", line 169, in open
    self.device = self._netmiko_open(
  File "/home/macaktom/.local/share/virtualenvs/network_automation-NLxdyicX/lib/python3.8/site-packages/napalm/base/base.py", line 95, in _netmiko_open
    raise ConnectionException("Cannot connect to {}".format(self.hostname))
napalm.base.exceptions.ConnectionException: Cannot connect to 10.10.10.3

2020-11-02 10:49:52,461 - nornir.core.task -    ERROR -      start() - Host 'SW2': task 'napalm_get' failed with traceback:
Traceback (most recent call last):
  File "/home/macaktom/.local/share/virtualenvs/network_automation-NLxdyicX/lib/python3.8/site-packages/netmiko/base_connection.py", line 918, in establish_connection
    self.remote_conn_pre.connect(**ssh_connect_params)
  File "/home/macaktom/.local/share/virtualenvs/network_automation-NLxdyicX/lib/python3.8/site-packages/paramiko/client.py", line 349, in connect
    retry_on_signal(lambda: sock.connect(addr))
  File "/home/macaktom/.local/share/virtualenvs/network_automation-NLxdyicX/lib/python3.8/site-packages/paramiko/util.py", line 283, in retry_on_signal
    return function()
  File "/home/macaktom/.local/share/virtualenvs/network_automation-NLxdyicX/lib/python3.8/site-packages/paramiko/client.py", line 349, in <lambda>
    retry_on_signal(lambda: sock.connect(addr))
socket.timeout: timed out

During handling of the above exception, another exception occurred:

Traceback (most recent call last):
  File "/home/macaktom/.local/share/virtualenvs/network_automation-NLxdyicX/lib/python3.8/site-packages/napalm/base/base.py", line 86, in _netmiko_open
    self._netmiko_device = ConnectHandler(
  File "/home/macaktom/.local/share/virtualenvs/network_automation-NLxdyicX/lib/python3.8/site-packages/netmiko/ssh_dispatcher.py", line 302, in ConnectHandler
    return ConnectionClass(*args, **kwargs)
  File "/home/macaktom/.local/share/virtualenvs/network_automation-NLxdyicX/lib/python3.8/site-packages/netmiko/cisco/cisco_ios.py", line 17, in __init__
    return super().__init__(*args, **kwargs)
  File "/home/macaktom/.local/share/virtualenvs/network_automation-NLxdyicX/lib/python3.8/site-packages/netmiko/base_connection.py", line 344, in __init__
    self._open()
  File "/home/macaktom/.local/share/virtualenvs/network_automation-NLxdyicX/lib/python3.8/site-packages/netmiko/base_connection.py", line 349, in _open
    self.establish_connection()
  File "/home/macaktom/.local/share/virtualenvs/network_automation-NLxdyicX/lib/python3.8/site-packages/netmiko/base_connection.py", line 940, in establish_connection
    raise NetmikoTimeoutException(msg)
netmiko.ssh_exception.NetmikoTimeoutException: TCP connection to device failed.

Common causes of this problem are:
1. Incorrect hostname or IP address.
2. Wrong TCP port.
3. Intermediate firewall blocking access.

Device settings: cisco_ios 10.10.10.6:22



During handling of the above exception, another exception occurred:

Traceback (most recent call last):
  File "/home/macaktom/.local/share/virtualenvs/network_automation-NLxdyicX/lib/python3.8/site-packages/nornir/core/task.py", line 98, in start
    r = self.task(self, **self.params)
  File "/home/macaktom/.local/share/virtualenvs/network_automation-NLxdyicX/lib/python3.8/site-packages/nornir_napalm/plugins/tasks/napalm_get.py", line 32, in napalm_get
    device = task.host.get_connection(CONNECTION_NAME, task.nornir.config)
  File "/home/macaktom/.local/share/virtualenvs/network_automation-NLxdyicX/lib/python3.8/site-packages/nornir/core/inventory.py", line 440, in get_connection
    self.open_connection(
  File "/home/macaktom/.local/share/virtualenvs/network_automation-NLxdyicX/lib/python3.8/site-packages/nornir/core/inventory.py", line 492, in open_connection
    conn_obj.open(
  File "/home/macaktom/.local/share/virtualenvs/network_automation-NLxdyicX/lib/python3.8/site-packages/nornir_napalm/plugins/connections/__init__.py", line 57, in open
    connection.open()
  File "/home/macaktom/.local/share/virtualenvs/network_automation-NLxdyicX/lib/python3.8/site-packages/napalm/ios/ios.py", line 169, in open
    self.device = self._netmiko_open(
  File "/home/macaktom/.local/share/virtualenvs/network_automation-NLxdyicX/lib/python3.8/site-packages/napalm/base/base.py", line 95, in _netmiko_open
    raise ConnectionException("Cannot connect to {}".format(self.hostname))
napalm.base.exceptions.ConnectionException: Cannot connect to 10.10.10.6

2020-11-02 10:50:51,665 -  nornir.core -     INFO -        run() - Running task 'napalm_get' with args {'getters': ['facts']} on 6 hosts
2020-11-02 10:50:54,740 - nornir.core.task -    ERROR -      start() - Host 'SW3': task 'napalm_get' failed with traceback:
Traceback (most recent call last):
  File "/home/macaktom/.local/share/virtualenvs/network_automation-NLxdyicX/lib/python3.8/site-packages/netmiko/base_connection.py", line 918, in establish_connection
    self.remote_conn_pre.connect(**ssh_connect_params)
  File "/home/macaktom/.local/share/virtualenvs/network_automation-NLxdyicX/lib/python3.8/site-packages/paramiko/client.py", line 368, in connect
    raise NoValidConnectionsError(errors)
paramiko.ssh_exception.NoValidConnectionsError: [Errno None] Unable to connect to port 22 on 10.10.10.7

During handling of the above exception, another exception occurred:

Traceback (most recent call last):
  File "/home/macaktom/.local/share/virtualenvs/network_automation-NLxdyicX/lib/python3.8/site-packages/napalm/base/base.py", line 86, in _netmiko_open
    self._netmiko_device = ConnectHandler(
  File "/home/macaktom/.local/share/virtualenvs/network_automation-NLxdyicX/lib/python3.8/site-packages/netmiko/ssh_dispatcher.py", line 302, in ConnectHandler
    return ConnectionClass(*args, **kwargs)
  File "/home/macaktom/.local/share/virtualenvs/network_automation-NLxdyicX/lib/python3.8/site-packages/netmiko/cisco/cisco_ios.py", line 17, in __init__
    return super().__init__(*args, **kwargs)
  File "/home/macaktom/.local/share/virtualenvs/network_automation-NLxdyicX/lib/python3.8/site-packages/netmiko/base_connection.py", line 344, in __init__
    self._open()
  File "/home/macaktom/.local/share/virtualenvs/network_automation-NLxdyicX/lib/python3.8/site-packages/netmiko/base_connection.py", line 349, in _open
    self.establish_connection()
  File "/home/macaktom/.local/share/virtualenvs/network_automation-NLxdyicX/lib/python3.8/site-packages/netmiko/base_connection.py", line 940, in establish_connection
    raise NetmikoTimeoutException(msg)
netmiko.ssh_exception.NetmikoTimeoutException: TCP connection to device failed.

Common causes of this problem are:
1. Incorrect hostname or IP address.
2. Wrong TCP port.
3. Intermediate firewall blocking access.

Device settings: cisco_ios 10.10.10.7:22



During handling of the above exception, another exception occurred:

Traceback (most recent call last):
  File "/home/macaktom/.local/share/virtualenvs/network_automation-NLxdyicX/lib/python3.8/site-packages/nornir/core/task.py", line 98, in start
    r = self.task(self, **self.params)
  File "/home/macaktom/.local/share/virtualenvs/network_automation-NLxdyicX/lib/python3.8/site-packages/nornir_napalm/plugins/tasks/napalm_get.py", line 32, in napalm_get
    device = task.host.get_connection(CONNECTION_NAME, task.nornir.config)
  File "/home/macaktom/.local/share/virtualenvs/network_automation-NLxdyicX/lib/python3.8/site-packages/nornir/core/inventory.py", line 440, in get_connection
    self.open_connection(
  File "/home/macaktom/.local/share/virtualenvs/network_automation-NLxdyicX/lib/python3.8/site-packages/nornir/core/inventory.py", line 492, in open_connection
    conn_obj.open(
  File "/home/macaktom/.local/share/virtualenvs/network_automation-NLxdyicX/lib/python3.8/site-packages/nornir_napalm/plugins/connections/__init__.py", line 57, in open
    connection.open()
  File "/home/macaktom/.local/share/virtualenvs/network_automation-NLxdyicX/lib/python3.8/site-packages/napalm/ios/ios.py", line 169, in open
    self.device = self._netmiko_open(
  File "/home/macaktom/.local/share/virtualenvs/network_automation-NLxdyicX/lib/python3.8/site-packages/napalm/base/base.py", line 95, in _netmiko_open
    raise ConnectionException("Cannot connect to {}".format(self.hostname))
napalm.base.exceptions.ConnectionException: Cannot connect to 10.10.10.7

2020-11-02 10:52:38,020 -  nornir.core -     INFO -        run() - Running task 'napalm_get' with args {'getters': ['facts']} on 6 hosts
2020-11-02 10:52:41,111 - nornir.core.task -    ERROR -      start() - Host 'SW3': task 'napalm_get' failed with traceback:
Traceback (most recent call last):
  File "/home/macaktom/.local/share/virtualenvs/network_automation-NLxdyicX/lib/python3.8/site-packages/netmiko/base_connection.py", line 918, in establish_connection
    self.remote_conn_pre.connect(**ssh_connect_params)
  File "/home/macaktom/.local/share/virtualenvs/network_automation-NLxdyicX/lib/python3.8/site-packages/paramiko/client.py", line 368, in connect
    raise NoValidConnectionsError(errors)
paramiko.ssh_exception.NoValidConnectionsError: [Errno None] Unable to connect to port 22 on 10.10.10.7

During handling of the above exception, another exception occurred:

Traceback (most recent call last):
  File "/home/macaktom/.local/share/virtualenvs/network_automation-NLxdyicX/lib/python3.8/site-packages/napalm/base/base.py", line 86, in _netmiko_open
    self._netmiko_device = ConnectHandler(
  File "/home/macaktom/.local/share/virtualenvs/network_automation-NLxdyicX/lib/python3.8/site-packages/netmiko/ssh_dispatcher.py", line 302, in ConnectHandler
    return ConnectionClass(*args, **kwargs)
  File "/home/macaktom/.local/share/virtualenvs/network_automation-NLxdyicX/lib/python3.8/site-packages/netmiko/cisco/cisco_ios.py", line 17, in __init__
    return super().__init__(*args, **kwargs)
  File "/home/macaktom/.local/share/virtualenvs/network_automation-NLxdyicX/lib/python3.8/site-packages/netmiko/base_connection.py", line 344, in __init__
    self._open()
  File "/home/macaktom/.local/share/virtualenvs/network_automation-NLxdyicX/lib/python3.8/site-packages/netmiko/base_connection.py", line 349, in _open
    self.establish_connection()
  File "/home/macaktom/.local/share/virtualenvs/network_automation-NLxdyicX/lib/python3.8/site-packages/netmiko/base_connection.py", line 940, in establish_connection
    raise NetmikoTimeoutException(msg)
netmiko.ssh_exception.NetmikoTimeoutException: TCP connection to device failed.

Common causes of this problem are:
1. Incorrect hostname or IP address.
2. Wrong TCP port.
3. Intermediate firewall blocking access.

Device settings: cisco_ios 10.10.10.7:22



During handling of the above exception, another exception occurred:

Traceback (most recent call last):
  File "/home/macaktom/.local/share/virtualenvs/network_automation-NLxdyicX/lib/python3.8/site-packages/nornir/core/task.py", line 98, in start
    r = self.task(self, **self.params)
  File "/home/macaktom/.local/share/virtualenvs/network_automation-NLxdyicX/lib/python3.8/site-packages/nornir_napalm/plugins/tasks/napalm_get.py", line 32, in napalm_get
    device = task.host.get_connection(CONNECTION_NAME, task.nornir.config)
  File "/home/macaktom/.local/share/virtualenvs/network_automation-NLxdyicX/lib/python3.8/site-packages/nornir/core/inventory.py", line 440, in get_connection
    self.open_connection(
  File "/home/macaktom/.local/share/virtualenvs/network_automation-NLxdyicX/lib/python3.8/site-packages/nornir/core/inventory.py", line 492, in open_connection
    conn_obj.open(
  File "/home/macaktom/.local/share/virtualenvs/network_automation-NLxdyicX/lib/python3.8/site-packages/nornir_napalm/plugins/connections/__init__.py", line 57, in open
    connection.open()
  File "/home/macaktom/.local/share/virtualenvs/network_automation-NLxdyicX/lib/python3.8/site-packages/napalm/ios/ios.py", line 169, in open
    self.device = self._netmiko_open(
  File "/home/macaktom/.local/share/virtualenvs/network_automation-NLxdyicX/lib/python3.8/site-packages/napalm/base/base.py", line 95, in _netmiko_open
    raise ConnectionException("Cannot connect to {}".format(self.hostname))
napalm.base.exceptions.ConnectionException: Cannot connect to 10.10.10.7

2020-11-02 10:53:26,957 -  nornir.core -     INFO -        run() - Running task 'napalm_get' with args {'getters': ['facts']} on 6 hosts
2020-11-02 10:54:27,087 -  nornir.core -     INFO -        run() - Running task 'napalm_get' with args {'getters': ['facts']} on 6 hosts
2020-11-02 10:55:10,148 -  nornir.core -     INFO -        run() - Running task 'napalm_get' with args {'getters': ['facts']} on 7 hosts
2020-11-02 11:22:58,085 -  nornir.core -     INFO -        run() - Running task 'napalm_get' with args {'getters': ['facts']} on 6 hosts
2020-11-02 11:37:01,566 -  nornir.core -     INFO -        run() - Running task 'napalm_get' with args {'getters': ['facts']} on 6 hosts
2020-11-02 11:45:45,614 -  nornir.core -     INFO -        run() - Running task 'napalm_get' with args {'getters': ['facts']} on 6 hosts
2020-11-02 11:53:08,373 -  nornir.core -     INFO -        run() - Running task 'napalm_get' with args {'getters': ['facts']} on 6 hosts
2020-11-02 12:06:19,776 -  nornir.core -     INFO -        run() - Running task 'napalm_get' with args {'getters': ['facts']} on 6 hosts
2020-11-02 12:11:49,501 -  nornir.core -     INFO -        run() - Running task 'napalm_get' with args {'getters': ['facts']} on 6 hosts
2020-11-02 12:17:24,699 -  nornir.core -     INFO -        run() - Running task 'napalm_get' with args {'getters': ['facts']} on 6 hosts
2020-11-04 10:38:11,480 -  nornir.core -     INFO -        run() - Running task 'napalm_get' with args {'getters': ['facts']} on 6 hosts
2020-11-04 10:38:14,557 - nornir.core.task -    ERROR -      start() - Host 'SW3': task 'napalm_get' failed with traceback:
Traceback (most recent call last):
  File "/home/macaktom/.local/share/virtualenvs/network_automation-NLxdyicX/lib/python3.8/site-packages/netmiko/base_connection.py", line 918, in establish_connection
    self.remote_conn_pre.connect(**ssh_connect_params)
  File "/home/macaktom/.local/share/virtualenvs/network_automation-NLxdyicX/lib/python3.8/site-packages/paramiko/client.py", line 368, in connect
    raise NoValidConnectionsError(errors)
paramiko.ssh_exception.NoValidConnectionsError: [Errno None] Unable to connect to port 22 on 10.10.10.7

During handling of the above exception, another exception occurred:

Traceback (most recent call last):
  File "/home/macaktom/.local/share/virtualenvs/network_automation-NLxdyicX/lib/python3.8/site-packages/napalm/base/base.py", line 86, in _netmiko_open
    self._netmiko_device = ConnectHandler(
  File "/home/macaktom/.local/share/virtualenvs/network_automation-NLxdyicX/lib/python3.8/site-packages/netmiko/ssh_dispatcher.py", line 302, in ConnectHandler
    return ConnectionClass(*args, **kwargs)
  File "/home/macaktom/.local/share/virtualenvs/network_automation-NLxdyicX/lib/python3.8/site-packages/netmiko/cisco/cisco_ios.py", line 17, in __init__
    return super().__init__(*args, **kwargs)
  File "/home/macaktom/.local/share/virtualenvs/network_automation-NLxdyicX/lib/python3.8/site-packages/netmiko/base_connection.py", line 344, in __init__
    self._open()
  File "/home/macaktom/.local/share/virtualenvs/network_automation-NLxdyicX/lib/python3.8/site-packages/netmiko/base_connection.py", line 349, in _open
    self.establish_connection()
  File "/home/macaktom/.local/share/virtualenvs/network_automation-NLxdyicX/lib/python3.8/site-packages/netmiko/base_connection.py", line 940, in establish_connection
    raise NetmikoTimeoutException(msg)
netmiko.ssh_exception.NetmikoTimeoutException: TCP connection to device failed.

Common causes of this problem are:
1. Incorrect hostname or IP address.
2. Wrong TCP port.
3. Intermediate firewall blocking access.

Device settings: cisco_ios 10.10.10.7:22



During handling of the above exception, another exception occurred:

Traceback (most recent call last):
  File "/home/macaktom/.local/share/virtualenvs/network_automation-NLxdyicX/lib/python3.8/site-packages/nornir/core/task.py", line 98, in start
    r = self.task(self, **self.params)
  File "/home/macaktom/.local/share/virtualenvs/network_automation-NLxdyicX/lib/python3.8/site-packages/nornir_napalm/plugins/tasks/napalm_get.py", line 32, in napalm_get
    device = task.host.get_connection(CONNECTION_NAME, task.nornir.config)
  File "/home/macaktom/.local/share/virtualenvs/network_automation-NLxdyicX/lib/python3.8/site-packages/nornir/core/inventory.py", line 440, in get_connection
    self.open_connection(
  File "/home/macaktom/.local/share/virtualenvs/network_automation-NLxdyicX/lib/python3.8/site-packages/nornir/core/inventory.py", line 492, in open_connection
    conn_obj.open(
  File "/home/macaktom/.local/share/virtualenvs/network_automation-NLxdyicX/lib/python3.8/site-packages/nornir_napalm/plugins/connections/__init__.py", line 57, in open
    connection.open()
  File "/home/macaktom/.local/share/virtualenvs/network_automation-NLxdyicX/lib/python3.8/site-packages/napalm/ios/ios.py", line 169, in open
    self.device = self._netmiko_open(
  File "/home/macaktom/.local/share/virtualenvs/network_automation-NLxdyicX/lib/python3.8/site-packages/napalm/base/base.py", line 95, in _netmiko_open
    raise ConnectionException("Cannot connect to {}".format(self.hostname))
napalm.base.exceptions.ConnectionException: Cannot connect to 10.10.10.7

2020-11-04 10:38:14,558 - nornir.core.task -    ERROR -      start() - Host 'SW4': task 'napalm_get' failed with traceback:
Traceback (most recent call last):
  File "/home/macaktom/.local/share/virtualenvs/network_automation-NLxdyicX/lib/python3.8/site-packages/netmiko/base_connection.py", line 918, in establish_connection
    self.remote_conn_pre.connect(**ssh_connect_params)
  File "/home/macaktom/.local/share/virtualenvs/network_automation-NLxdyicX/lib/python3.8/site-packages/paramiko/client.py", line 368, in connect
    raise NoValidConnectionsError(errors)
paramiko.ssh_exception.NoValidConnectionsError: [Errno None] Unable to connect to port 22 on 10.10.10.8

During handling of the above exception, another exception occurred:

Traceback (most recent call last):
  File "/home/macaktom/.local/share/virtualenvs/network_automation-NLxdyicX/lib/python3.8/site-packages/napalm/base/base.py", line 86, in _netmiko_open
    self._netmiko_device = ConnectHandler(
  File "/home/macaktom/.local/share/virtualenvs/network_automation-NLxdyicX/lib/python3.8/site-packages/netmiko/ssh_dispatcher.py", line 302, in ConnectHandler
    return ConnectionClass(*args, **kwargs)
  File "/home/macaktom/.local/share/virtualenvs/network_automation-NLxdyicX/lib/python3.8/site-packages/netmiko/cisco/cisco_ios.py", line 17, in __init__
    return super().__init__(*args, **kwargs)
  File "/home/macaktom/.local/share/virtualenvs/network_automation-NLxdyicX/lib/python3.8/site-packages/netmiko/base_connection.py", line 344, in __init__
    self._open()
  File "/home/macaktom/.local/share/virtualenvs/network_automation-NLxdyicX/lib/python3.8/site-packages/netmiko/base_connection.py", line 349, in _open
    self.establish_connection()
  File "/home/macaktom/.local/share/virtualenvs/network_automation-NLxdyicX/lib/python3.8/site-packages/netmiko/base_connection.py", line 940, in establish_connection
    raise NetmikoTimeoutException(msg)
netmiko.ssh_exception.NetmikoTimeoutException: TCP connection to device failed.

Common causes of this problem are:
1. Incorrect hostname or IP address.
2. Wrong TCP port.
3. Intermediate firewall blocking access.

Device settings: cisco_ios 10.10.10.8:22



During handling of the above exception, another exception occurred:

Traceback (most recent call last):
  File "/home/macaktom/.local/share/virtualenvs/network_automation-NLxdyicX/lib/python3.8/site-packages/nornir/core/task.py", line 98, in start
    r = self.task(self, **self.params)
  File "/home/macaktom/.local/share/virtualenvs/network_automation-NLxdyicX/lib/python3.8/site-packages/nornir_napalm/plugins/tasks/napalm_get.py", line 32, in napalm_get
    device = task.host.get_connection(CONNECTION_NAME, task.nornir.config)
  File "/home/macaktom/.local/share/virtualenvs/network_automation-NLxdyicX/lib/python3.8/site-packages/nornir/core/inventory.py", line 440, in get_connection
    self.open_connection(
  File "/home/macaktom/.local/share/virtualenvs/network_automation-NLxdyicX/lib/python3.8/site-packages/nornir/core/inventory.py", line 492, in open_connection
    conn_obj.open(
  File "/home/macaktom/.local/share/virtualenvs/network_automation-NLxdyicX/lib/python3.8/site-packages/nornir_napalm/plugins/connections/__init__.py", line 57, in open
    connection.open()
  File "/home/macaktom/.local/share/virtualenvs/network_automation-NLxdyicX/lib/python3.8/site-packages/napalm/ios/ios.py", line 169, in open
    self.device = self._netmiko_open(
  File "/home/macaktom/.local/share/virtualenvs/network_automation-NLxdyicX/lib/python3.8/site-packages/napalm/base/base.py", line 95, in _netmiko_open
    raise ConnectionException("Cannot connect to {}".format(self.hostname))
napalm.base.exceptions.ConnectionException: Cannot connect to 10.10.10.8

2020-11-04 10:39:13,046 -  nornir.core -     INFO -        run() - Running task 'napalm_get' with args {'getters': ['facts']} on 6 hosts
2020-11-04 10:39:16,182 - nornir.core.task -    ERROR -      start() - Host 'SW3': task 'napalm_get' failed with traceback:
Traceback (most recent call last):
  File "/home/macaktom/.local/share/virtualenvs/network_automation-NLxdyicX/lib/python3.8/site-packages/netmiko/base_connection.py", line 918, in establish_connection
    self.remote_conn_pre.connect(**ssh_connect_params)
  File "/home/macaktom/.local/share/virtualenvs/network_automation-NLxdyicX/lib/python3.8/site-packages/paramiko/client.py", line 368, in connect
    raise NoValidConnectionsError(errors)
paramiko.ssh_exception.NoValidConnectionsError: [Errno None] Unable to connect to port 22 on 10.10.10.7

During handling of the above exception, another exception occurred:

Traceback (most recent call last):
  File "/home/macaktom/.local/share/virtualenvs/network_automation-NLxdyicX/lib/python3.8/site-packages/napalm/base/base.py", line 86, in _netmiko_open
    self._netmiko_device = ConnectHandler(
  File "/home/macaktom/.local/share/virtualenvs/network_automation-NLxdyicX/lib/python3.8/site-packages/netmiko/ssh_dispatcher.py", line 302, in ConnectHandler
    return ConnectionClass(*args, **kwargs)
  File "/home/macaktom/.local/share/virtualenvs/network_automation-NLxdyicX/lib/python3.8/site-packages/netmiko/cisco/cisco_ios.py", line 17, in __init__
    return super().__init__(*args, **kwargs)
  File "/home/macaktom/.local/share/virtualenvs/network_automation-NLxdyicX/lib/python3.8/site-packages/netmiko/base_connection.py", line 344, in __init__
    self._open()
  File "/home/macaktom/.local/share/virtualenvs/network_automation-NLxdyicX/lib/python3.8/site-packages/netmiko/base_connection.py", line 349, in _open
    self.establish_connection()
  File "/home/macaktom/.local/share/virtualenvs/network_automation-NLxdyicX/lib/python3.8/site-packages/netmiko/base_connection.py", line 940, in establish_connection
    raise NetmikoTimeoutException(msg)
netmiko.ssh_exception.NetmikoTimeoutException: TCP connection to device failed.

Common causes of this problem are:
1. Incorrect hostname or IP address.
2. Wrong TCP port.
3. Intermediate firewall blocking access.

Device settings: cisco_ios 10.10.10.7:22



During handling of the above exception, another exception occurred:

Traceback (most recent call last):
  File "/home/macaktom/.local/share/virtualenvs/network_automation-NLxdyicX/lib/python3.8/site-packages/nornir/core/task.py", line 98, in start
    r = self.task(self, **self.params)
  File "/home/macaktom/.local/share/virtualenvs/network_automation-NLxdyicX/lib/python3.8/site-packages/nornir_napalm/plugins/tasks/napalm_get.py", line 32, in napalm_get
    device = task.host.get_connection(CONNECTION_NAME, task.nornir.config)
  File "/home/macaktom/.local/share/virtualenvs/network_automation-NLxdyicX/lib/python3.8/site-packages/nornir/core/inventory.py", line 440, in get_connection
    self.open_connection(
  File "/home/macaktom/.local/share/virtualenvs/network_automation-NLxdyicX/lib/python3.8/site-packages/nornir/core/inventory.py", line 492, in open_connection
    conn_obj.open(
  File "/home/macaktom/.local/share/virtualenvs/network_automation-NLxdyicX/lib/python3.8/site-packages/nornir_napalm/plugins/connections/__init__.py", line 57, in open
    connection.open()
  File "/home/macaktom/.local/share/virtualenvs/network_automation-NLxdyicX/lib/python3.8/site-packages/napalm/ios/ios.py", line 169, in open
    self.device = self._netmiko_open(
  File "/home/macaktom/.local/share/virtualenvs/network_automation-NLxdyicX/lib/python3.8/site-packages/napalm/base/base.py", line 95, in _netmiko_open
    raise ConnectionException("Cannot connect to {}".format(self.hostname))
napalm.base.exceptions.ConnectionException: Cannot connect to 10.10.10.7

2020-11-04 10:39:16,214 - nornir.core.task -    ERROR -      start() - Host 'SW4': task 'napalm_get' failed with traceback:
Traceback (most recent call last):
  File "/home/macaktom/.local/share/virtualenvs/network_automation-NLxdyicX/lib/python3.8/site-packages/netmiko/base_connection.py", line 918, in establish_connection
    self.remote_conn_pre.connect(**ssh_connect_params)
  File "/home/macaktom/.local/share/virtualenvs/network_automation-NLxdyicX/lib/python3.8/site-packages/paramiko/client.py", line 368, in connect
    raise NoValidConnectionsError(errors)
paramiko.ssh_exception.NoValidConnectionsError: [Errno None] Unable to connect to port 22 on 10.10.10.8

During handling of the above exception, another exception occurred:

Traceback (most recent call last):
  File "/home/macaktom/.local/share/virtualenvs/network_automation-NLxdyicX/lib/python3.8/site-packages/napalm/base/base.py", line 86, in _netmiko_open
    self._netmiko_device = ConnectHandler(
  File "/home/macaktom/.local/share/virtualenvs/network_automation-NLxdyicX/lib/python3.8/site-packages/netmiko/ssh_dispatcher.py", line 302, in ConnectHandler
    return ConnectionClass(*args, **kwargs)
  File "/home/macaktom/.local/share/virtualenvs/network_automation-NLxdyicX/lib/python3.8/site-packages/netmiko/cisco/cisco_ios.py", line 17, in __init__
    return super().__init__(*args, **kwargs)
  File "/home/macaktom/.local/share/virtualenvs/network_automation-NLxdyicX/lib/python3.8/site-packages/netmiko/base_connection.py", line 344, in __init__
    self._open()
  File "/home/macaktom/.local/share/virtualenvs/network_automation-NLxdyicX/lib/python3.8/site-packages/netmiko/base_connection.py", line 349, in _open
    self.establish_connection()
  File "/home/macaktom/.local/share/virtualenvs/network_automation-NLxdyicX/lib/python3.8/site-packages/netmiko/base_connection.py", line 940, in establish_connection
    raise NetmikoTimeoutException(msg)
netmiko.ssh_exception.NetmikoTimeoutException: TCP connection to device failed.

Common causes of this problem are:
1. Incorrect hostname or IP address.
2. Wrong TCP port.
3. Intermediate firewall blocking access.

Device settings: cisco_ios 10.10.10.8:22



During handling of the above exception, another exception occurred:

Traceback (most recent call last):
  File "/home/macaktom/.local/share/virtualenvs/network_automation-NLxdyicX/lib/python3.8/site-packages/nornir/core/task.py", line 98, in start
    r = self.task(self, **self.params)
  File "/home/macaktom/.local/share/virtualenvs/network_automation-NLxdyicX/lib/python3.8/site-packages/nornir_napalm/plugins/tasks/napalm_get.py", line 32, in napalm_get
    device = task.host.get_connection(CONNECTION_NAME, task.nornir.config)
  File "/home/macaktom/.local/share/virtualenvs/network_automation-NLxdyicX/lib/python3.8/site-packages/nornir/core/inventory.py", line 440, in get_connection
    self.open_connection(
  File "/home/macaktom/.local/share/virtualenvs/network_automation-NLxdyicX/lib/python3.8/site-packages/nornir/core/inventory.py", line 492, in open_connection
    conn_obj.open(
  File "/home/macaktom/.local/share/virtualenvs/network_automation-NLxdyicX/lib/python3.8/site-packages/nornir_napalm/plugins/connections/__init__.py", line 57, in open
    connection.open()
  File "/home/macaktom/.local/share/virtualenvs/network_automation-NLxdyicX/lib/python3.8/site-packages/napalm/ios/ios.py", line 169, in open
    self.device = self._netmiko_open(
  File "/home/macaktom/.local/share/virtualenvs/network_automation-NLxdyicX/lib/python3.8/site-packages/napalm/base/base.py", line 95, in _netmiko_open
    raise ConnectionException("Cannot connect to {}".format(self.hostname))
napalm.base.exceptions.ConnectionException: Cannot connect to 10.10.10.8

2020-11-04 10:41:51,360 -  nornir.core -     INFO -        run() - Running task 'napalm_get' with args {'getters': ['facts']} on 6 hosts
2020-11-04 10:41:56,388 - nornir.core.task -    ERROR -      start() - Host 'SW4': task 'napalm_get' failed with traceback:
Traceback (most recent call last):
  File "/home/macaktom/.local/share/virtualenvs/network_automation-NLxdyicX/lib/python3.8/site-packages/netmiko/base_connection.py", line 918, in establish_connection
    self.remote_conn_pre.connect(**ssh_connect_params)
  File "/home/macaktom/.local/share/virtualenvs/network_automation-NLxdyicX/lib/python3.8/site-packages/paramiko/client.py", line 349, in connect
    retry_on_signal(lambda: sock.connect(addr))
  File "/home/macaktom/.local/share/virtualenvs/network_automation-NLxdyicX/lib/python3.8/site-packages/paramiko/util.py", line 283, in retry_on_signal
    return function()
  File "/home/macaktom/.local/share/virtualenvs/network_automation-NLxdyicX/lib/python3.8/site-packages/paramiko/client.py", line 349, in <lambda>
    retry_on_signal(lambda: sock.connect(addr))
socket.timeout: timed out

During handling of the above exception, another exception occurred:

Traceback (most recent call last):
  File "/home/macaktom/.local/share/virtualenvs/network_automation-NLxdyicX/lib/python3.8/site-packages/napalm/base/base.py", line 86, in _netmiko_open
    self._netmiko_device = ConnectHandler(
  File "/home/macaktom/.local/share/virtualenvs/network_automation-NLxdyicX/lib/python3.8/site-packages/netmiko/ssh_dispatcher.py", line 302, in ConnectHandler
    return ConnectionClass(*args, **kwargs)
  File "/home/macaktom/.local/share/virtualenvs/network_automation-NLxdyicX/lib/python3.8/site-packages/netmiko/cisco/cisco_ios.py", line 17, in __init__
    return super().__init__(*args, **kwargs)
  File "/home/macaktom/.local/share/virtualenvs/network_automation-NLxdyicX/lib/python3.8/site-packages/netmiko/base_connection.py", line 344, in __init__
    self._open()
  File "/home/macaktom/.local/share/virtualenvs/network_automation-NLxdyicX/lib/python3.8/site-packages/netmiko/base_connection.py", line 349, in _open
    self.establish_connection()
  File "/home/macaktom/.local/share/virtualenvs/network_automation-NLxdyicX/lib/python3.8/site-packages/netmiko/base_connection.py", line 940, in establish_connection
    raise NetmikoTimeoutException(msg)
netmiko.ssh_exception.NetmikoTimeoutException: TCP connection to device failed.

Common causes of this problem are:
1. Incorrect hostname or IP address.
2. Wrong TCP port.
3. Intermediate firewall blocking access.

Device settings: cisco_ios 10.10.10.8:22



During handling of the above exception, another exception occurred:

Traceback (most recent call last):
  File "/home/macaktom/.local/share/virtualenvs/network_automation-NLxdyicX/lib/python3.8/site-packages/nornir/core/task.py", line 98, in start
    r = self.task(self, **self.params)
  File "/home/macaktom/.local/share/virtualenvs/network_automation-NLxdyicX/lib/python3.8/site-packages/nornir_napalm/plugins/tasks/napalm_get.py", line 32, in napalm_get
    device = task.host.get_connection(CONNECTION_NAME, task.nornir.config)
  File "/home/macaktom/.local/share/virtualenvs/network_automation-NLxdyicX/lib/python3.8/site-packages/nornir/core/inventory.py", line 440, in get_connection
    self.open_connection(
  File "/home/macaktom/.local/share/virtualenvs/network_automation-NLxdyicX/lib/python3.8/site-packages/nornir/core/inventory.py", line 492, in open_connection
    conn_obj.open(
  File "/home/macaktom/.local/share/virtualenvs/network_automation-NLxdyicX/lib/python3.8/site-packages/nornir_napalm/plugins/connections/__init__.py", line 57, in open
    connection.open()
  File "/home/macaktom/.local/share/virtualenvs/network_automation-NLxdyicX/lib/python3.8/site-packages/napalm/ios/ios.py", line 169, in open
    self.device = self._netmiko_open(
  File "/home/macaktom/.local/share/virtualenvs/network_automation-NLxdyicX/lib/python3.8/site-packages/napalm/base/base.py", line 95, in _netmiko_open
    raise ConnectionException("Cannot connect to {}".format(self.hostname))
napalm.base.exceptions.ConnectionException: Cannot connect to 10.10.10.8

2020-11-04 10:42:02,817 -  nornir.core -     INFO -        run() - Running task 'napalm_get' with args {'getters': ['facts']} on 6 hosts
2020-11-04 10:42:05,942 - nornir.core.task -    ERROR -      start() - Host 'SW4': task 'napalm_get' failed with traceback:
Traceback (most recent call last):
  File "/home/macaktom/.local/share/virtualenvs/network_automation-NLxdyicX/lib/python3.8/site-packages/netmiko/base_connection.py", line 918, in establish_connection
    self.remote_conn_pre.connect(**ssh_connect_params)
  File "/home/macaktom/.local/share/virtualenvs/network_automation-NLxdyicX/lib/python3.8/site-packages/paramiko/client.py", line 368, in connect
    raise NoValidConnectionsError(errors)
paramiko.ssh_exception.NoValidConnectionsError: [Errno None] Unable to connect to port 22 on 10.10.10.8

During handling of the above exception, another exception occurred:

Traceback (most recent call last):
  File "/home/macaktom/.local/share/virtualenvs/network_automation-NLxdyicX/lib/python3.8/site-packages/napalm/base/base.py", line 86, in _netmiko_open
    self._netmiko_device = ConnectHandler(
  File "/home/macaktom/.local/share/virtualenvs/network_automation-NLxdyicX/lib/python3.8/site-packages/netmiko/ssh_dispatcher.py", line 302, in ConnectHandler
    return ConnectionClass(*args, **kwargs)
  File "/home/macaktom/.local/share/virtualenvs/network_automation-NLxdyicX/lib/python3.8/site-packages/netmiko/cisco/cisco_ios.py", line 17, in __init__
    return super().__init__(*args, **kwargs)
  File "/home/macaktom/.local/share/virtualenvs/network_automation-NLxdyicX/lib/python3.8/site-packages/netmiko/base_connection.py", line 344, in __init__
    self._open()
  File "/home/macaktom/.local/share/virtualenvs/network_automation-NLxdyicX/lib/python3.8/site-packages/netmiko/base_connection.py", line 349, in _open
    self.establish_connection()
  File "/home/macaktom/.local/share/virtualenvs/network_automation-NLxdyicX/lib/python3.8/site-packages/netmiko/base_connection.py", line 940, in establish_connection
    raise NetmikoTimeoutException(msg)
netmiko.ssh_exception.NetmikoTimeoutException: TCP connection to device failed.

Common causes of this problem are:
1. Incorrect hostname or IP address.
2. Wrong TCP port.
3. Intermediate firewall blocking access.

Device settings: cisco_ios 10.10.10.8:22



During handling of the above exception, another exception occurred:

Traceback (most recent call last):
  File "/home/macaktom/.local/share/virtualenvs/network_automation-NLxdyicX/lib/python3.8/site-packages/nornir/core/task.py", line 98, in start
    r = self.task(self, **self.params)
  File "/home/macaktom/.local/share/virtualenvs/network_automation-NLxdyicX/lib/python3.8/site-packages/nornir_napalm/plugins/tasks/napalm_get.py", line 32, in napalm_get
    device = task.host.get_connection(CONNECTION_NAME, task.nornir.config)
  File "/home/macaktom/.local/share/virtualenvs/network_automation-NLxdyicX/lib/python3.8/site-packages/nornir/core/inventory.py", line 440, in get_connection
    self.open_connection(
  File "/home/macaktom/.local/share/virtualenvs/network_automation-NLxdyicX/lib/python3.8/site-packages/nornir/core/inventory.py", line 492, in open_connection
    conn_obj.open(
  File "/home/macaktom/.local/share/virtualenvs/network_automation-NLxdyicX/lib/python3.8/site-packages/nornir_napalm/plugins/connections/__init__.py", line 57, in open
    connection.open()
  File "/home/macaktom/.local/share/virtualenvs/network_automation-NLxdyicX/lib/python3.8/site-packages/napalm/ios/ios.py", line 169, in open
    self.device = self._netmiko_open(
  File "/home/macaktom/.local/share/virtualenvs/network_automation-NLxdyicX/lib/python3.8/site-packages/napalm/base/base.py", line 95, in _netmiko_open
    raise ConnectionException("Cannot connect to {}".format(self.hostname))
napalm.base.exceptions.ConnectionException: Cannot connect to 10.10.10.8

2020-11-04 10:44:38,952 -  nornir.core -     INFO -        run() - Running task 'napalm_get' with args {'getters': ['facts']} on 6 hosts
2020-11-04 10:44:44,014 - nornir.core.task -    ERROR -      start() - Host 'SW4': task 'napalm_get' failed with traceback:
Traceback (most recent call last):
  File "/home/macaktom/.local/share/virtualenvs/network_automation-NLxdyicX/lib/python3.8/site-packages/netmiko/base_connection.py", line 918, in establish_connection
    self.remote_conn_pre.connect(**ssh_connect_params)
  File "/home/macaktom/.local/share/virtualenvs/network_automation-NLxdyicX/lib/python3.8/site-packages/paramiko/client.py", line 349, in connect
    retry_on_signal(lambda: sock.connect(addr))
  File "/home/macaktom/.local/share/virtualenvs/network_automation-NLxdyicX/lib/python3.8/site-packages/paramiko/util.py", line 283, in retry_on_signal
    return function()
  File "/home/macaktom/.local/share/virtualenvs/network_automation-NLxdyicX/lib/python3.8/site-packages/paramiko/client.py", line 349, in <lambda>
    retry_on_signal(lambda: sock.connect(addr))
socket.timeout: timed out

During handling of the above exception, another exception occurred:

Traceback (most recent call last):
  File "/home/macaktom/.local/share/virtualenvs/network_automation-NLxdyicX/lib/python3.8/site-packages/napalm/base/base.py", line 86, in _netmiko_open
    self._netmiko_device = ConnectHandler(
  File "/home/macaktom/.local/share/virtualenvs/network_automation-NLxdyicX/lib/python3.8/site-packages/netmiko/ssh_dispatcher.py", line 302, in ConnectHandler
    return ConnectionClass(*args, **kwargs)
  File "/home/macaktom/.local/share/virtualenvs/network_automation-NLxdyicX/lib/python3.8/site-packages/netmiko/cisco/cisco_ios.py", line 17, in __init__
    return super().__init__(*args, **kwargs)
  File "/home/macaktom/.local/share/virtualenvs/network_automation-NLxdyicX/lib/python3.8/site-packages/netmiko/base_connection.py", line 344, in __init__
    self._open()
  File "/home/macaktom/.local/share/virtualenvs/network_automation-NLxdyicX/lib/python3.8/site-packages/netmiko/base_connection.py", line 349, in _open
    self.establish_connection()
  File "/home/macaktom/.local/share/virtualenvs/network_automation-NLxdyicX/lib/python3.8/site-packages/netmiko/base_connection.py", line 940, in establish_connection
    raise NetmikoTimeoutException(msg)
netmiko.ssh_exception.NetmikoTimeoutException: TCP connection to device failed.

Common causes of this problem are:
1. Incorrect hostname or IP address.
2. Wrong TCP port.
3. Intermediate firewall blocking access.

Device settings: cisco_ios 10.10.10.8:22



During handling of the above exception, another exception occurred:

Traceback (most recent call last):
  File "/home/macaktom/.local/share/virtualenvs/network_automation-NLxdyicX/lib/python3.8/site-packages/nornir/core/task.py", line 98, in start
    r = self.task(self, **self.params)
  File "/home/macaktom/.local/share/virtualenvs/network_automation-NLxdyicX/lib/python3.8/site-packages/nornir_napalm/plugins/tasks/napalm_get.py", line 32, in napalm_get
    device = task.host.get_connection(CONNECTION_NAME, task.nornir.config)
  File "/home/macaktom/.local/share/virtualenvs/network_automation-NLxdyicX/lib/python3.8/site-packages/nornir/core/inventory.py", line 440, in get_connection
    self.open_connection(
  File "/home/macaktom/.local/share/virtualenvs/network_automation-NLxdyicX/lib/python3.8/site-packages/nornir/core/inventory.py", line 492, in open_connection
    conn_obj.open(
  File "/home/macaktom/.local/share/virtualenvs/network_automation-NLxdyicX/lib/python3.8/site-packages/nornir_napalm/plugins/connections/__init__.py", line 57, in open
    connection.open()
  File "/home/macaktom/.local/share/virtualenvs/network_automation-NLxdyicX/lib/python3.8/site-packages/napalm/ios/ios.py", line 169, in open
    self.device = self._netmiko_open(
  File "/home/macaktom/.local/share/virtualenvs/network_automation-NLxdyicX/lib/python3.8/site-packages/napalm/base/base.py", line 95, in _netmiko_open
    raise ConnectionException("Cannot connect to {}".format(self.hostname))
napalm.base.exceptions.ConnectionException: Cannot connect to 10.10.10.8

2020-11-04 10:46:10,922 -  nornir.core -     INFO -        run() - Running task 'napalm_get' with args {'getters': ['facts']} on 6 hosts
2020-11-04 10:48:53,643 -  nornir.core -     INFO -        run() - Running task 'napalm_get' with args {'getters': ['facts']} on 7 hosts
